Workbook

Sheet Cover
B2: Airbnb (ABNB): the team's forecasting model in one workbook
B3: 2026 Citadel Intercollegiate Stock Pitch Competition. Built 16 Sep 2026 from the repo's processed outputs (main at PR #56). Prelim memo due 2 Oct 2026; next print 5 Nov 2026 (3Q26).
A5: What this is
B6: • One place to see everything the team has built for the upcoming quarters: the revenue model (nights x ADR x FX x take rate), the cost stack line by line, a full income statement to FY27, the operating schedules behind them, the annotated stock history, the two reverse-DCF studies, and the Street/guidance comparison with its price implications.
B7: • Nothing here is typed in by hand: every blue number is read from a CSV in data/processed (the path is beside it or in the Sources block at the foot of each tab); every black number is an Excel formula. Rebuild with: py -3.13 analysis/src/model_workbook/build.py (the script recalculates in Excel and saves the cached values).
B8: • Two cases run through the workbook. BASE = the team model (bridge v3 revenue path, 40_line_build costs). SHORT = the pitch case added 15 Sep (the 4Q25-1Q26 bundle and the World Cup flattered 1H26 nights; RNPL eligibility expanding into a cohort that cancels more; costs at management's budget). STREET = LSEG/Bloomberg consensus, 11-12 Sep 2026.
A10: How to read it
B11: Blue font | C11: hard-coded source value from a repo CSV
B12: Black font | C12: formula in this sheet
B13: Green font | C13: link to another tab
B14: Grey italic | C14: note, source, caveat
B15: Yellow fill | C15: forecast column (3Q26E onward)
B16: Green fill | C16: team base case
B17: Orange fill | C17: short (pitch) case
B18: Grey fill | C18: Street consensus
B19: Pink fill | C19: bear / warning
B20: • The Income Statement tab has a scenario dropdown in cell B3 (Base, the two Short cases, evidence-only costs, revenue/cost bear and bull). The forecast columns on the Income Statement, Margins and Operating Schedules tabs re-flow to the chosen scenario; the Revenue Model and 5 Nov & Street tabs always show Base, Short and Street side by side.
B21: • Units are USD millions unless a row says otherwise; nights in millions; GBV in $bn; percentages are y/y unless labelled '% of revenue'. Quarters are labelled 1Q23A ... 4Q27E.
B22: • Forecast vs scenario: 3Q26 is a tested forecast (the calibrated margin combination beat the Street 14/14 and 10/10 at h=0 in the two backtest windows; the revenue bridge and nights index were scored through the harness). 4Q26 margin is quoted from the Street (no h=1 edge). FY27 is a labelled spending scenario. FY28 is a roll-forward, not a forecast. The short case is a mechanism-plus-current-data view, not a backtest.
A24: Tab map
B25: Income Statement | C25: Quarterly 1Q23A-4Q27E and FY23-FY27: KPIs, cash cost lines, adjusted EBITDA, GAAP bridge to EPS. Scenario dropdown. Street and Short comparison rows underneath.
B26: Revenue Model | C26: Nights (with the regional and lap builds), ADR ex-FX and FX, GBV, take rate, the bridge conversion, revenue; bear/bull/short scenarios; Street on every KPI; the 3Q26 guide in force and the 4Q26 guide the model implies; guide history.
B27: Margins | C27: Each cost line with its drivers, the 3Q26 'down slightly' reconciliation, the 5 Nov margin card (calibrated run), the FY26 sentence expectation and budget identity, FY27 scenario grid, sensitivities, the short case quarter by quarter, seasonality.
B28: Operating Schedules | C28: Bookings and unit economics, revenue by region, the 2027 nights and ADR builds, FX paths, unit-cost drivers, below-EBITDA items, the full parameter sheet.
B29: 5 Nov & Street | C29: Key items side by side (Street / base / short / management delivered), the 5 Nov sequence the model expects, and what each path implies for the price (joint solve, fixed multiple, print reaction, repricing ladder).
B30: Stock Chart | C30: Annotated price history since the IPO: every earnings reaction, every 7%+ day and its driver, and the read-across to 5 Nov.
B31: Reverse DCF - Mgmt | C31: What management's words are worth: Literal / Delivered / Ambition cases, inputs, implied prices by lens, reverse-DCF growth.
B32: Reverse DCF - Market | C32: What the price, the options market and the sell-side tape are paying for; the reaction function; the positioning card.
B33: Scenario Data | C33: The data block behind the dropdown (every scenario x line x quarter). Reference only.
A35: The numbers in one table
B36: Item | C36: Street | D36: Team base | E36: Short (pitch) | F36: Base vs Street | G36: Short vs Street
B37: 3Q26 revenue ($m) | C37: 4744.3221 | D37: 4804.0355 | E37: 4680.9 | F37: =D37/C37-1 -> 0.012586283 | G37: =E37/C37-1 -> -0.013368005
B38: 3Q26 nights y/y | C38: 0.11527 | D38: 0.0989 | E38: 0.085 | F38: =D38-C38 -> -0.01637 | G38: =E38-C38 -> -0.03027
B39: 3Q26 adj. EBITDA ($m) | C39: 2361.5218 | D39: 2419.6425 | E39: 2289.8152 | F39: =D39/C39-1 -> 0.024611549 | G39: =E39/C39-1 -> -0.030364556
B40: 3Q26 adj. EBITDA margin | C40: 0.49775747 | D40: 0.50366874 | E40: 0.48918268 | F40: =D40-C40 -> 0.0059112654 | G40: =E40-C40 -> -0.0085747881
B41: 3Q26 EPS ($) | C41: 2.84539 | D41: 2.9071599 | E41: 2.7144969 | F41: =D41/C41-1 -> 0.021708758 | G41: =E41/C41-1 -> -0.046001803
B42: 4Q26 revenue ($m) | C42: 3161.8163 | D42: 3178.1078 | E42: 2965.8677 | F42: =D42/C42-1 -> 0.0051525859 | G42: =E42/C42-1 -> -0.061973428
B43: 4Q26 adj. EBITDA ($m) | C43: 913.68388 | D43: 898.87164 | E43: 699.60784 | F43: =D43/C43-1 -> -0.016211557 | G43: =E43/C43-1 -> -0.2342999
B44: FY26 revenue ($m) | C44: 14189.557 | D44: 14268.143 | E44: 13932.768 | F44: =D44/C44-1 -> 0.0055383159 | G44: =E44/C44-1 -> -0.018097068
B45: FY26 adj. EBITDA margin | C45: 0.35615785 | D45: 0.3573355 | E45: 0.34231699 | F45: =D45-C45 -> 0.0011776509 | G45: =E45-C45 -> -0.013840862
...

Sheet Income Statement
A1: Airbnb income statement: actuals 1Q23-2Q26, forecast 3Q26-4Q27, FY23-FY27
A2: USD millions unless stated. Blue = source value (10-Q/10-K panel, 40_line_build), black = formula. Forecast columns (yellow) follow the scenario chosen in B3 and pull from the 'Scenario Data' tab. Adjusted EBITDA = revenue less cash costs plus D&A (cash cost lines are GAAP less SBC and other add-backs, as management defines them).
A3: Scenario shown in the forecast columns → | B3: Base (team model) | G3: =INDEX('Scenario Data'!$M$5:$M$14,MATCH($B$3,'Scenario Data'!$L$5:$L$14,0)) -> base | H3: ← scenario key (used by the lookups). Pick from the dropdown in B3: Base, the two Short (pitch) cases, evidence-only costs, or the bear/bull revenue and cost cases.
B4: 1Q23 | C4: 2Q23 | D4: 3Q23 | E4: 4Q23 | F4: 1Q24 | G4: 2Q24 | H4: 3Q24 | I4: 4Q24 | J4: 1Q25 | K4: 2Q25 | L4: 3Q25 | M4: 4Q25 | N4: 1Q26 | O4: 2Q26 | P4: 3Q26 | Q4: 4Q26 | R4: 1Q27 | S4: 2Q27 | T4: 3Q27 | U4: 4Q27 | W4: FY23 | X4: FY24 | Y4: FY25 | Z4: FY26 | AA4: FY27
A5: Quarter | B5: 1Q23A | C5: 2Q23A | D5: 3Q23A | E5: 4Q23A | F5: 1Q24A | G5: 2Q24A | H5: 3Q24A | I5: 4Q24A | J5: 1Q25A | K5: 2Q25A | L5: 3Q25A | M5: 4Q25A | N5: 1Q26A | O5: 2Q26A | P5: 3Q26E | Q5: 4Q26E | R5: 1Q27E | S5: 2Q27E | T5: 3Q27E | U5: 4Q27E | W5: FY23 | X5: FY24 | Y5: FY25 | Z5: FY26E | AA5: FY27E
A6: Operating KPIs
A7: Nights & seats booked (m) | B7: 121.1 | C7: 115.1 | D7: 113.2 | E7: 98.8 | F7: 132.6 | G7: 125.1 | H7: 122.8 | I7: 111 | J7: 143.1 | K7: 134.4 | L7: 133.6 | M7: 121.9 | N7: 156.2 | O7: 148.3 | P7: =INDEX('Scenario Data'!$D$5:$I$345,MATCH($G$3&"|nights_m",'Scenario Data'!$A$5:$A$345,0),MATCH(P$4,'Scenario Data'!$D$4:$I$4,0)) -> 146.813 | Q7: =INDEX('Scenario Data'!$D$5:$I$345,MATCH($G$3&"|nights_m",'Scenario Data'!$A$5:$A$345,0),MATCH(Q$4,'Scenario Data'!$D$4:$I$4,0)) -> 131.7983 | R7: =INDEX('Scenario Data'!$D$5:$I$345,MATCH($G$3&"|nights_m",'Scenario Data'!$A$5:$A$345,0),MATCH(R$4,'Scenario Data'!$D$4:$I$4,0)) -> 169.0178 | S7: =INDEX('Scenario Data'!$D$5:$I$345,MATCH($G$3&"|nights_m",'Scenario Data'!$A$5:$A$345,0),MATCH(S$4,'Scenario Data'!$D$4:$I$4,0)) -> 157.1001 | T7: =INDEX('Scenario Data'!$D$5:$I$345,MATCH($G$3&"|nights_m",'Scenario Data'!$A$5:$A$345,0),MATCH(T$4,'Scenario Data'!$D$4:$I$4,0)) -> 155.958 | U7: =INDEX('Scenario Data'!$D$5:$I$345,MATCH($G$3&"|nights_m",'Scenario Data'!$A$5:$A$345,0),MATCH(U$4,'Scenario Data'!$D$4:$I$4,0)) -> 139.7655 | W7: 448.2 | X7: 491.5 | Y7: 533 | Z7: =SUM(N7:O7,P7:Q7) -> 583.1113 | AA7: =SUM(R7:U7) -> 621.8414
A8: y/y | F8: =IFERROR(F7/B7-1,"") -> 0.094962841 | G8: =IFERROR(G7/C7-1,"") -> 0.086880973 | H8: =IFERROR(H7/D7-1,"") -> 0.084805654 | I8: =IFERROR(I7/E7-1,"") -> 0.12348178 | J8: =IFERROR(J7/F7-1,"") -> 0.07918552 | K8: =IFERROR(K7/G7-1,"") -> 0.074340528 | L8: =IFERROR(L7/H7-1,"") -> 0.087947883 | M8: =IFERROR(M7/I7-1,"") -> 0.098198198 | ... U8: =IFERROR(U7/Q7-1,"") -> 0.060449945 | X8: =IFERROR(X7/W7-1,"") -> 0.096608657 | Y8: =IFERROR(Y7/X7-1,"") -> 0.084435402 | Z8: =IFERROR(Z7/Y7-1,"") -> 0.094017448 | AA8: =IFERROR(AA7/Z7-1,"") -> 0.066419738
A9: Gross booking value ($bn) | B9: 20.4 | C9: 19.1 | D9: 18.3 | E9: 15.5 | F9: 22.9 | G9: 21.2 | H9: 20.1 | I9: 17.6 | J9: 24.5 | K9: 23.5 | L9: 22.9 | M9: 20.4 | N9: 29.2 | O9: 27.2 | P9: =INDEX('Scenario Data'!$D$5:$I$345,MATCH($G$3&"|gbv_busd",'Scenario Data'!$A$5:$A$345,0),MATCH(P$4,'Scenario Data'!$D$4:$I$4,0)) -> 26.028 | Q9: =INDEX('Scenario Data'!$D$5:$I$345,MATCH($G$3&"|gbv_busd",'Scenario Data'!$A$5:$A$345,0),MATCH(Q$4,'Scenario Data'!$D$4:$I$4,0)) -> 22.9873 | R9: =INDEX('Scenario Data'!$D$5:$I$345,MATCH($G$3&"|gbv_busd",'Scenario Data'!$A$5:$A$345,0),MATCH(R$4,'Scenario Data'!$D$4:$I$4,0)) -> 32.5996 | S9: =INDEX('Scenario Data'!$D$5:$I$345,MATCH($G$3&"|gbv_busd",'Scenario Data'!$A$5:$A$345,0),MATCH(S$4,'Scenario Data'!$D$4:$I$4,0)) -> 29.6479 | T9: =INDEX('Scenario Data'!$D$5:$I$345,MATCH($G$3&"|gbv_busd",'Scenario Data'!$A$5:$A$345,0),MATCH(T$4,'Scenario Data'!$D$4:$I$4,0)) -> 28.3908 | U9: =INDEX('Scenario Data'!$D$5:$I$345,MATCH($G$3&"|gbv_busd",'Scenario Data'!$A$5:$A$345,0),MATCH(U$4,'Scenario Data'!$D$4:$I$4,0)) -> 24.8342 | W9: 73.3 | X9: 81.8 | Y9: 91.3 | Z9: =SUM(N9:O9,P9:Q9) -> 105.4153 | AA9: =SUM(R9:U9) -> 115.4725
A10: y/y | F10: =IFERROR(F9/B9-1,"") -> 0.12254902 | G10: =IFERROR(G9/C9-1,"") -> 0.10994764 | H10: =IFERROR(H9/D9-1,"") -> 0.098360656 | I10: =IFERROR(I9/E9-1,"") -> 0.13548387 | J10: =IFERROR(J9/F9-1,"") -> 0.069868996 | K10: =IFERROR(K9/G9-1,"") -> 0.10849057 | L10: =IFERROR(L9/H9-1,"") -> 0.13930348 | M10: =IFERROR(M9/I9-1,"") -> 0.15909091 | ... U10: =IFERROR(U9/Q9-1,"") -> 0.080344364 | X10: =IFERROR(X9/W9-1,"") -> 0.1159618 | Y10: =IFERROR(Y9/X9-1,"") -> 0.11613692 | Z10: =IFERROR(Z9/Y9-1,"") -> 0.1546035 | AA10: =IFERROR(AA9/Z9-1,"") -> 0.095405506
A11: ADR ($, = GBV / nights) | B11: =IFERROR(B9/B7*1000,"") -> 168.45582 | C11: =IFERROR(C9/C7*1000,"") -> 165.94266 | D11: =IFERROR(D9/D7*1000,"") -> 161.66078 | E11: =IFERROR(E9/E7*1000,"") -> 156.88259 | F11: =IFERROR(F9/F7*1000,"") -> 172.69985 | G11: =IFERROR(G9/G7*1000,"") -> 169.46443 | H11: =IFERROR(H9/H7*1000,"") -> 163.68078 | I11: =IFERROR(I9/I7*1000,"") -> 158.55856 | ... U11: =IFERROR(U9/U7*1000,"") -> 177.68476 | W11: =IFERROR(W9/W7*1000,"") -> 163.54306 | X11: =IFERROR(X9/X7*1000,"") -> 166.4293 | Y11: =IFERROR(Y9/Y7*1000,"") -> 171.29456 | Z11: =IFERROR(Z9/Z7*1000,"") -> 180.78075 | AA11: =IFERROR(AA9/AA7*1000,"") -> 185.69446
A12: y/y | F12: =IFERROR(F11/B11-1,"") -> 0.025193712 | G12: =IFERROR(G11/C11-1,"") -> 0.021222812 | H12: =IFERROR(H11/D11-1,"") -> 0.012495328 | I12: =IFERROR(I11/E11-1,"") -> 0.010682941 | J12: =IFERROR(J11/F11-1,"") -> -0.0086329223 | K12: =IFERROR(K11/G11-1,"") -> 0.031786978 | L12: =IFERROR(L11/H11-1,"") -> 0.047204099 | M12: =IFERROR(M11/I11-1,"") -> 0.055447834 | ... U12: =IFERROR(U11/Q11-1,"") -> 0.018760356 | X12: =IFERROR(X11/W11-1,"") -> 0.017648177 | Y12: =IFERROR(Y11/X11-1,"") -> 0.0292332 | Z12: =IFERROR(Z11/Y11-1,"") -> 0.055379424 | AA12: =IFERROR(AA11/Z11-1,"") -> 0.027180449
A14: Income statement (adjusted EBITDA build, then GAAP bridge)
A15: Revenue | B15: 1818 | C15: 2484 | D15: 3397 | E15: 2218 | F15: 2142 | G15: 2748 | H15: 3732 | I15: 2480 | J15: 2272 | K15: 3096 | L15: 4095 | M15: 2778 | N15: 2678 | O15: 3608 | P15: =INDEX('Scenario Data'!$D$5:$I$345,MATCH($G$3&"|revenue",'Scenario Data'!$A$5:$A$345,0),MATCH(P$4,'Scenario Data'!$D$4:$I$4,0)) -> 4804.0355 | Q15: =INDEX('Scenario Data'!$D$5:$I$345,MATCH($G$3&"|revenue",'Scenario Data'!$A$5:$A$345,0),MATCH(Q$4,'Scenario Data'!$D$4:$I$4,0)) -> 3178.1078 | R15: =INDEX('Scenario Data'!$D$5:$I$345,MATCH($G$3&"|revenue",'Scenario Data'!$A$5:$A$345,0),MATCH(R$4,'Scenario Data'!$D$4:$I$4,0)) -> 3053.1293 | S15: =INDEX('Scenario Data'!$D$5:$I$345,MATCH($G$3&"|revenue",'Scenario Data'!$A$5:$A$345,0),MATCH(S$4,'Scenario Data'!$D$4:$I$4,0)) -> 4028.9807 | T15: =INDEX('Scenario Data'!$D$5:$I$345,MATCH($G$3&"|revenue",'Scenario Data'!$A$5:$A$345,0),MATCH(T$4,'Scenario Data'!$D$4:$I$4,0)) -> 5280.7325 | U15: =INDEX('Scenario Data'!$D$5:$I$345,MATCH($G$3&"|revenue",'Scenario Data'!$A$5:$A$345,0),MATCH(U$4,'Scenario Data'!$D$4:$I$4,0)) -> 3465.7641 | W15: 9917 | X15: 11102 | Y15: 12241 | Z15: =SUM(N15:O15,P15:Q15) -> 14268.143 | AA15: =SUM(R15:U15) -> 15828.607
A16: y/y | F16: =IFERROR(F15/B15-1,"") -> 0.17821782 | G16: =IFERROR(G15/C15-1,"") -> 0.10628019 | H16: =IFERROR(H15/D15-1,"") -> 0.098616426 | I16: =IFERROR(I15/E15-1,"") -> 0.11812444 | J16: =IFERROR(J15/F15-1,"") -> 0.060690943 | K16: =IFERROR(K15/G15-1,"") -> 0.12663755 | L16: =IFERROR(L15/H15-1,"") -> 0.097266881 | M16: =IFERROR(M15/I15-1,"") -> 0.12016129 | ... U16: =IFERROR(U15/Q15-1,"") -> 0.090511813 | X16: =IFERROR(X15/W15-1,"") -> 0.11949178 | Y16: =IFERROR(Y15/X15-1,"") -> 0.10259413 | Z16: =IFERROR(Z15/Y15-1,"") -> 0.16560275 | AA16: =IFERROR(AA15/Z15-1,"") -> 0.10936695
A17: Take rate (revenue / GBV) | B17: =IFERROR(B15/B9/1000,"") -> 0.089117647 | C17: =IFERROR(C15/C9/1000,"") -> 0.13005236 | D17: =IFERROR(D15/D9/1000,"") -> 0.18562842 | E17: =IFERROR(E15/E9/1000,"") -> 0.14309677 | F17: =IFERROR(F15/F9/1000,"") -> 0.093537118 | G17: =IFERROR(G15/G9/1000,"") -> 0.12962264 | H17: =IFERROR(H15/H9/1000,"") -> 0.18567164 | I17: =IFERROR(I15/I9/1000,"") -> 0.14090909 | ... U17: =IFERROR(U15/U9/1000,"") -> 0.1395561 | W17: =IFERROR(W15/W9/1000,"") -> 0.13529332 | X17: =IFERROR(X15/X9/1000,"") -> 0.13572127 | Y17: =IFERROR(Y15/Y9/1000,"") -> 0.13407448 | Z17: =IFERROR(Z15/Z9/1000,"") -> 0.13535173 | AA17: =IFERROR(AA15/AA9/1000,"") -> 0.13707685
A19: Cost of revenue (cash) | B19: 428 | C19: 432 | D19: 459 | E19: 384 | F19: 480 | G19: 506 | H19: 465 | I19: 427 | J19: 506 | K19: 544 | L19: 549 | M19: 487 | N19: 581 | O19: 633 | P19: =INDEX('Scenario Data'!$D$5:$I$345,MATCH($G$3&"|cor_cash",'Scenario Data'!$A$5:$A$345,0),MATCH(P$4,'Scenario Data'!$D$4:$I$4,0)) -> 640.78412 | Q19: =INDEX('Scenario Data'!$D$5:$I$345,MATCH($G$3&"|cor_cash",'Scenario Data'!$A$5:$A$345,0),MATCH(Q$4,'Scenario Data'!$D$4:$I$4,0)) -> 578.03946 | R19: =INDEX('Scenario Data'!$D$5:$I$345,MATCH($G$3&"|cor_cash",'Scenario Data'!$A$5:$A$345,0),MATCH(R$4,'Scenario Data'!$D$4:$I$4,0)) -> 706.00359 | S19: =INDEX('Scenario Data'!$D$5:$I$345,MATCH($G$3&"|cor_cash",'Scenario Data'!$A$5:$A$345,0),MATCH(S$4,'Scenario Data'!$D$4:$I$4,0)) -> 727.29954 | T19: =INDEX('Scenario Data'!$D$5:$I$345,MATCH($G$3&"|cor_cash",'Scenario Data'!$A$5:$A$345,0),MATCH(T$4,'Scenario Data'!$D$4:$I$4,0)) -> 699.45368 | U19: =INDEX('Scenario Data'!$D$5:$I$345,MATCH($G$3&"|cor_cash",'Scenario Data'!$A$5:$A$345,0),MATCH(U$4,'Scenario Data'!$D$4:$I$4,0)) -> 626.85228 | W19: 1703 | X19: 1878 | Y19: 2086 | Z19: =SUM(N19:O19,P19:Q19) -> 2432.8236 | AA19: =SUM(R19:U19) -> 2759.6091
A20: Operations & support (cash) | B20: 267 | C20: 298 | D20: 299 | E20: 254 | F20: 266 | G20: 314 | H20: 347 | I20: 265 | J20: 282 | K20: 309 | L20: 343 | M20: 303 | N20: 301 | O20: 323 | P20: =INDEX('Scenario Data'!$D$5:$I$345,MATCH($G$3&"|ops_cash",'Scenario Data'!$A$5:$A$345,0),MATCH(P$4,'Scenario Data'!$D$4:$I$4,0)) -> 361.44309 | Q20: =INDEX('Scenario Data'!$D$5:$I$345,MATCH($G$3&"|ops_cash",'Scenario Data'!$A$5:$A$345,0),MATCH(Q$4,'Scenario Data'!$D$4:$I$4,0)) -> 318.28709 | R20: =INDEX('Scenario Data'!$D$5:$I$345,MATCH($G$3&"|ops_cash",'Scenario Data'!$A$5:$A$345,0),MATCH(R$4,'Scenario Data'!$D$4:$I$4,0)) -> 319.08609 | S20: =INDEX('Scenario Data'!$D$5:$I$345,MATCH($G$3&"|ops_cash",'Scenario Data'!$A$5:$A$345,0),MATCH(S$4,'Scenario Data'!$D$4:$I$4,0)) -> 340.96824 | T20: =INDEX('Scenario Data'!$D$5:$I$345,MATCH($G$3&"|ops_cash",'Scenario Data'!$A$5:$A$345,0),MATCH(T$4,'Scenario Data'!$D$4:$I$4,0)) -> 381.7591 | U20: =INDEX('Scenario Data'!$D$5:$I$345,MATCH($G$3&"|ops_cash",'Scenario Data'!$A$5:$A$345,0),MATCH(U$4,'Scenario Data'!$D$4:$I$4,0)) -> 336.06248 | W20: 1118 | X20: 1192 | Y20: 1237 | Z20: =SUM(N20:O20,P20:Q20) -> 1303.7302 | AA20: =SUM(R20:U20) -> 1377.8759
A21: Product development (cash) | B21: 271 | C21: 260 | D21: 244 | E21: 253 | F21: 290 | G21: 280 | H21: 294 | I21: 306 | J21: 338 | K21: 331 | L21: 333 | M21: 335 | N21: 375 | O21: 374 | P21: =INDEX('Scenario Data'!$D$5:$I$345,MATCH($G$3&"|pd_cash",'Scenario Data'!$A$5:$A$345,0),MATCH(P$4,'Scenario Data'!$D$4:$I$4,0)) -> 359.09488 | Q21: =INDEX('Scenario Data'!$D$5:$I$345,MATCH($G$3&"|pd_cash",'Scenario Data'!$A$5:$A$345,0),MATCH(Q$4,'Scenario Data'!$D$4:$I$4,0)) -> 369.02512 | R21: =INDEX('Scenario Data'!$D$5:$I$345,MATCH($G$3&"|pd_cash",'Scenario Data'!$A$5:$A$345,0),MATCH(R$4,'Scenario Data'!$D$4:$I$4,0)) -> 414.12379 | S21: =INDEX('Scenario Data'!$D$5:$I$345,MATCH($G$3&"|pd_cash",'Scenario Data'!$A$5:$A$345,0),MATCH(S$4,'Scenario Data'!$D$4:$I$4,0)) -> 400.79642 | T21: =INDEX('Scenario Data'!$D$5:$I$345,MATCH($G$3&"|pd_cash",'Scenario Data'!$A$5:$A$345,0),MATCH(T$4,'Scenario Data'!$D$4:$I$4,0)) -> 399.65871 | U21: =INDEX('Scenario Data'!$D$5:$I$345,MATCH($G$3&"|pd_cash",'Scenario Data'!$A$5:$A$345,0),MATCH(U$4,'Scenario Data'!$D$4:$I$4,0)) -> 410.71068 | W21: 1028 | X21: 1170 | Y21: 1337 | Z21: =SUM(N21:O21,P21:Q21) -> 1477.12 | AA21: =SUM(R21:U21) -> 1625.2896
A22: Sales & marketing (cash) | B22: 422 | C22: 450 | D22: 370 | E22: 391 | F22: 479 | G22: 527 | H22: 471 | I22: 501 | J22: 519 | K22: 639 | L22: 585 | M22: 633 | N22: 696 | O22: 808 | P22: =INDEX('Scenario Data'!$D$5:$I$345,MATCH($G$3&"|sm_cash",'Scenario Data'!$A$5:$A$345,0),MATCH(P$4,'Scenario Data'!$D$4:$I$4,0)) -> 778.31581 | Q22: =INDEX('Scenario Data'!$D$5:$I$345,MATCH($G$3&"|sm_cash",'Scenario Data'!$A$5:$A$345,0),MATCH(Q$4,'Scenario Data'!$D$4:$I$4,0)) -> 758.10753 | R22: =INDEX('Scenario Data'!$D$5:$I$345,MATCH($G$3&"|sm_cash",'Scenario Data'!$A$5:$A$345,0),MATCH(R$4,'Scenario Data'!$D$4:$I$4,0)) -> 829.27179 | S22: =INDEX('Scenario Data'!$D$5:$I$345,MATCH($G$3&"|sm_cash",'Scenario Data'!$A$5:$A$345,0),MATCH(S$4,'Scenario Data'!$D$4:$I$4,0)) -> 935.13627 | T22: =INDEX('Scenario Data'!$D$5:$I$345,MATCH($G$3&"|sm_cash",'Scenario Data'!$A$5:$A$345,0),MATCH(T$4,'Scenario Data'!$D$4:$I$4,0)) -> 819.9308 | U22: =INDEX('Scenario Data'!$D$5:$I$345,MATCH($G$3&"|sm_cash",'Scenario Data'!$A$5:$A$345,0),MATCH(U$4,'Scenario Data'!$D$4:$I$4,0)) -> 875.28478 | W22: 1633 | X22: 1978 | Y22: 2376 | Z22: =SUM(N22:O22,P22:Q22) -> 3040.4233 | AA22: =SUM(R22:U22) -> 3459.6236
A23: General & administrative (cash, ex lodging-tax reserves) | B23: 191 | C23: 219 | D23: 202 | E23: 211 | F23: 223 | G23: 242 | H23: 210 | I23: 226 | J23: 235 | K23: 244 | L23: 257 | M23: 259 | N23: 226 | O23: 227 | P23: =INDEX('Scenario Data'!$D$5:$I$345,MATCH($G$3&"|ga_cash",'Scenario Data'!$A$5:$A$345,0),MATCH(P$4,'Scenario Data'!$D$4:$I$4,0)) -> 265.38907 | Q23: =INDEX('Scenario Data'!$D$5:$I$345,MATCH($G$3&"|ga_cash",'Scenario Data'!$A$5:$A$345,0),MATCH(Q$4,'Scenario Data'!$D$4:$I$4,0)) -> 276.41093 | R23: =INDEX('Scenario Data'!$D$5:$I$345,MATCH($G$3&"|ga_cash",'Scenario Data'!$A$5:$A$345,0),MATCH(R$4,'Scenario Data'!$D$4:$I$4,0)) -> 249.22724 | S23: =INDEX('Scenario Data'!$D$5:$I$345,MATCH($G$3&"|ga_cash",'Scenario Data'!$A$5:$A$345,0),MATCH(S$4,'Scenario Data'!$D$4:$I$4,0)) -> 271.5804 | T23: =INDEX('Scenario Data'!$D$5:$I$345,MATCH($G$3&"|ga_cash",'Scenario Data'!$A$5:$A$345,0),MATCH(T$4,'Scenario Data'!$D$4:$I$4,0)) -> 256.53902 | U23: =INDEX('Scenario Data'!$D$5:$I$345,MATCH($G$3&"|ga_cash",'Scenario Data'!$A$5:$A$345,0),MATCH(U$4,'Scenario Data'!$D$4:$I$4,0)) -> 267.19333 | W23: 823 | X23: 901 | Y23: 995 | Z23: =SUM(N23:O23,P23:Q23) -> 994.8 | AA23: =SUM(R23:U23) -> 1044.54
A24: Total cash costs | B24: =SUM(B19:B23) -> 1579 | C24: =SUM(C19:C23) -> 1659 | D24: =SUM(D19:D23) -> 1574 | E24: =SUM(E19:E23) -> 1493 | F24: =SUM(F19:F23) -> 1738 | G24: =SUM(G19:G23) -> 1869 | H24: =SUM(H19:H23) -> 1787 | I24: =SUM(I19:I23) -> 1725 | ... U24: =SUM(U19:U23) -> 2516.1036 | W24: =SUM(W19:W23) -> 6305 | X24: =SUM(X19:X23) -> 7119 | Y24: =SUM(Y19:Y23) -> 8031 | Z24: =SUM(Z19:Z23) -> 9248.8971 | AA24: =SUM(AA19:AA23) -> 10266.938
A25: % of revenue | B25: =IFERROR(B24/B15,"") -> 0.86853685 | C25: =IFERROR(C24/C15,"") -> 0.6678744 | D25: =IFERROR(D24/D15,"") -> 0.46335001 | E25: =IFERROR(E24/E15,"") -> 0.67312894 | F25: =IFERROR(F24/F15,"") -> 0.81139122 | G25: =IFERROR(G24/G15,"") -> 0.680131 | H25: =IFERROR(H24/H15,"") -> 0.47883173 | I25: =IFERROR(I24/I15,"") -> 0.69556452 | ... U25: =IFERROR(U24/U15,"") -> 0.72598812 | W25: =IFERROR(W24/W15,"") -> 0.63577695 | X25: =IFERROR(X24/X15,"") -> 0.64123581 | Y25: =IFERROR(Y24/Y15,"") -> 0.65607385 | Z25: =IFERROR(Z24/Z15,"") -> 0.64822009 | AA25: =IFERROR(AA24/AA15,"") -> 0.64863184
A26: Depreciation & amortisation (inside the cash lines) | B26: 11 | C26: 9 | D26: 8 | E26: 16 | F26: 14 | G26: 14 | H26: 15 | I26: 22 | J26: 25 | K26: 21 | L26: 22 | M26: 23 | N26: 22 | O26: 17 | P26: =INDEX('Scenario Data'!$D$5:$I$345,MATCH($G$3&"|da",'Scenario Data'!$A$5:$A$345,0),MATCH(P$4,'Scenario Data'!$D$4:$I$4,0)) -> 20.633971 | Q26: =INDEX('Scenario Data'!$D$5:$I$345,MATCH($G$3&"|da",'Scenario Data'!$A$5:$A$345,0),MATCH(Q$4,'Scenario Data'!$D$4:$I$4,0)) -> 20.633971 | R26: =INDEX('Scenario Data'!$D$5:$I$345,MATCH($G$3&"|da",'Scenario Data'!$A$5:$A$345,0),MATCH(R$4,'Scenario Data'!$D$4:$I$4,0)) -> 20.633971 | S26: =INDEX('Scenario Data'!$D$5:$I$345,MATCH($G$3&"|da",'Scenario Data'!$A$5:$A$345,0),MATCH(S$4,'Scenario Data'!$D$4:$I$4,0)) -> 20.633971 | T26: =INDEX('Scenario Data'!$D$5:$I$345,MATCH($G$3&"|da",'Scenario Data'!$A$5:$A$345,0),MATCH(T$4,'Scenario Data'!$D$4:$I$4,0)) -> 20.633971 | U26: =INDEX('Scenario Data'!$D$5:$I$345,MATCH($G$3&"|da",'Scenario Data'!$A$5:$A$345,0),MATCH(U$4,'Scenario Data'!$D$4:$I$4,0)) -> 20.633971 | W26: 44 | X26: 65 | Y26: 91 | Z26: =SUM(N26:O26,P26:Q26) -> 80.267941 | AA26: =SUM(R26:U26) -> 82.535882
A27: Other add-backs / reconciling items (history only) | B27: 12 | C27: -15 | D27: 3 | E27: -3 | F27: 6 | G27: 1 | H27: -2 | I27: -12 | J27: 0 | K27: -7 | L27: 1 | M27: 2 | N27: -2 | O27: 1 | W27: -3 | X27: -7 | Y27: -4 | Z27: =SUM(N27:O27,P27:Q27) -> -1 | AA27: =SUM(R27:U27) -> 0 | AC27: History: reported adjusted EBITDA less (revenue - cash costs + D&A); lodging-tax reserves, restructuring and rounding. Forecast: nil by construction.
A28: Adjusted EBITDA | B28: =B15-B24+B26+B27 -> 262 | C28: =C15-C24+C26+C27 -> 819 | D28: =D15-D24+D26+D27 -> 1834 | E28: =E15-E24+E26+E27 -> 738 | F28: =F15-F24+F26+F27 -> 424 | G28: =G15-G24+G26+G27 -> 894 | H28: =H15-H24+H26+H27 -> 1958 | I28: =I15-I24+I26+I27 -> 765 | ... O28: =O15-O24+O26+O27 -> 1261 | P28: =P15-P24+P26 -> 2419.6425 | Q28: =Q15-Q24+Q26 -> 898.87164 | R28: =R15-R24+R26 -> 556.05077 | S28: =S15-S24+S26 -> 1373.8338 | T28: =T15-T24+T26 -> 2744.0252 | U28: =U15-U24+U26 -> 970.29451 | W28: =W15-W24+W26+IF(ISNUMBER(W27),W27,0) -> 3653 | X28: =X15-X24+X26+IF(ISNUMBER(X27),X27,0) -> 4041 | Y28: =Y15-Y24+Y26+IF(ISNUMBER(Y27),Y27,0) -> 4297 | Z28: =Z15-Z24+Z26+IF(ISNUMBER(Z27),Z27,0) -> 5098.5141 | AA28: =AA15-AA24+AA26+IF(ISNUMBER(AA27),AA27,0) -> 5644.2042
A29: Adjusted EBITDA margin | B29: =IFERROR(B28/B15,"") -> 0.14411441 | C29: =IFERROR(C28/C15,"") -> 0.32971014 | D29: =IFERROR(D28/D15,"") -> 0.53988814 | E29: =IFERROR(E28/E15,"") -> 0.33273219 | F29: =IFERROR(F28/F15,"") -> 0.19794585 | G29: =IFERROR(G28/G15,"") -> 0.32532751 | H29: =IFERROR(H28/H15,"") -> 0.52465166 | I29: =IFERROR(I28/I15,"") -> 0.30846774 | ... U29: =IFERROR(U28/U15,"") -> 0.27996554 | W29: =IFERROR(W28/W15,"") -> 0.36835737 | X29: =IFERROR(X28/X15,"") -> 0.36398847 | Y29: =IFERROR(Y28/Y15,"") -> 0.35103341 | Z29: =IFERROR(Z28/Z15,"") -> 0.3573355 | AA29: =IFERROR(AA28/AA15,"") -> 0.35658251
A30: y/y | F30: =IFERROR(F28/B28-1,"") -> 0.61832061 | G30: =IFERROR(G28/C28-1,"") -> 0.091575092 | H30: =IFERROR(H28/D28-1,"") -> 0.067611778 | I30: =IFERROR(I28/E28-1,"") -> 0.036585366 | J30: =IFERROR(J28/F28-1,"") -> -0.016509434 | K30: =IFERROR(K28/G28-1,"") -> 0.16666667 | L30: =IFERROR(L28/H28-1,"") -> 0.047497446 | M30: =IFERROR(M28/I28-1,"") -> 0.02745098 | ... U30: =IFERROR(U28/Q28-1,"") -> 0.079458364 | X30: =IFERROR(X28/W28-1,"") -> 0.10621407 | Y30: =IFERROR(Y28/X28-1,"") -> 0.063350656 | Z30: =IFERROR(Z28/Y28-1,"") -> 0.18652877 | AA30: =IFERROR(AA28/Z28-1,"") -> 0.10702924
A32: Stock-based compensation | B32: 240 | C32: 304 | D32: 286 | E32: 290 | F32: 295 | G32: 382 | H32: 362 | I32: 368 | J32: 358 | K32: 424 | L32: 399 | M32: 411 | N32: 410 | O32: 487 | P32: =INDEX('Scenario Data'!$D$5:$I$345,MATCH($G$3&"|sbc",'Scenario Data'!$A$5:$A$345,0),MATCH(P$4,'Scenario Data'!$D$4:$I$4,0)) -> 451.57919 | Q32: =INDEX('Scenario Data'!$D$5:$I$345,MATCH($G$3&"|sbc",'Scenario Data'!$A$5:$A$345,0),MATCH(Q$4,'Scenario Data'!$D$4:$I$4,0)) -> 465.16051 | R32: =INDEX('Scenario Data'!$D$5:$I$345,MATCH($G$3&"|sbc",'Scenario Data'!$A$5:$A$345,0),MATCH(R$4,'Scenario Data'!$D$4:$I$4,0)) -> 464.02874 | S32: =INDEX('Scenario Data'!$D$5:$I$345,MATCH($G$3&"|sbc",'Scenario Data'!$A$5:$A$345,0),MATCH(S$4,'Scenario Data'!$D$4:$I$4,0)) -> 551.1756 | T32: =INDEX('Scenario Data'!$D$5:$I$345,MATCH($G$3&"|sbc",'Scenario Data'!$A$5:$A$345,0),MATCH(T$4,'Scenario Data'!$D$4:$I$4,0)) -> 511.08712 | U32: =INDEX('Scenario Data'!$D$5:$I$345,MATCH($G$3&"|sbc",'Scenario Data'!$A$5:$A$345,0),MATCH(U$4,'Scenario Data'!$D$4:$I$4,0)) -> 526.45816 | W32: 1120 | X32: 1407 | Y32: 1592 | Z32: =SUM(N32:O32,P32:Q32) -> 1813.7397 | AA32: =SUM(R32:U32) -> 2052.7496
A33: % of revenue | B33: =IFERROR(B32/B15,"") -> 0.1320132 | C33: =IFERROR(C32/C15,"") -> 0.12238325 | D33: =IFERROR(D32/D15,"") -> 0.084191934 | E33: =IFERROR(E32/E15,"") -> 0.13074842 | F33: =IFERROR(F32/F15,"") -> 0.13772176 | G33: =IFERROR(G32/G15,"") -> 0.13901019 | H33: =IFERROR(H32/H15,"") -> 0.096998928 | I33: =IFERROR(I32/I15,"") -> 0.1483871 | ... U33: =IFERROR(U32/U15,"") -> 0.15190248 | W33: =IFERROR(W32/W15,"") -> 0.11293738 | X33: =IFERROR(X32/X15,"") -> 0.12673392 | Y33: =IFERROR(Y32/Y15,"") -> 0.13005473 | Z33: =IFERROR(Z32/Z15,"") -> 0.12711813 | AA33: =IFERROR(AA32/AA15,"") -> 0.12968606
A34: Other GAAP items vs the adjusted stack (history only) | B34: -16 | C34: 17 | D34: -44 | E34: -928 | F34: -14 | G34: -1 | H34: -56 | I34: 55 | J34: 4 | K34: 14 | L34: -5 | M34: -83 | N34: -1 | O34: 1 | W34: -971 | X34: -16 | Y34: -70 | Z34: =SUM(N34:O34,P34:Q34) -> 0 | AA34: =SUM(R34:U34) -> 0 | AC34: History: reported operating income less (adjusted EBITDA - D&A - SBC): restructuring, lodging-tax reserves, acquisition items. Forecast: nil.
A35: Operating income (GAAP) | B35: =B28-B26-B32+B34 -> -5 | C35: =C28-C26-C32+C34 -> 523 | D35: =D28-D26-D32+D34 -> 1496 | E35: =E28-E26-E32+E34 -> -496 | F35: =F28-F26-F32+F34 -> 101 | G35: =G28-G26-G32+G34 -> 497 | H35: =H28-H26-H32+H34 -> 1525 | I35: =I28-I26-I32+I34 -> 430 | ... O35: =O28-O26-O32+O34 -> 758 | P35: =P28-P26-P32 -> 1947.4293 | Q35: =Q28-Q26-Q32 -> 413.07716 | R35: =R28-R26-R32 -> 71.388062 | S35: =S28-S26-S32 -> 802.02423 | T35: =T28-T26-T32 -> 2212.3041 | U35: =U28-U26-U32 -> 423.20238 | W35: =W28-W26-W32+IF(ISNUMBER(W34),W34,0) -> 1518 | X35: =X28-X26-X32+IF(ISNUMBER(X34),X34,0) -> 2553 | Y35: =Y28-Y26-Y32+IF(ISNUMBER(Y34),Y34,0) -> 2544 | Z35: =Z28-Z26-Z32+IF(ISNUMBER(Z34),Z34,0) -> 3204.5065 | AA35: =AA28-AA26-AA32+IF(ISNUMBER(AA34),AA34,0) -> 3508.9187
A36: Operating margin | B36: =IFERROR(B35/B15,"") -> -0.002750275 | C36: =IFERROR(C35/C15,"") -> 0.2105475 | D36: =IFERROR(D35/D15,"") -> 0.44038858 | E36: =IFERROR(E35/E15,"") -> -0.22362489 | F36: =IFERROR(F35/F15,"") -> 0.047152194 | G36: =IFERROR(G35/G15,"") -> 0.18085881 | H36: =IFERROR(H35/H15,"") -> 0.40862808 | I36: =IFERROR(I35/I15,"") -> 0.1733871 | ... U36: =IFERROR(U35/U15,"") -> 0.1221094 | W36: =IFERROR(W35/W15,"") -> 0.15307049 | X36: =IFERROR(X35/X15,"") -> 0.22995857 | Y36: =IFERROR(Y35/Y15,"") -> 0.20782616 | Z36: =IFERROR(Z35/Z15,"") -> 0.2245917 | AA36: =IFERROR(AA35/AA15,"") -> 0.2216821
A37: Interest income | B37: 146 | C37: 191 | D37: 192 | E37: 192 | F37: 202 | G37: 226 | H37: 207 | I37: 183 | J37: 173 | K37: 190 | L37: 180 | M37: 162 | N37: 155 | O37: 183 | P37: =INDEX('Scenario Data'!$D$5:$I$345,MATCH($G$3&"|interest_income",'Scenario Data'!$A$5:$A$345,0),MATCH(P$4,'Scenario Data'!$D$4:$I$4,0)) -> 183.54893 | Q37: =INDEX('Scenario Data'!$D$5:$I$345,MATCH($G$3&"|interest_income",'Scenario Data'!$A$5:$A$345,0),MATCH(Q$4,'Scenario Data'!$D$4:$I$4,0)) -> 165.49547 | R37: =INDEX('Scenario Data'!$D$5:$I$345,MATCH($G$3&"|interest_income",'Scenario Data'!$A$5:$A$345,0),MATCH(R$4,'Scenario Data'!$D$4:$I$4,0)) -> 180.26226 | S37: =INDEX('Scenario Data'!$D$5:$I$345,MATCH($G$3&"|interest_income",'Scenario Data'!$A$5:$A$345,0),MATCH(S$4,'Scenario Data'!$D$4:$I$4,0)) -> 202.84769 | T37: =INDEX('Scenario Data'!$D$5:$I$345,MATCH($G$3&"|interest_income",'Scenario Data'!$A$5:$A$345,0),MATCH(T$4,'Scenario Data'!$D$4:$I$4,0)) -> 191.14509 | U37: =INDEX('Scenario Data'!$D$5:$I$345,MATCH($G$3&"|interest_income",'Scenario Data'!$A$5:$A$345,0),MATCH(U$4,'Scenario Data'!$D$4:$I$4,0)) -> 171.15508 | W37: 721 | X37: 818 | Y37: 705 | Z37: =SUM(N37:O37,P37:Q37) -> 687.0444 | AA37: =SUM(R37:U37) -> 745.41011
A38: Interest expense | B38: 4 | C38: 2 | D38: 6 | E38: 71 | G38: 9 | H38: 2 | I38: 10 | J38: 5 | K38: 6 | L38: 6 | M38: 26 | N38: 21 | O38: 37 | P38: =INDEX('Scenario Data'!$D$5:$I$345,MATCH($G$3&"|interest_expense",'Scenario Data'!$A$5:$A$345,0),MATCH(P$4,'Scenario Data'!$D$4:$I$4,0)) -> 37 | Q38: =INDEX('Scenario Data'!$D$5:$I$345,MATCH($G$3&"|interest_expense",'Scenario Data'!$A$5:$A$345,0),MATCH(Q$4,'Scenario Data'!$D$4:$I$4,0)) -> 37 | R38: =INDEX('Scenario Data'!$D$5:$I$345,MATCH($G$3&"|interest_expense",'Scenario Data'!$A$5:$A$345,0),MATCH(R$4,'Scenario Data'!$D$4:$I$4,0)) -> 37 | S38: =INDEX('Scenario Data'!$D$5:$I$345,MATCH($G$3&"|interest_expense",'Scenario Data'!$A$5:$A$345,0),MATCH(S$4,'Scenario Data'!$D$4:$I$4,0)) -> 37 | T38: =INDEX('Scenario Data'!$D$5:$I$345,MATCH($G$3&"|interest_expense",'Scenario Data'!$A$5:$A$345,0),MATCH(T$4,'Scenario Data'!$D$4:$I$4,0)) -> 37 | U38: =INDEX('Scenario Data'!$D$5:$I$345,MATCH($G$3&"|interest_expense",'Scenario Data'!$A$5:$A$345,0),MATCH(U$4,'Scenario Data'!$D$4:$I$4,0)) -> 37 | W38: 83 | Y38: 43 | Z38: =SUM(N38:O38,P38:Q38) -> 132 | AA38: =SUM(R38:U38) -> 148
A39: Other income / (expense), net | B39: -7 | C39: -36 | D39: -3 | E39: -8 | F39: -10 | G39: -33 | H39: 5 | I39: 19 | J39: -33 | K39: -17 | L39: -7 | M39: -12 | N39: 61 | O39: -7 | P39: =INDEX('Scenario Data'!$D$5:$I$345,MATCH($G$3&"|other_income",'Scenario Data'!$A$5:$A$345,0),MATCH(P$4,'Scenario Data'!$D$4:$I$4,0)) -> 3.7 | Q39: =INDEX('Scenario Data'!$D$5:$I$345,MATCH($G$3&"|other_income",'Scenario Data'!$A$5:$A$345,0),MATCH(Q$4,'Scenario Data'!$D$4:$I$4,0)) -> 3.7 | R39: =INDEX('Scenario Data'!$D$5:$I$345,MATCH($G$3&"|other_income",'Scenario Data'!$A$5:$A$345,0),MATCH(R$4,'Scenario Data'!$D$4:$I$4,0)) -> 3.7 | S39: =INDEX('Scenario Data'!$D$5:$I$345,MATCH($G$3&"|other_income",'Scenario Data'!$A$5:$A$345,0),MATCH(S$4,'Scenario Data'!$D$4:$I$4,0)) -> 3.7 | T39: =INDEX('Scenario Data'!$D$5:$I$345,MATCH($G$3&"|other_income",'Scenario Data'!$A$5:$A$345,0),MATCH(T$4,'Scenario Data'!$D$4:$I$4,0)) -> 3.7 | U39: =INDEX('Scenario Data'!$D$5:$I$345,MATCH($G$3&"|other_income",'Scenario Data'!$A$5:$A$345,0),MATCH(U$4,'Scenario Data'!$D$4:$I$4,0)) -> 3.7 | W39: -54 | X39: -40 | Y39: -69 | Z39: =SUM(N39:O39,P39:Q39) -> 61.4 | AA39: =SUM(R39:U39) -> 14.8
A40: Pre-tax income | B40: =B35+B37-B38+B39 -> 130 | C40: =C35+C37-C38+C39 -> 676 | D40: =D35+D37-D38+D39 -> 1679 | E40: =E35+E37-E38+E39 -> -383 | F40: =F35+F37-F38+F39 -> 293 | G40: =G35+G37-G38+G39 -> 681 | H40: =H35+H37-H38+H39 -> 1735 | I40: =I35+I37-I38+I39 -> 622 | ... U40: =U35+U37-U38+U39 -> 561.05746 | W40: =W35+W37-W38+W39 -> 2102 | X40: =X35+X37-X38+X39 -> 3331 | Y40: =Y35+Y37-Y38+Y39 -> 3137 | Z40: =Z35+Z37-Z38+Z39 -> 3820.9509 | AA40: =AA35+AA37-AA38+AA39 -> 4121.1288
A41: Income tax provision / (benefit) | B41: 13.4 | C41: 26 | D41: -2695 | E41: -34 | F41: 29 | G41: 126 | H41: 367 | I41: 161 | J41: 19 | K41: 137 | L41: 418 | M41: 52 | N41: 121 | O41: 81 | P41: =INDEX('Scenario Data'!$D$5:$I$345,MATCH($G$3&"|tax",'Scenario Data'!$A$5:$A$345,0),MATCH(P$4,'Scenario Data'!$D$4:$I$4,0)) -> 377.58209 | Q41: =INDEX('Scenario Data'!$D$5:$I$345,MATCH($G$3&"|tax",'Scenario Data'!$A$5:$A$345,0),MATCH(Q$4,'Scenario Data'!$D$4:$I$4,0)) -> 98.149072 | R41: =INDEX('Scenario Data'!$D$5:$I$345,MATCH($G$3&"|tax",'Scenario Data'!$A$5:$A$345,0),MATCH(R$4,'Scenario Data'!$D$4:$I$4,0)) -> 38.211306 | S41: =INDEX('Scenario Data'!$D$5:$I$345,MATCH($G$3&"|tax",'Scenario Data'!$A$5:$A$345,0),MATCH(S$4,'Scenario Data'!$D$4:$I$4,0)) -> 170.02509 | T41: =INDEX('Scenario Data'!$D$5:$I$345,MATCH($G$3&"|tax",'Scenario Data'!$A$5:$A$345,0),MATCH(T$4,'Scenario Data'!$D$4:$I$4,0)) -> 414.7761 | U41: =INDEX('Scenario Data'!$D$5:$I$345,MATCH($G$3&"|tax",'Scenario Data'!$A$5:$A$345,0),MATCH(U$4,'Scenario Data'!$D$4:$I$4,0)) -> 98.185055 | W41: -2690 | X41: 683 | Y41: 626 | Z41: =SUM(N41:O41,P41:Q41) -> 677.73116 | AA41: =SUM(R41:U41) -> 721.19755 | AC41: 4Q23 carries the $2.7bn valuation-allowance release; FY23 GAAP net income is not comparable.
A42: Effective tax rate | B42: =IFERROR(B41/B40,"") -> 0.10307692 | C42: =IFERROR(C41/C40,"") -> 0.038461538 | D42: =IFERROR(D41/D40,"") -> -1.6051221 | E42: =IFERROR(E41/E40,"") -> 0.088772846 | F42: =IFERROR(F41/F40,"") -> 0.098976109 | G42: =IFERROR(G41/G40,"") -> 0.18502203 | H42: =IFERROR(H41/H40,"") -> 0.21152738 | I42: =IFERROR(I41/I40,"") -> 0.25884244 | ... U42: =IFERROR(U41/U40,"") -> 0.175 | W42: =IFERROR(W41/W40,"") -> -1.2797336 | X42: =IFERROR(X41/X40,"") -> 0.20504353 | Y42: =IFERROR(Y41/Y40,"") -> 0.19955371 | Z42: =IFERROR(Z41/Z40,"") -> 0.17737238 | AA42: =IFERROR(AA41/AA40,"") -> 0.175
A43: Net income | B43: =B40-B41 -> 116.6 | C43: =C40-C41 -> 650 | D43: =D40-D41 -> 4374 | E43: =E40-E41 -> -349 | F43: =F40-F41 -> 264 | G43: =G40-G41 -> 555 | H43: =H40-H41 -> 1368 | I43: =I40-I41 -> 461 | ... U43: =U40-U41 -> 462.8724 | W43: =W40-W41 -> 4792 | X43: =X40-X41 -> 2648 | Y43: =Y40-Y41 -> 2511 | Z43: =Z40-Z41 -> 3143.2197 | AA43: =AA40-AA41 -> 3399.9313
...

Sheet Revenue Model
A1: Revenue model: nights x ADR (ex-FX + FX) = GBV; GBV x take rate = revenue
A2: Base path = bridge v3 for 3Q26-4Q26 (team nights baseline PR #32, ADR card v3, FX kernel) and the WS06 v2b path for 2027. Blue = source value, black = formula. Percent changes are y/y. FX shown in percentage points of y/y growth.
A5: Quarter | B5: 1Q23A | C5: 2Q23A | D5: 3Q23A | E5: 4Q23A | F5: 1Q24A | G5: 2Q24A | H5: 3Q24A | I5: 4Q24A | J5: 1Q25A | K5: 2Q25A | L5: 3Q25A | M5: 4Q25A | N5: 1Q26A | O5: 2Q26A | P5: 3Q26E | Q5: 4Q26E | R5: 1Q27E | S5: 2Q27E | T5: 3Q27E | U5: 4Q27E | W5: FY23 | X5: FY24 | Y5: FY25 | Z5: FY26E | AA5: FY27E
A6: 1. Base path: volume, price, FX and take rate | B6: team baseline; comparison scenarios are in section 2
B7: 121.1 | C7: 115.1 | D7: 113.2 | E7: 98.8 | F7: 132.6 | G7: 125.1 | H7: 122.8 | I7: 111 | J7: 143.1 | K7: 134.4 | L7: 133.6 | M7: 121.9 | N7: 156.2 | O7: 148.3 | P7: 146.813 | Q7: 131.7983 | R7: 169.0178 | S7: 157.1001 | T7: 155.958 | U7: 139.7655 | W7: =SUM(B7:E7) -> 448.2 | X7: =SUM(F7:I7) -> 491.5 | Y7: =SUM(J7:M7) -> 533 | Z7: =SUM(N7:O7,P7:Q7) -> 583.1113 | AA7: =SUM(R7:U7) -> 621.8414
A8: y/y | F8: =IFERROR(F7/B7-1,"") -> 0.094962841 | G8: =IFERROR(G7/C7-1,"") -> 0.086880973 | H8: =IFERROR(H7/D7-1,"") -> 0.084805654 | I8: =IFERROR(I7/E7-1,"") -> 0.12348178 | J8: =IFERROR(J7/F7-1,"") -> 0.07918552 | K8: =IFERROR(K7/G7-1,"") -> 0.074340528 | L8: =IFERROR(L7/H7-1,"") -> 0.087947883 | M8: =IFERROR(M7/I7-1,"") -> 0.098198198 | ... U8: =IFERROR(U7/Q7-1,"") -> 0.060449945 | X8: =IFERROR(X7/W7-1,"") -> 0.096608657 | Y8: =IFERROR(Y7/X7-1,"") -> 0.084435402 | Z8: =IFERROR(Z7/Y7-1,"") -> 0.094017448 | AA8: =IFERROR(AA7/Z7-1,"") -> 0.066419738
A9: NA nights y/y (regional build) | N9: 0.08 | O9: 0.08 | P9: 0.11 | Q9: 0.11 | AC9: 1H26 from letters/10-Q commentary; 2H26 = WS10 regional build re-based (h2_bridge_2026_projection.csv). No regional 2027 build.
A10: EMEA nights y/y (regional build) | N10: 0.05 | O10: 0.08 | P10: 0.065 | Q10: 0.095
A11: LatAm nights y/y (regional build) | N11: 0.18 | O11: 0.2 | P11: 0.19333333 | Q11: 0.19666667
A12: APAC nights y/y (regional build) | N12: 0.18 | O12: 0.18 | P12: 0.14666667 | Q12: 0.14
B14: 168.43 | C14: 166.01 | D14: 161.38 | E14: 156.73 | F14: 172.88 | G14: 169.53 | H14: 163.64 | I14: 158.13 | J14: 171.34 | K14: 174.48 | L14: 171.29 | M14: 167.51 | N14: 186.82 | O14: 183.73 | P14: 177.1652 | Q14: 174.5789 | R14: 192.7534 | S14: 189.0471 | T14: 181.9168 | U14: 177.854
A15: ADR y/y reported | F15: =IFERROR(F14/B14-1,"") -> 0.026420471 | G15: =IFERROR(G14/C14-1,"") -> 0.021203542 | H15: =IFERROR(H14/D14-1,"") -> 0.014004214 | I15: =IFERROR(I14/E14-1,"") -> 0.0089325592 | J15: =IFERROR(J14/F14-1,"") -> -0.008907913 | K15: =IFERROR(K14/G14-1,"") -> 0.029198372 | L15: =IFERROR(L14/H14-1,"") -> 0.046748961 | M15: =IFERROR(M14/I14-1,"") -> 0.059318282 | ... U15: =IFERROR(U14/Q14-1,"") -> 0.018759999 | X15: =IFERROR(X14/W14-1,"") | Y15: =IFERROR(Y14/X14-1,"") | Z15: =IFERROR(Z14/Y14-1,"") | AA15: =IFERROR(AA14/Z14-1,"")
A16: ADR y/y ex-FX | L16: =L15-L17 -> 0.019748961 | M16: =M15-M17 -> 0.030318282 | N16: =N15-N17 -> 0.040346679 | O16: =O15-O17 -> 0.040014672 | P16: 0.0386 | Q16: 0.0407 | R16: 0.03478 | S16: 0.03087 | T16: 0.02648 | U16: 0.02161 | AC16: Forecast: ADR card v3 (3Q26 +3.9%, 4Q26 +4.1%) then the WS06 ADR build (residual + K line + geo mix + party size + LOS + seats).
A17: FX contribution to ADR y/y (pts) | L17: 0.027 | M17: 0.029 | N17: 0.05 | O17: 0.013 | P17: -0.0043 | Q17: 0.0015 | R17: -0.00301 | S17: -0.00193 | T17: 0.00034 | U17: -0.00285 | AC17: History: disclosed in the letters (3Q25-2Q26). Forecast: ADR v3 midpoint of the EUR fit and regional baskets (3Q26 -0.4pt, 4Q26 +0.2pt), then the FX kernel.
B19: 20.4 | C19: 19.1 | D19: 18.3 | E19: 15.5 | F19: 22.9 | G19: 21.2 | H19: 20.1 | I19: 17.6 | J19: 24.5 | K19: 23.5 | L19: 22.9 | M19: 20.4 | N19: 29.2 | O19: 27.2 | P19: =P7*P14/1000 -> 26.010155 | Q19: =Q7*Q14/1000 -> 23.009202 | R19: =R7*R14/1000 -> 32.578756 | S19: =S7*S14/1000 -> 29.699318 | T19: =T7*T14/1000 -> 28.37138 | U19: =U7*U14/1000 -> 24.857853 | W19: =SUM(B19:E19) -> 73.3 | X19: =SUM(F19:I19) -> 81.8 | Y19: =SUM(J19:M19) -> 91.3 | Z19: =SUM(N19:O19,P19:Q19) -> 105.41936 | AA19: =SUM(R19:U19) -> 115.50731 | AC19: Forecast GBV = nights x ADR (the 06 path carries a <0.2% identity gap to its own GBV line).
A20: y/y | F20: =IFERROR(F19/B19-1,"") -> 0.12254902 | G20: =IFERROR(G19/C19-1,"") -> 0.10994764 | H20: =IFERROR(H19/D19-1,"") -> 0.098360656 | I20: =IFERROR(I19/E19-1,"") -> 0.13548387 | J20: =IFERROR(J19/F19-1,"") -> 0.069868996 | K20: =IFERROR(K19/G19-1,"") -> 0.10849057 | L20: =IFERROR(L19/H19-1,"") -> 0.13930348 | M20: =IFERROR(M19/I19-1,"") -> 0.15909091 | ... U20: =IFERROR(U19/Q19-1,"") -> 0.080343985 | X20: =IFERROR(X19/W19-1,"") -> 0.1159618 | Y20: =IFERROR(Y19/X19-1,"") -> 0.11613692 | Z20: =IFERROR(Z19/Y19-1,"") -> 0.15464794 | AA20: =IFERROR(AA19/Z19-1,"") -> 0.095693533
A22: Take rate, prior-year quarter (%) | P22: 0.178821 | Q22: 0.136176 | R22: 0.091712 | S22: 0.132647 | T22: 0.184572 | U22: 0.138255
A23: Take rate change y/y (pts) | P23: 0.005751 | Q23: 0.002079 | R23: 0.001943 | S23: 0.003247 | T23: 0.001429 | U23: 0.001301 | AC23: 3Q26 +0.58pt: FX timing (revenue recognised at check-in on bookings made when the dollar was weaker) and the fee changes; 2027 +0.1-0.3pt.
A24: Lagged GBV used by the bridge ($bn) | P24: 27.8667 | Q24: 26.4186 | R24: 24.0008 | S24: 29.3955 | T24: 30.6318 | U24: 28.8098 | AC24: Revenue converts from bookings made earlier: the bridge kernel maps a lagged GBV mix to revenue at a seasonal conversion rate.
A25: Conversion: revenue / lagged GBV | P25: =IFERROR(P26/(P24*1000),"") -> 0.17239341 | Q25: =IFERROR(Q26/(Q24*1000),"") -> 0.12029812 | R25: =IFERROR(R26/(R24*1000),"") -> 0.12720948 | S25: =IFERROR(S26/(S24*1000),"") -> 0.13706114 | T25: =IFERROR(T26/(T24*1000),"") -> 0.1723938 | U25: =IFERROR(U26/(U24*1000),"") -> 0.1202981
B26: 1818 | C26: 2484 | D26: 3397 | E26: 2218 | F26: 2142 | G26: 2748 | H26: 3732 | I26: 2480 | J26: 2272 | K26: 3096 | L26: 4095 | M26: 2778 | N26: 2678 | O26: 3608 | P26: 4804.0355 | Q26: 3178.1078 | R26: 3053.1293 | S26: 4028.9807 | T26: 5280.7325 | U26: 3465.7641 | W26: =SUM(B26:E26) -> 9917 | X26: =SUM(F26:I26) -> 11102 | Y26: =SUM(J26:M26) -> 12241 | Z26: =SUM(N26:O26,P26:Q26) -> 14268.143 | AA26: =SUM(R26:U26) -> 15828.607
A27: Revenue y/y reported | F27: =IFERROR(F26/B26-1,"") -> 0.17821782 | G27: =IFERROR(G26/C26-1,"") -> 0.10628019 | H27: =IFERROR(H26/D26-1,"") -> 0.098616426 | I27: =IFERROR(I26/E26-1,"") -> 0.11812444 | J27: =IFERROR(J26/F26-1,"") -> 0.060690943 | K27: =IFERROR(K26/G26-1,"") -> 0.12663755 | L27: =IFERROR(L26/H26-1,"") -> 0.097266881 | M27: =IFERROR(M26/I26-1,"") -> 0.12016129 | ... U27: =IFERROR(U26/Q26-1,"") -> 0.090511813 | X27: =IFERROR(X26/W26-1,"") -> 0.11949178 | Y27: =IFERROR(Y26/X26-1,"") -> 0.10259413 | Z27: =IFERROR(Z26/Y26-1,"") -> 0.16560275 | AA27: =IFERROR(AA26/Z26-1,"") -> 0.10936695
A28: FX contribution to revenue y/y (pts) | B28: -0.04 | C28: -0.01 | D28: 0.04 | E28: 0.03 | F28: 0 | G28: 0 | H28: 0 | J28: -0.02 | K28: 0 | L28: 0 | M28: 0.01 | N28: 0.03 | O28: 0.04 | P28: 0.03 | Q28: 0.0098 | R28: 0.0093 | S28: 0.0062 | T28: 0.0031 | U28: 0.0038 | AC28: History: reported less constant-currency growth from the letters. 3Q26 = management's ~3pt after hedging; 4Q26+ = FX-lag kernel (0.98, 0.93, 0.62, 0.31, 0.38pt).
A29: Revenue y/y ex-FX | B29: =IFERROR(B27-B28,"") -> 0.04 | C29: =IFERROR(C27-C28,"") -> 0.01 | D29: =IFERROR(D27-D28,"") -> -0.04 | E29: =IFERROR(E27-E28,"") -> -0.03 | F29: =IFERROR(F27-F28,"") -> 0.17821782 | G29: =IFERROR(G27-G28,"") -> 0.10628019 | H29: =IFERROR(H27-H28,"") -> 0.098616426 | I29: =IFERROR(I27-I28,"") -> 0.11812444 | ... O29: =IFERROR(O27-O28,"") -> 0.12537468 | P29: =P27-P28 -> 0.14314664 | Q29: =Q27-Q28 -> 0.13422729 | R29: =R27-R28 -> 0.13077816 | S29: =S27-S28 -> 0.11047979 | T29: =T27-T28 -> 0.096128451 | U29: =U27-U28 -> 0.086711813
A30: Take rate printed (revenue / GBV) | B30: =IFERROR(B26/(B19*1000),"") -> 0.089117647 | C30: =IFERROR(C26/(C19*1000),"") -> 0.13005236 | D30: =IFERROR(D26/(D19*1000),"") -> 0.18562842 | E30: =IFERROR(E26/(E19*1000),"") -> 0.14309677 | F30: =IFERROR(F26/(F19*1000),"") -> 0.093537118 | G30: =IFERROR(G26/(G19*1000),"") -> 0.12962264 | H30: =IFERROR(H26/(H19*1000),"") -> 0.18567164 | I30: =IFERROR(I26/(I19*1000),"") -> 0.14090909 | ... U30: =IFERROR(U26/(U19*1000),"") -> 0.13942331 | W30: =IFERROR(W26/(W19*1000),"") -> 0.13529332 | X30: =IFERROR(X26/(X19*1000),"") -> 0.13572127 | Y30: =IFERROR(Y26/(Y19*1000),"") -> 0.13407448 | Z30: =IFERROR(Z26/(Z19*1000),"") -> 0.13534652 | AA30: =IFERROR(AA26/(AA19*1000),"") -> 0.13703554
A31: Revenue band low (conversion band) | P31: 4777.8744 | Q31: 3156.008 | R31: 2958.2216 | S31: 3953.2896 | T31: 5251.9755 | U31: 3441.6639
A32: Revenue band high (conversion band) | P32: 4846.2321 | Q32: 3201.2166 | R32: 3128.384 | S32: 4099.4831 | T32: 5327.1162 | U32: 3490.9644 | AC32: Conversion min/max over the fitted years; it is not the nights band (section 2 has that).
A34: 2. Revenue scenarios: nights, ADR and revenue by case | B34: bear/bull = WS06 v2b on the bridge v3 bands; Short = the pitch case (lap + RNPL cancellations)
A35: Nights y/y: Bear | P35: 0.085 | Q35: 0.08 | R35: 0.04707 | S35: 0.03026 | T35: 0.03405 | U35: 0.03327 | Z35: 0.090259 | AA35: 0.036406
A36: Nights y/y: Base | P36: 0.0989 | Q36: 0.0812 | R36: 0.08206 | S36: 0.05934 | T36: 0.06229 | U36: 0.06045 | Z36: 0.094017 | AA36: 0.06642
A37: Nights y/y: Bull | P37: 0.11 | Q37: 0.0886 | R37: 0.10524 | S37: 0.0882 | T37: 0.08684 | U37: 0.08571 | Z37: 0.098492 | AA37: 0.091837
A38: Nights y/y: Short (pitch) | P38: 0.085 | Q38: 0.05 | R38: 0.04 | S38: 0.02 | T38: 0.03 | U38: 0.04 | AC38: Short: nights +8.5% in 3Q26 (guide low; July still has the World Cup) then +5/+4/+2/+3/+4% as the 4Q25-1Q26 bundle and World Cup lap and RNPL cancellations land; ADR ex-FX +2.5% then flat.
A40: ADR y/y reported: Bear | P40: 0.0203 | Q40: 0.0277 | R40: -0.00875 | S40: -0.00798 | T40: -0.00198 | U40: 0.00723 | Z40: 0.048749 | AA40: -0.003331
A41: ADR y/y reported: Base | P41: 0.0343 | Q41: 0.0422 | R41: 0.03176 | S41: 0.02894 | T41: 0.02682 | U41: 0.01876 | Z41: 0.055379 | AA41: 0.027181
A42: ADR y/y reported: Bull | P42: 0.0484 | Q42: 0.0566 | R42: 0.0573 | S42: 0.05801 | T42: 0.05268 | U42: 0.03174 | Z42: 0.062032 | AA42: 0.050872
A43: ADR y/y reported: Short (pitch) | P43: 0.0207 | Q43: 0.0015 | R43: -0.00302 | S43: -0.00193 | T43: 0.00034 | U43: -0.00285
A45: Revenue ($m): Bear | P45: 4755 | Q45: 3123.807 | R45: 2995.1629 | S45: 3803.7239 | T45: 4936.538 | U45: 3212.9091 | Z45: 14164.807 | AA45: 14948.334
A46: Revenue ($m): Base | P46: 4804.0355 | Q46: 3178.1078 | R46: 3053.1293 | S46: 4028.9807 | T46: 5280.7325 | U46: 3465.7641 | Z46: 14268.143 | AA46: 15828.607
A47: Revenue ($m): Bull | P47: 4878 | Q47: 3227.9366 | R47: 3119.9376 | S47: 4189.9054 | T47: 5559.9477 | U47: 3700.9529 | Z47: 14391.937 | AA47: 16570.744
A48: Revenue ($m): Short (pitch) | P48: 4680.9 | Q48: 2965.8677 | R48: 2835.5346 | S48: 3762.9716 | T48: 4988.1742 | U48: 3326.8311 | Z48: 13932.768 | AA48: 14913.512
...

Sheet Margins
A1: Margins: the cost stack line by line, the 3Q26 sentence, the 5 Nov card and the FY26/FY27 margin view
A2: Cash cost lines = GAAP less SBC and add-backs (management's adjusted EBITDA definition). Forecast columns follow the scenario dropdown on the Income Statement tab (B3). Blue = source value, black = formula, green = link.
A3: Scenario in the forecast columns: | B3: ='Income Statement'!B3 -> Base (team model)
B4: 1Q23 | C4: 2Q23 | D4: 3Q23 | E4: 4Q23 | F4: 1Q24 | G4: 2Q24 | H4: 3Q24 | I4: 4Q24 | J4: 1Q25 | K4: 2Q25 | L4: 3Q25 | M4: 4Q25 | N4: 1Q26 | O4: 2Q26 | P4: 3Q26 | Q4: 4Q26 | R4: 1Q27 | S4: 2Q27 | T4: 3Q27 | U4: 4Q27
A5: Quarter | B5: 1Q23A | C5: 2Q23A | D5: 3Q23A | E5: 4Q23A | F5: 1Q24A | G5: 2Q24A | H5: 3Q24A | I5: 4Q24A | J5: 1Q25A | K5: 2Q25A | L5: 3Q25A | M5: 4Q25A | N5: 1Q26A | O5: 2Q26A | P5: 3Q26E | Q5: 4Q26E | R5: 1Q27E | S5: 2Q27E | T5: 3Q27E | U5: 4Q27E | W5: FY23 | X5: FY24 | Y5: FY25 | Z5: FY26E | AA5: FY27E
A6: 1. The cost stack, cash basis (what adjusted EBITDA is made of)
A7: Revenue | B7: 1818 | C7: 2484 | D7: 3397 | E7: 2218 | F7: 2142 | G7: 2748 | H7: 3732 | I7: 2480 | J7: 2272 | K7: 3096 | L7: 4095 | M7: 2778 | N7: 2678 | O7: 3608 | P7: =INDEX('Scenario Data'!$D$5:$I$345,MATCH('Income Statement'!$G$3&"|revenue",'Scenario Data'!$A$5:$A$345,0),MATCH(P$4,'Scenario Data'!$D$4:$I$4,0)) -> 4804.0355 | Q7: =INDEX('Scenario Data'!$D$5:$I$345,MATCH('Income Statement'!$G$3&"|revenue",'Scenario Data'!$A$5:$A$345,0),MATCH(Q$4,'Scenario Data'!$D$4:$I$4,0)) -> 3178.1078 | R7: =INDEX('Scenario Data'!$D$5:$I$345,MATCH('Income Statement'!$G$3&"|revenue",'Scenario Data'!$A$5:$A$345,0),MATCH(R$4,'Scenario Data'!$D$4:$I$4,0)) -> 3053.1293 | S7: =INDEX('Scenario Data'!$D$5:$I$345,MATCH('Income Statement'!$G$3&"|revenue",'Scenario Data'!$A$5:$A$345,0),MATCH(S$4,'Scenario Data'!$D$4:$I$4,0)) -> 4028.9807 | T7: =INDEX('Scenario Data'!$D$5:$I$345,MATCH('Income Statement'!$G$3&"|revenue",'Scenario Data'!$A$5:$A$345,0),MATCH(T$4,'Scenario Data'!$D$4:$I$4,0)) -> 5280.7325 | U7: =INDEX('Scenario Data'!$D$5:$I$345,MATCH('Income Statement'!$G$3&"|revenue",'Scenario Data'!$A$5:$A$345,0),MATCH(U$4,'Scenario Data'!$D$4:$I$4,0)) -> 3465.7641 | W7: 9917 | X7: 11102 | Y7: 12241 | Z7: =SUM(N7:O7,P7:Q7) -> 14268.143 | AA7: =SUM(R7:U7) -> 15828.607
A8: Cost of revenue | B8: 428 | C8: 432 | D8: 459 | E8: 384 | F8: 480 | G8: 506 | H8: 465 | I8: 427 | J8: 506 | K8: 544 | L8: 549 | M8: 487 | N8: 581 | O8: 633 | P8: =INDEX('Scenario Data'!$D$5:$I$345,MATCH('Income Statement'!$G$3&"|cor_cash",'Scenario Data'!$A$5:$A$345,0),MATCH(P$4,'Scenario Data'!$D$4:$I$4,0)) -> 640.78412 | Q8: =INDEX('Scenario Data'!$D$5:$I$345,MATCH('Income Statement'!$G$3&"|cor_cash",'Scenario Data'!$A$5:$A$345,0),MATCH(Q$4,'Scenario Data'!$D$4:$I$4,0)) -> 578.03946 | R8: =INDEX('Scenario Data'!$D$5:$I$345,MATCH('Income Statement'!$G$3&"|cor_cash",'Scenario Data'!$A$5:$A$345,0),MATCH(R$4,'Scenario Data'!$D$4:$I$4,0)) -> 706.00359 | S8: =INDEX('Scenario Data'!$D$5:$I$345,MATCH('Income Statement'!$G$3&"|cor_cash",'Scenario Data'!$A$5:$A$345,0),MATCH(S$4,'Scenario Data'!$D$4:$I$4,0)) -> 727.29954 | T8: =INDEX('Scenario Data'!$D$5:$I$345,MATCH('Income Statement'!$G$3&"|cor_cash",'Scenario Data'!$A$5:$A$345,0),MATCH(T$4,'Scenario Data'!$D$4:$I$4,0)) -> 699.45368 | U8: =INDEX('Scenario Data'!$D$5:$I$345,MATCH('Income Statement'!$G$3&"|cor_cash",'Scenario Data'!$A$5:$A$345,0),MATCH(U$4,'Scenario Data'!$D$4:$I$4,0)) -> 626.85228 | W8: 1703 | X8: 1878 | Y8: 2086 | Z8: =SUM(N8:O8,P8:Q8) -> 2432.8236 | AA8: =SUM(R8:U8) -> 2759.6091
A9: % of revenue | B9: =IFERROR(B8/B7,"") -> 0.23542354 | C9: =IFERROR(C8/C7,"") -> 0.17391304 | D9: =IFERROR(D8/D7,"") -> 0.13511922 | E9: =IFERROR(E8/E7,"") -> 0.17312894 | F9: =IFERROR(F8/F7,"") -> 0.22408964 | G9: =IFERROR(G8/G7,"") -> 0.18413392 | H9: =IFERROR(H8/H7,"") -> 0.12459807 | I9: =IFERROR(I8/I7,"") -> 0.17217742 | ... U9: =IFERROR(U8/U7,"") -> 0.18086986 | W9: =IFERROR(W8/W7,"") -> 0.17172532 | X9: =IFERROR(X8/X7,"") -> 0.16915871 | Y9: =IFERROR(Y8/Y7,"") -> 0.17041091 | Z9: =IFERROR(Z8/Z7,"") -> 0.17050737 | AA9: =IFERROR(AA8/AA7,"") -> 0.17434315
A10: y/y | F10: =IFERROR(F8/B8-1,"") -> 0.12149533 | G10: =IFERROR(G8/C8-1,"") -> 0.1712963 | H10: =IFERROR(H8/D8-1,"") -> 0.013071895 | I10: =IFERROR(I8/E8-1,"") -> 0.11197917 | J10: =IFERROR(J8/F8-1,"") -> 0.054166667 | K10: =IFERROR(K8/G8-1,"") -> 0.075098814 | L10: =IFERROR(L8/H8-1,"") -> 0.18064516 | M10: =IFERROR(M8/I8-1,"") -> 0.14051522 | ... U10: =IFERROR(U8/Q8-1,"") -> 0.084445489 | X10: =IFERROR(X8/W8-1,"") -> 0.10275984 | Y10: =IFERROR(Y8/X8-1,"") -> 0.11075612 | Z10: =IFERROR(Z8/Y8-1,"") -> 0.1662625 | AA10: =IFERROR(AA8/Z8-1,"") -> 0.13432356
A11: Merchant / payment fees | P11: =INDEX('Scenario Data'!$D$5:$I$345,MATCH('Income Statement'!$G$3&"|cor_fees",'Scenario Data'!$A$5:$A$345,0),MATCH(P$4,'Scenario Data'!$D$4:$I$4,0)) -> 458.76313 | Q11: =INDEX('Scenario Data'!$D$5:$I$345,MATCH('Income Statement'!$G$3&"|cor_fees",'Scenario Data'!$A$5:$A$345,0),MATCH(Q$4,'Scenario Data'!$D$4:$I$4,0)) -> 404.38557 | R11: =INDEX('Scenario Data'!$D$5:$I$345,MATCH('Income Statement'!$G$3&"|cor_fees",'Scenario Data'!$A$5:$A$345,0),MATCH(R$4,'Scenario Data'!$D$4:$I$4,0)) -> 499.64569 | S11: =INDEX('Scenario Data'!$D$5:$I$345,MATCH('Income Statement'!$G$3&"|cor_fees",'Scenario Data'!$A$5:$A$345,0),MATCH(S$4,'Scenario Data'!$D$4:$I$4,0)) -> 527.61555 | T11: =INDEX('Scenario Data'!$D$5:$I$345,MATCH('Income Statement'!$G$3&"|cor_fees",'Scenario Data'!$A$5:$A$345,0),MATCH(T$4,'Scenario Data'!$D$4:$I$4,0)) -> 500.40927 | U11: =INDEX('Scenario Data'!$D$5:$I$345,MATCH('Income Statement'!$G$3&"|cor_fees",'Scenario Data'!$A$5:$A$345,0),MATCH(U$4,'Scenario Data'!$D$4:$I$4,0)) -> 436.87567 | AC11: 1.70% of GBV annual-equivalent, seasonal factors 0.90/1.045/1.035/1.033; 1H26 rate 1.68% after processor rebates
A12: Chargebacks | P12: =INDEX('Scenario Data'!$D$5:$I$345,MATCH('Income Statement'!$G$3&"|cor_chargebacks",'Scenario Data'!$A$5:$A$345,0),MATCH(P$4,'Scenario Data'!$D$4:$I$4,0)) -> 28.960373 | Q12: =INDEX('Scenario Data'!$D$5:$I$345,MATCH('Income Statement'!$G$3&"|cor_chargebacks",'Scenario Data'!$A$5:$A$345,0),MATCH(Q$4,'Scenario Data'!$D$4:$I$4,0)) -> 25.998569 | R12: =INDEX('Scenario Data'!$D$5:$I$345,MATCH('Income Statement'!$G$3&"|cor_chargebacks",'Scenario Data'!$A$5:$A$345,0),MATCH(R$4,'Scenario Data'!$D$4:$I$4,0)) -> 33.80356 | S12: =INDEX('Scenario Data'!$D$5:$I$345,MATCH('Income Statement'!$G$3&"|cor_chargebacks",'Scenario Data'!$A$5:$A$345,0),MATCH(S$4,'Scenario Data'!$D$4:$I$4,0)) -> 31.42002 | T12: =INDEX('Scenario Data'!$D$5:$I$345,MATCH('Income Statement'!$G$3&"|cor_chargebacks",'Scenario Data'!$A$5:$A$345,0),MATCH(T$4,'Scenario Data'!$D$4:$I$4,0)) -> 31.1916 | U12: =INDEX('Scenario Data'!$D$5:$I$345,MATCH('Income Statement'!$G$3&"|cor_chargebacks",'Scenario Data'!$A$5:$A$345,0),MATCH(U$4,'Scenario Data'!$D$4:$I$4,0)) -> 27.9531 | AC12: $0.72 per booking (1H26 +$25M y/y); short case adds $0.15 per booking
A13: Hosting | P13: =INDEX('Scenario Data'!$D$5:$I$345,MATCH('Income Statement'!$G$3&"|cor_hosting",'Scenario Data'!$A$5:$A$345,0),MATCH(P$4,'Scenario Data'!$D$4:$I$4,0)) -> 100.20793 | Q13: =INDEX('Scenario Data'!$D$5:$I$345,MATCH('Income Statement'!$G$3&"|cor_hosting",'Scenario Data'!$A$5:$A$345,0),MATCH(Q$4,'Scenario Data'!$D$4:$I$4,0)) -> 100.20793 | R13: =INDEX('Scenario Data'!$D$5:$I$345,MATCH('Income Statement'!$G$3&"|cor_hosting",'Scenario Data'!$A$5:$A$345,0),MATCH(R$4,'Scenario Data'!$D$4:$I$4,0)) -> 111.70793 | S13: =INDEX('Scenario Data'!$D$5:$I$345,MATCH('Income Statement'!$G$3&"|cor_hosting",'Scenario Data'!$A$5:$A$345,0),MATCH(S$4,'Scenario Data'!$D$4:$I$4,0)) -> 111.70793 | T13: =INDEX('Scenario Data'!$D$5:$I$345,MATCH('Income Statement'!$G$3&"|cor_hosting",'Scenario Data'!$A$5:$A$345,0),MATCH(T$4,'Scenario Data'!$D$4:$I$4,0)) -> 111.70793 | U13: =INDEX('Scenario Data'!$D$5:$I$345,MATCH('Income Statement'!$G$3&"|cor_hosting",'Scenario Data'!$A$5:$A$345,0),MATCH(U$4,'Scenario Data'!$D$4:$I$4,0)) -> 111.70793 | AC13: $224M/yr FY25 + $30M per half step in 2H26 + AI reconciliation step; $330M/yr FY27. The least-sourced number in the build.
A14: Other cost of revenue | P14: =INDEX('Scenario Data'!$D$5:$I$345,MATCH('Income Statement'!$G$3&"|cor_other",'Scenario Data'!$A$5:$A$345,0),MATCH(P$4,'Scenario Data'!$D$4:$I$4,0)) -> 52.85268 | Q14: =INDEX('Scenario Data'!$D$5:$I$345,MATCH('Income Statement'!$G$3&"|cor_other",'Scenario Data'!$A$5:$A$345,0),MATCH(Q$4,'Scenario Data'!$D$4:$I$4,0)) -> 47.447388 | R14: =INDEX('Scenario Data'!$D$5:$I$345,MATCH('Income Statement'!$G$3&"|cor_other",'Scenario Data'!$A$5:$A$345,0),MATCH(R$4,'Scenario Data'!$D$4:$I$4,0)) -> 60.846408 | S14: =INDEX('Scenario Data'!$D$5:$I$345,MATCH('Income Statement'!$G$3&"|cor_other",'Scenario Data'!$A$5:$A$345,0),MATCH(S$4,'Scenario Data'!$D$4:$I$4,0)) -> 56.556036 | T14: =INDEX('Scenario Data'!$D$5:$I$345,MATCH('Income Statement'!$G$3&"|cor_other",'Scenario Data'!$A$5:$A$345,0),MATCH(T$4,'Scenario Data'!$D$4:$I$4,0)) -> 56.14488 | U14: =INDEX('Scenario Data'!$D$5:$I$345,MATCH('Income Statement'!$G$3&"|cor_other",'Scenario Data'!$A$5:$A$345,0),MATCH(U$4,'Scenario Data'!$D$4:$I$4,0)) -> 50.31558 | AC14: $0.36 per night
A15: Operations & support | B15: 267 | C15: 298 | D15: 299 | E15: 254 | F15: 266 | G15: 314 | H15: 347 | I15: 265 | J15: 282 | K15: 309 | L15: 343 | M15: 303 | N15: 301 | O15: 323 | P15: =INDEX('Scenario Data'!$D$5:$I$345,MATCH('Income Statement'!$G$3&"|ops_cash",'Scenario Data'!$A$5:$A$345,0),MATCH(P$4,'Scenario Data'!$D$4:$I$4,0)) -> 361.44309 | Q15: =INDEX('Scenario Data'!$D$5:$I$345,MATCH('Income Statement'!$G$3&"|ops_cash",'Scenario Data'!$A$5:$A$345,0),MATCH(Q$4,'Scenario Data'!$D$4:$I$4,0)) -> 318.28709 | R15: =INDEX('Scenario Data'!$D$5:$I$345,MATCH('Income Statement'!$G$3&"|ops_cash",'Scenario Data'!$A$5:$A$345,0),MATCH(R$4,'Scenario Data'!$D$4:$I$4,0)) -> 319.08609 | S15: =INDEX('Scenario Data'!$D$5:$I$345,MATCH('Income Statement'!$G$3&"|ops_cash",'Scenario Data'!$A$5:$A$345,0),MATCH(S$4,'Scenario Data'!$D$4:$I$4,0)) -> 340.96824 | T15: =INDEX('Scenario Data'!$D$5:$I$345,MATCH('Income Statement'!$G$3&"|ops_cash",'Scenario Data'!$A$5:$A$345,0),MATCH(T$4,'Scenario Data'!$D$4:$I$4,0)) -> 381.7591 | U15: =INDEX('Scenario Data'!$D$5:$I$345,MATCH('Income Statement'!$G$3&"|ops_cash",'Scenario Data'!$A$5:$A$345,0),MATCH(U$4,'Scenario Data'!$D$4:$I$4,0)) -> 336.06248 | W15: 1118 | X15: 1192 | Y15: 1237 | Z15: =SUM(N15:O15,P15:Q15) -> 1303.7302 | AA15: =SUM(R15:U15) -> 1377.8759
A16: % of revenue | B16: =IFERROR(B15/B7,"") -> 0.14686469 | C16: =IFERROR(C15/C7,"") -> 0.11996779 | D16: =IFERROR(D15/D7,"") -> 0.08801884 | E16: =IFERROR(E15/E7,"") -> 0.11451758 | F16: =IFERROR(F15/F7,"") -> 0.12418301 | G16: =IFERROR(G15/G7,"") -> 0.11426492 | H16: =IFERROR(H15/H7,"") -> 0.092979636 | I16: =IFERROR(I15/I7,"") -> 0.10685484 | ... U16: =IFERROR(U15/U7,"") -> 0.096966346 | W16: =IFERROR(W15/W7,"") -> 0.11273571 | X16: =IFERROR(X15/X7,"") -> 0.10736804 | Y16: =IFERROR(Y15/Y7,"") -> 0.10105384 | Z16: =IFERROR(Z15/Z7,"") -> 0.091373499 | AA16: =IFERROR(AA15/AA7,"") -> 0.087049729
A17: y/y | F17: =IFERROR(F15/B15-1,"") -> -0.0037453184 | G17: =IFERROR(G15/C15-1,"") -> 0.053691275 | H17: =IFERROR(H15/D15-1,"") -> 0.16053512 | I17: =IFERROR(I15/E15-1,"") -> 0.043307087 | J17: =IFERROR(J15/F15-1,"") -> 0.060150376 | K17: =IFERROR(K15/G15-1,"") -> -0.015923567 | L17: =IFERROR(L15/H15-1,"") -> -0.011527378 | M17: =IFERROR(M15/I15-1,"") -> 0.14339623 | ... U17: =IFERROR(U15/Q15-1,"") -> 0.055847024 | X17: =IFERROR(X15/W15-1,"") -> 0.066189624 | Y17: =IFERROR(Y15/X15-1,"") -> 0.037751678 | Z17: =IFERROR(Z15/Y15-1,"") -> 0.053945175 | AA17: =IFERROR(AA15/Z15-1,"") -> 0.05687199
A18: Variable part (AI-addressable, 21.5% of the line) | P18: =INDEX('Scenario Data'!$D$5:$I$345,MATCH('Income Statement'!$G$3&"|ops_variable",'Scenario Data'!$A$5:$A$345,0),MATCH(P$4,'Scenario Data'!$D$4:$I$4,0)) -> 70.647687 | Q18: =INDEX('Scenario Data'!$D$5:$I$345,MATCH('Income Statement'!$G$3&"|ops_variable",'Scenario Data'!$A$5:$A$345,0),MATCH(Q$4,'Scenario Data'!$D$4:$I$4,0)) -> 61.403694 | R18: =INDEX('Scenario Data'!$D$5:$I$345,MATCH('Income Statement'!$G$3&"|ops_variable",'Scenario Data'!$A$5:$A$345,0),MATCH(R$4,'Scenario Data'!$D$4:$I$4,0)) -> 63.898291 | S18: =INDEX('Scenario Data'!$D$5:$I$345,MATCH('Income Statement'!$G$3&"|ops_variable",'Scenario Data'!$A$5:$A$345,0),MATCH(S$4,'Scenario Data'!$D$4:$I$4,0)) -> 67.128844 | T18: =INDEX('Scenario Data'!$D$5:$I$345,MATCH('Income Statement'!$G$3&"|ops_variable",'Scenario Data'!$A$5:$A$345,0),MATCH(T$4,'Scenario Data'!$D$4:$I$4,0)) -> 75.327647 | U18: =INDEX('Scenario Data'!$D$5:$I$345,MATCH('Income Statement'!$G$3&"|ops_variable",'Scenario Data'!$A$5:$A$345,0),MATCH(U$4,'Scenario Data'!$D$4:$I$4,0)) -> 66.218683 | AC18: per booking -14% y/y in 2H26, -10% in FY27 (management: support cost per booking -10% and -16% in 1H26)
