Workbook

Sheet Cover
A1: ABNB: the market-implied model
A3: Built 13 Sep 2026 by analysis/src/reverse_dcf/market_implied_model.py from the workstream outputs under data/processed/reverse_dcf/A-D. Rebuild: py -3.13 analysis/src/reverse_dcf/market_implied_model.py
A4: Question: what do the share price, the options market and the sell-side tape imply for FY27 revenue growth, EBITDA and nights, and for the 5 Nov print, against management's cases and the team's forecasts?
A5: Inputs - anchors, the multiple-vs-growth regression (workstream A), decomposition assumptions, EPS map, reaction coefficients (C), options numbers (B). Yellow = editable.
A6: Market_Implied- one row per price point: the joint solve (closed-form quadratic), both FY27 mappings, implied nights, the fixed-multiple fallback, options probabilities, reverse-DCF growth.
A7: Cases - management literal / delivered / ambition, Street, team base / bear / bull: the price each is worth on the joint solve and at 16.5x, and the options-implied probability of reaching it.
A8: Print_5Nov - the reaction function (C) applied to print scenarios; the breakeven guide; the options-implied event sd (B).
A9: SellSide - the target tape percentiles (D) and what each requires at 16.5x.
A10: Options - B's headline numbers, 12-month percentiles, skew by expiry, print base rates.
A11: Comparison - the one table: what is priced by whom.
A12: Recon - Excel recalculated values vs the Python mirror (must be ~0).
A13: Labels: ANCHOR = brief; MEASURED = computed by a workstream; JUDGEMENT = analyst choice. Blue cells are values carried from workstream CSVs; black cells are live formulas.

Sheet Inputs
A1: Inputs
A3: Item | B3: Value | C3: Source / label
A4: Share price ($) | B4: 170.19 | C4: close 11 Sep 2026; ANCHOR
A5: Diluted shares (M) | B5: 597 | C5: 2Q26 diluted WA; ANCHOR
A6: Net cash ex float ($M) | B6: 9593 | C6: 30 Jun 2026; ANCHOR
A7: LTM revenue, 3Q25-2Q26 ($M) | B7: 13159 | C7: letters; the base the NTM multiple was fitted on
A8: LTM adj. EBITDA margin (%) | B8: 35.086253 | C8: 4,617 / 13,159
A9: FY26E revenue base ($M) | B9: 14231.303 | C9: management Delivered case (BRIEF)
A10: FY27E adj. EBITDA margin (%) | B10: 36.2 | C10: management Delivered case; 35.5 / 37.0 sensitivities
A11: Multiple regression intercept a (EV/NTM EBITDA, x) | B11: 12.533 | C11: workstream A primary: EV/NTM EBITDA on NTM growth proxy, 2023-26 monthly, n 45, R2 0.23, NW t 3.1; MEASURED
A12: Multiple regression slope b (turns per pt of NTM growth) | B12: 0.3955 | C12: same; +0.40 vs WS12's +0.48 on the LTM multiple; weakly identified (see audit_A)
A13: Slope band: intercept at b - 1 s.e. | B13: 14.428 | C13: line rotated about the sample means
A14: Slope band: b - 1 s.e. | B14: 0.2662
A15: Slope band: intercept at b + 1 s.e. | B15: 10.639
A16: Slope band: b + 1 s.e. | B16: 0.5248
A17: NTM-to-FY27 growth spread (pp) | B17: 1.421 | C17: Delivered case: NTM growth 14.0% less FY27 12.6%; used by the proportional mapping
A18: FY27 ADR ex-FX growth (%) | B18: 3 | C18: management: mix and price appreciation; team H note
A19: FY27 revenue FX after hedging (pp) | B19: -0.6 | C19: WS29 consensus EUR path
A20: FY27 take-rate change (%) | B20: 0 | C20: management: flat
A21: Fixed-multiple fallback: EV / FY27E EBITDA (x) | B21: 16.5 | C21: WS12 mid
A22: FY27E SBC ($M) | B22: 1935.731 | C22: Delivered case; EPS map
A23: D&A (% revenue) | B23: 0.65 | C23: EPS map
A24: FY27E net interest income ($M) | B24: 516 | C24: 4 x 160 - 4 x 31
A25: Effective tax rate (%) | B25: 18 | C25: high teens
A26: FY27E average diluted shares (M) | B26: 577.051 | C26: Delivered case
A27: Street 4Q26 revenue comparator ($M) | B27: 3154 | C27: Bloomberg FA 4 Sep; Zacks $3,200m alternative
A28: 3Q26 nights growth above which the print is 'accelerating' (%) | B28: 10.6 | C28: workstream C threshold (2Q26 printed 10.34%)
... A30: Reaction S2 (ex-reopening, n 16): intercept (%) | B30: -1.866 | C30: C: E[r] = c + b_sign x sign(accel) + b_gvs x guide-vs-Street %; post-hoc spec, LOO R2 0.22
A31: Reaction S2: b_sign (% per unit sign) | B31: 3.859
A32: Reaction S2: b_gvs (% per 1% guide vs Street) | B32: 2.0596
A33: Reaction S1 (post-2022 sign rule, n 14): intercept (%) | B33: -0.452 | C33: C: pre-stated sign rule; LOO R2 0.28, perm p 0.013
A34: Reaction S1: b_sign (% per unit sign) | B34: 5.6573
A35: Options-implied 5 Nov event sd (%) | C35: B central reading (8.3 to 11.0 across specs); JUDGEMENT
A36: Options-implied expected absolute 5 Nov move (%) | C36: 0.80 x sd

Sheet Market_Implied
A1: Market-implied operating case by price point (joint solve: EV = (a + b g) x base x (1 + g/100) x margin, closed-form root)
A2: Black = live formula. Blue = value carried from a workstream CSV (band from A's delta-method fit, options probabilities from B, reverse-DCF growth from A). The solve identifies NTM growth (guide-proxy units, about 1pp above realised); FY27 is quoted as the range between the proportional and the chained mappings. Rows away from the price are JUDGEMENT (mapping-dependent).
A4: Price ($) | B4: Label | C4: Market cap ($M) | D4: EV ($M) | E4: Implied NTM revenue growth (%) | F4: NTM growth, fitted-line band low (%) | G4: NTM growth, fitted-line band high (%) | H4: Implied EV/NTM EBITDA (x) | I4: FY27 growth, proportional (%) | J4: FY27 growth, chained through Street 2H26 (%) | K4: FY27 revenue, proportional ($M) | L4: FY27 adj. EBITDA ($M) | M4: FY27 GAAP EPS ($) | N4: Implied EV/FY27 EBITDA (x) | O4: FY27 nights growth, proportional (%) | P4: FY27 nights growth, chained (%) | Q4: Fixed 16.5x: FY27 growth (%) | R4: Fixed 16.5x: nights (%) | S4: P(price above this in 12M, options RN) | T4: P(above at 20 Nov, options RN) | U4: Reverse DCF FY28 growth, reported FCF (%) | V4: Reverse DCF, SBC-adj FCF (%)
A5: 125.5 | B5: options-implied 12M p25 (lognormal) | C5: =A5*Inputs!$B$5 -> 74923.5 | D5: =C5-Inputs!$B$6 -> 65330.5 | E5: =(-(Inputs!$B$11/100+Inputs!$B$12)+SQRT((Inputs!$B$11/100+Inputs!$B$12)^2-4*(Inputs!$B$12/100)*(Inputs!$B$11-D5/(Inputs!$B$7*Inputs!$B$8/100))))/(2*(Inputs!$B$12/100)) -> 3.0347058 | F5: -0.6803 | G5: 5.3266 | H5: =Inputs!$B$11+Inputs!$B$12*E5 -> 13.733226 | I5: =E5-Inputs!$B$17 -> 1.6137058 | J5: =((Inputs!$B$7*(1+E5/100)-7921)/6286-1)*100 -> -10.319171 | K5: =Inputs!$B$9*(1+I5/100) -> 14460.954 | L5: =K5*Inputs!$B$10/100 -> 5234.8655 | M5: =((L5-Inputs!$B$22-Inputs!$B$23/100*K5)+Inputs!$B$24)*(1-Inputs!$B$25/100)/Inputs!$B$26 -> 5.2878054 | N5: =D5/L5 -> 12.479881 | O5: =(EXP(LN(1+I5/100)-LN(1+Inputs!$B$18/100)-LN(1+Inputs!$B$19/100)-LN(1+Inputs!$B$20/100))-1)*100 -> -0.7504192 | P5: =(EXP(LN(1+J5/100)-LN(1+Inputs!$B$18/100)-LN(1+Inputs!$B$19/100)-LN(1+Inputs!$B$20/100))-1)*100 -> -12.405668 | Q5: =(D5/Inputs!$B$21/(Inputs!$B$10/100)/Inputs!$B$9-1)*100 -> -23.143819 | R5: =(EXP(LN(1+Q5/100)-LN(1+Inputs!$B$18/100)-LN(1+Inputs!$B$19/100)-LN(1+Inputs!$B$20/100))-1)*100 -> -24.93194 | S5: 0.741 | T5: 0.951
A6: 150 | B6: bear tape | C6: =A6*Inputs!$B$5 -> 89550 | D6: =C6-Inputs!$B$6 -> 79957 | E6: =(-(Inputs!$B$11/100+Inputs!$B$12)+SQRT((Inputs!$B$11/100+Inputs!$B$12)^2-4*(Inputs!$B$12/100)*(Inputs!$B$11-D6/(Inputs!$B$7*Inputs!$B$8/100))))/(2*(Inputs!$B$12/100)) -> 8.6225922 | F6: 7.26 | G6: 9.99 | H6: =Inputs!$B$11+Inputs!$B$12*E6 -> 15.943235 | I6: =E6-Inputs!$B$17 -> 7.2015922 | J6: =((Inputs!$B$7*(1+E6/100)-7921)/6286-1)*100 -> 1.3784109 | K6: =Inputs!$B$9*(1+I6/100) -> 15256.183 | L6: =K6*Inputs!$B$10/100 -> 5522.7384 | M6: =((L6-Inputs!$B$22-Inputs!$B$23/100*K6)+Inputs!$B$24)*(1-Inputs!$B$25/100)/Inputs!$B$26 -> 5.6895328 | N6: =D6/L6 -> 14.477782 | O6: =(EXP(LN(1+I6/100)-LN(1+Inputs!$B$18/100)-LN(1+Inputs!$B$19/100)-LN(1+Inputs!$B$20/100))-1)*100 -> 4.7074605 | P6: =(EXP(LN(1+J6/100)-LN(1+Inputs!$B$18/100)-LN(1+Inputs!$B$19/100)-LN(1+Inputs!$B$20/100))-1)*100 -> -0.98023977 | Q6: =(D6/Inputs!$B$21/(Inputs!$B$10/100)/Inputs!$B$9-1)*100 -> -5.9368949 | R6: =(EXP(LN(1+Q6/100)-LN(1+Inputs!$B$18/100)-LN(1+Inputs!$B$19/100)-LN(1+Inputs!$B$20/100))-1)*100 -> -8.1253491 | S6: 0.599 | T6: 0.75 | U6: 0.65 | V6: 11.87
A7: 163.8 | B7: options-implied 12M p50 (lognormal) | C7: =A7*Inputs!$B$5 -> 97788.6 | D7: =C7-Inputs!$B$6 -> 88195.6 | E7: =(-(Inputs!$B$11/100+Inputs!$B$12)+SQRT((Inputs!$B$11/100+Inputs!$B$12)^2-4*(Inputs!$B$12/100)*(Inputs!$B$11-D7/(Inputs!$B$7*Inputs!$B$8/100))))/(2*(Inputs!$B$12/100)) -> 11.592732 | F7: 10.6518 | G7: 12.1759 | H7: =Inputs!$B$11+Inputs!$B$12*E7 -> 17.117926 | I7: =E7-Inputs!$B$17 -> 10.171732 | J7: =((Inputs!$B$7*(1+E7/100)-7921)/6286-1)*100 -> 7.5960488 | K7: =Inputs!$B$9*(1+I7/100) -> 15678.873 | L7: =K7*Inputs!$B$10/100 -> 5675.752 | M7: =((L7-Inputs!$B$22-Inputs!$B$23/100*K7)+Inputs!$B$24)*(1-Inputs!$B$25/100)/Inputs!$B$26 -> 5.9030638 | N7: =D7/L7 -> 15.539016 | O7: =(EXP(LN(1+I7/100)-LN(1+Inputs!$B$18/100)-LN(1+Inputs!$B$19/100)-LN(1+Inputs!$B$20/100))-1)*100 -> 7.6084977 | P7: =(EXP(LN(1+J7/100)-LN(1+Inputs!$B$18/100)-LN(1+Inputs!$B$19/100)-LN(1+Inputs!$B$20/100))-1)*100 -> 5.0927397 | Q7: =(D7/Inputs!$B$21/(Inputs!$B$10/100)/Inputs!$B$9-1)*100 -> 3.7551683 | R7: =(EXP(LN(1+Q7/100)-LN(1+Inputs!$B$18/100)-LN(1+Inputs!$B$19/100)-LN(1+Inputs!$B$20/100))-1)*100 -> 1.3412204 | S7: 0.517 | T7: 0.582
A8: 165 | B8: p25 sell-side target | C8: =A8*Inputs!$B$5 -> 98505 | D8: =C8-Inputs!$B$6 -> 88912 | E8: =(-(Inputs!$B$11/100+Inputs!$B$12)+SQRT((Inputs!$B$11/100+Inputs!$B$12)^2-4*(Inputs!$B$12/100)*(Inputs!$B$11-D8/(Inputs!$B$7*Inputs!$B$8/100))))/(2*(Inputs!$B$12/100)) -> 11.845639 | F8: 10.52 | G8: 13.17 | H8: =Inputs!$B$11+Inputs!$B$12*E8 -> 17.21795 | I8: =E8-Inputs!$B$17 -> 10.424639 | J8: =((Inputs!$B$7*(1+E8/100)-7921)/6286-1)*100 -> 8.1254797 | K8: =Inputs!$B$9*(1+I8/100) -> 15714.865 | L8: =K8*Inputs!$B$10/100 -> 5688.7811 | M8: =((L8-Inputs!$B$22-Inputs!$B$23/100*K8)+Inputs!$B$24)*(1-Inputs!$B$25/100)/Inputs!$B$26 -> 5.9212459 | N8: =D8/L8 -> 15.629359 | O8: =(EXP(LN(1+I8/100)-LN(1+Inputs!$B$18/100)-LN(1+Inputs!$B$19/100)-LN(1+Inputs!$B$20/100))-1)*100 -> 7.8555206 | P8: =(EXP(LN(1+J8/100)-LN(1+Inputs!$B$18/100)-LN(1+Inputs!$B$19/100)-LN(1+Inputs!$B$20/100))-1)*100 -> 5.609853 | Q8: =(D8/Inputs!$B$21/(Inputs!$B$10/100)/Inputs!$B$9-1)*100 -> 4.5979564 | R8: =(EXP(LN(1+Q8/100)-LN(1+Inputs!$B$18/100)-LN(1+Inputs!$B$19/100)-LN(1+Inputs!$B$20/100))-1)*100 -> 2.1644003 | S8: 0.51 | T8: 0.565 | U8: 3.64 | V8: 14.95
A9: 170.19 | B9: price, close 11 Sep 2026 | C9: =A9*Inputs!$B$5 -> 101603.43 | D9: =C9-Inputs!$B$6 -> 92010.43 | E9: =(-(Inputs!$B$11/100+Inputs!$B$12)+SQRT((Inputs!$B$11/100+Inputs!$B$12)^2-4*(Inputs!$B$12/100)*(Inputs!$B$11-D9/(Inputs!$B$7*Inputs!$B$8/100))))/(2*(Inputs!$B$12/100)) -> 12.930112 | F9: 11.53 | G9: 14.34 | H9: =Inputs!$B$11+Inputs!$B$12*E9 -> 17.646859 | I9: =E9-Inputs!$B$17 -> 11.509112 | J9: =((Inputs!$B$7*(1+E9/100)-7921)/6286-1)*100 -> 10.395696 | K9: =Inputs!$B$9*(1+I9/100) -> 15869.2 | L9: =K9*Inputs!$B$10/100 -> 5744.6503 | M9: =((L9-Inputs!$B$22-Inputs!$B$23/100*K9)+Inputs!$B$24)*(1-Inputs!$B$25/100)/Inputs!$B$26 -> 5.9992115 | N9: =D9/L9 -> 16.016716 | O9: =(EXP(LN(1+I9/100)-LN(1+Inputs!$B$18/100)-LN(1+Inputs!$B$19/100)-LN(1+Inputs!$B$20/100))-1)*100 -> 8.9147626 | P9: =(EXP(LN(1+J9/100)-LN(1+Inputs!$B$18/100)-LN(1+Inputs!$B$19/100)-LN(1+Inputs!$B$20/100))-1)*100 -> 7.8272513 | Q9: =(D9/Inputs!$B$21/(Inputs!$B$10/100)/Inputs!$B$9-1)*100 -> 8.2430149 | R9: =(EXP(LN(1+Q9/100)-LN(1+Inputs!$B$18/100)-LN(1+Inputs!$B$19/100)-LN(1+Inputs!$B$20/100))-1)*100 -> 5.7246537 | S9: 0.48 | T9: 0.493 | U9: 4.61 | V9: 15.95
A10: 179.5 | B10: mean sell-side target | C10: =A10*Inputs!$B$5 -> 107161.5 | D10: =C10-Inputs!$B$6 -> 97568.5 | E10: =(-(Inputs!$B$11/100+Inputs!$B$12)+SQRT((Inputs!$B$11/100+Inputs!$B$12)^2-4*(Inputs!$B$12/100)*(Inputs!$B$11-D10/(Inputs!$B$7*Inputs!$B$8/100))))/(2*(Inputs!$B$12/100)) -> 14.838959 | F10: 13.21 | G10: 16.48 | H10: =Inputs!$B$11+Inputs!$B$12*E10 -> 18.401808 | I10: =E10-Inputs!$B$17 -> 13.417959 | J10: =((Inputs!$B$7*(1+E10/100)-7921)/6286-1)*100 -> 14.391643 | K10: =Inputs!$B$9*(1+I10/100) -> 16140.853 | L10: =K10*Inputs!$B$10/100 -> 5842.9889 | M10: =((L10-Inputs!$B$22-Inputs!$B$23/100*K10)+Inputs!$B$24)*(1-Inputs!$B$25/100)/Inputs!$B$26 -> 6.1364433 | N10: =D10/L10 -> 16.698389 | O10: =(EXP(LN(1+I10/100)-LN(1+Inputs!$B$18/100)-LN(1+Inputs!$B$19/100)-LN(1+Inputs!$B$20/100))-1)*100 -> 10.779199 | P10: =(EXP(LN(1+J10/100)-LN(1+Inputs!$B$18/100)-LN(1+Inputs!$B$19/100)-LN(1+Inputs!$B$20/100))-1)*100 -> 11.730229 | Q10: =(D10/Inputs!$B$21/(Inputs!$B$10/100)/Inputs!$B$9-1)*100 -> 14.781646 | R10: =(EXP(LN(1+Q10/100)-LN(1+Inputs!$B$18/100)-LN(1+Inputs!$B$19/100)-LN(1+Inputs!$B$20/100))-1)*100 -> 12.111158 | S10: 0.428 | T10: 0.366 | U10: 6.28 | V10: 17.66
A11: 185 | B11: median yfinance target | C11: =A11*Inputs!$B$5 -> 110445 | D11: =C11-Inputs!$B$6 -> 100852 | E11: =(-(Inputs!$B$11/100+Inputs!$B$12)+SQRT((Inputs!$B$11/100+Inputs!$B$12)^2-4*(Inputs!$B$12/100)*(Inputs!$B$11-D11/(Inputs!$B$7*Inputs!$B$8/100))))/(2*(Inputs!$B$12/100)) -> 15.945705 | F11: 14.15 | G11: 17.76 | H11: =Inputs!$B$11+Inputs!$B$12*E11 -> 18.839526 | I11: =E11-Inputs!$B$17 -> 14.524705 | J11: =((Inputs!$B$7*(1+E11/100)-7921)/6286-1)*100 -> 16.708484 | K11: =Inputs!$B$9*(1+I11/100) -> 16298.358 | L11: =K11*Inputs!$B$10/100 -> 5900.0055 | M11: =((L11-Inputs!$B$22-Inputs!$B$23/100*K11)+Inputs!$B$24)*(1-Inputs!$B$25/100)/Inputs!$B$26 -> 6.2160101 | N11: =D11/L11 -> 17.093543 | O11: =(EXP(LN(1+I11/100)-LN(1+Inputs!$B$18/100)-LN(1+Inputs!$B$19/100)-LN(1+Inputs!$B$20/100))-1)*100 -> 11.860195 | P11: =(EXP(LN(1+J11/100)-LN(1+Inputs!$B$18/100)-LN(1+Inputs!$B$19/100)-LN(1+Inputs!$B$20/100))-1)*100 -> 13.993166 | Q11: =(D11/Inputs!$B$21/(Inputs!$B$10/100)/Inputs!$B$9-1)*100 -> 18.644425 | R11: =(EXP(LN(1+Q11/100)-LN(1+Inputs!$B$18/100)-LN(1+Inputs!$B$19/100)-LN(1+Inputs!$B$20/100))-1)*100 -> 15.884066 | S11: 0.399 | T11: 0.297 | U11: 7.22 | V11: 18.64
A12: 197.5 | B12: p75 sell-side target | C12: =A12*Inputs!$B$5 -> 117907.5 | D12: =C12-Inputs!$B$6 -> 108314.5 | E12: =(-(Inputs!$B$11/100+Inputs!$B$12)+SQRT((Inputs!$B$11/100+Inputs!$B$12)^2-4*(Inputs!$B$12/100)*(Inputs!$B$11-D12/(Inputs!$B$7*Inputs!$B$8/100))))/(2*(Inputs!$B$12/100)) -> 18.406984 | F12: 16.19 | G12: 20.65 | H12: =Inputs!$B$11+Inputs!$B$12*E12 -> 19.812962 | I12: =E12-Inputs!$B$17 -> 16.985984 | J12: =((Inputs!$B$7*(1+E12/100)-7921)/6286-1)*100 -> 21.860881 | K12: =Inputs!$B$9*(1+I12/100) -> 16648.63 | L12: =K12*Inputs!$B$10/100 -> 6026.804 | M12: =((L12-Inputs!$B$22-Inputs!$B$23/100*K12)+Inputs!$B$24)*(1-Inputs!$B$25/100)/Inputs!$B$26 -> 6.3929577 | N12: =D12/L12 -> 17.972129 | O12: =(EXP(LN(1+I12/100)-LN(1+Inputs!$B$18/100)-LN(1+Inputs!$B$19/100)-LN(1+Inputs!$B$20/100))-1)*100 -> 14.26421 | P12: =(EXP(LN(1+J12/100)-LN(1+Inputs!$B$18/100)-LN(1+Inputs!$B$19/100)-LN(1+Inputs!$B$20/100))-1)*100 -> 19.025689 | Q12: =(D12/Inputs!$B$21/(Inputs!$B$10/100)/Inputs!$B$9-1)*100 -> 27.423468 | R12: =(EXP(LN(1+Q12/100)-LN(1+Inputs!$B$18/100)-LN(1+Inputs!$B$19/100)-LN(1+Inputs!$B$20/100))-1)*100 -> 24.458858 | S12: 0.336 | T12: 0.17 | U12: 9.26 | V12: 20.74
A13: 213.9 | B13: options-implied 12M p75 (lognormal) | C13: =A13*Inputs!$B$5 -> 127698.3 | D13: =C13-Inputs!$B$6 -> 118105.3 | E13: =(-(Inputs!$B$11/100+Inputs!$B$12)+SQRT((Inputs!$B$11/100+Inputs!$B$12)^2-4*(Inputs!$B$12/100)*(Inputs!$B$11-D13/(Inputs!$B$7*Inputs!$B$8/100))))/(2*(Inputs!$B$12/100)) -> 21.531091 | F13: 20.2594 | G13: 23.5675 | H13: =Inputs!$B$11+Inputs!$B$12*E13 -> 21.048547 | I13: =E13-Inputs!$B$17 -> 20.110091 | J13: =((Inputs!$B$7*(1+E13/100)-7921)/6286-1)*100 -> 28.400832 | K13: =Inputs!$B$9*(1+I13/100) -> 17093.231 | L13: =K13*Inputs!$B$10/100 -> 6187.7496 | M13: =((L13-Inputs!$B$22-Inputs!$B$23/100*K13)+Inputs!$B$24)*(1-Inputs!$B$25/100)/Inputs!$B$26 -> 6.6175578 | N13: =D13/L13 -> 19.086955 | O13: =(EXP(LN(1+I13/100)-LN(1+Inputs!$B$18/100)-LN(1+Inputs!$B$19/100)-LN(1+Inputs!$B$20/100))-1)*100 -> 17.315633 | P13: =(EXP(LN(1+J13/100)-LN(1+Inputs!$B$18/100)-LN(1+Inputs!$B$19/100)-LN(1+Inputs!$B$20/100))-1)*100 -> 25.413483 | Q13: =(D13/Inputs!$B$21/(Inputs!$B$10/100)/Inputs!$B$9-1)*100 -> 38.941572 | R13: =(EXP(LN(1+Q13/100)-LN(1+Inputs!$B$18/100)-LN(1+Inputs!$B$19/100)-LN(1+Inputs!$B$20/100))-1)*100 -> 35.708984 | S13: 0.263 | T13: 0.069
A14: 220 | B14: top sell-side target | C14: =A14*Inputs!$B$5 -> 131340 | D14: =C14-Inputs!$B$6 -> 121747 | E14: =(-(Inputs!$B$11/100+Inputs!$B$12)+SQRT((Inputs!$B$11/100+Inputs!$B$12)^2-4*(Inputs!$B$12/100)*(Inputs!$B$11-D14/(Inputs!$B$7*Inputs!$B$8/100))))/(2*(Inputs!$B$12/100)) -> 22.664976 | F14: 19.64 | G14: 25.73 | H14: =Inputs!$B$11+Inputs!$B$12*E14 -> 21.496998 | I14: =E14-Inputs!$B$17 -> 21.243976 | J14: =((Inputs!$B$7*(1+E14/100)-7921)/6286-1)*100 -> 30.774486 | K14: =Inputs!$B$9*(1+I14/100) -> 17254.598 | L14: =K14*Inputs!$B$10/100 -> 6246.1643 | M14: =((L14-Inputs!$B$22-Inputs!$B$23/100*K14)+Inputs!$B$24)*(1-Inputs!$B$25/100)/Inputs!$B$26 -> 6.6990757 | N14: =D14/L14 -> 19.491482 | O14: =(EXP(LN(1+I14/100)-LN(1+Inputs!$B$18/100)-LN(1+Inputs!$B$19/100)-LN(1+Inputs!$B$20/100))-1)*100 -> 18.423137 | P14: =(EXP(LN(1+J14/100)-LN(1+Inputs!$B$18/100)-LN(1+Inputs!$B$19/100)-LN(1+Inputs!$B$20/100))-1)*100 -> 27.731912 | Q14: =(D14/Inputs!$B$21/(Inputs!$B$10/100)/Inputs!$B$9-1)*100 -> 43.225744 | R14: =(EXP(LN(1+Q14/100)-LN(1+Inputs!$B$18/100)-LN(1+Inputs!$B$19/100)-LN(1+Inputs!$B$20/100))-1)*100 -> 39.893482 | S14: 0.239 | T14: 0.047 | U14: 12.63 | V14: 24.22

Sheet Cases
A1: What each case is worth on the market's own pricing rule, and the options-implied probability of getting there
A2: Joint-solve price = ((a + b g_ntm) x LTM revenue x (1 + g_ntm/100) x LTM margin + net cash) / shares with g_ntm = FY27 growth + spread. Fixed = 16.5x on the case's revenue at 36.2% (and on its own EBITDA).
A4: Case | B4: FY27 revenue growth on FY26 Delivered base (%) | C4: FY27 EBITDA, case's own ($M) | D4: Price on the joint solve ($) | E4: Upside vs price (%) | F4: Price at 16.5x, case revenue at 36.2% ($) | G4: Price at 16.5x, case's own EBITDA ($) | H4: Implied FY27 nights growth (%) | I4: P(above joint-solve price in 12M, options RN)
A5: Management literal | B5: 9.8311 | C5: 5548.8 | D5: =((Inputs!$B$11+Inputs!$B$12*(B5+Inputs!$B$17))*Inputs!$B$7*(1+(B5+Inputs!$B$17)/100)*Inputs!$B$8/100+Inputs!$B$6)/Inputs!$B$5 -> 162.18994 | E5: =(D5/Inputs!$B$4-1)*100 -> -4.7006622 | F5: =(Inputs!$B$21*Inputs!$B$9*(1+B5/100)*Inputs!$B$10/100+Inputs!$B$6)/Inputs!$B$5 -> 172.45119 | G5: =(Inputs!$B$21*C5+Inputs!$B$6)/Inputs!$B$5 -> 169.42747 | H5: =(EXP(LN(1+B5/100)-LN(1+Inputs!$B$18/100)-LN(1+Inputs!$B$19/100)-LN(1+Inputs!$B$20/100))-1)*100 -> 7.2757907 | I5: 0.527
A6: Management delivered | B6: 12.6021 | C6: 5801 | D6: =((Inputs!$B$11+Inputs!$B$12*(B6+Inputs!$B$17))*Inputs!$B$7*(1+(B6+Inputs!$B$17)/100)*Inputs!$B$8/100+Inputs!$B$6)/Inputs!$B$5 -> 175.49354 | E6: =(D6/Inputs!$B$4-1)*100 -> 3.1162482 | F6: =(Inputs!$B$21*Inputs!$B$9*(1+B6/100)*Inputs!$B$10/100+Inputs!$B$6)/Inputs!$B$5 -> 176.39666 | G6: =(Inputs!$B$21*C6+Inputs!$B$6)/Inputs!$B$5 -> 176.39782 | H6: =(EXP(LN(1+B6/100)-LN(1+Inputs!$B$18/100)-LN(1+Inputs!$B$19/100)-LN(1+Inputs!$B$20/100))-1)*100 -> 9.9823211 | I6: 0.45
A7: Management ambition | B7: 17.9838 | C7: 6212.5 | D7: =((Inputs!$B$11+Inputs!$B$12*(B7+Inputs!$B$17))*Inputs!$B$7*(1+(B7+Inputs!$B$17)/100)*Inputs!$B$8/100+Inputs!$B$6)/Inputs!$B$5 -> 202.67314 | E7: =(D7/Inputs!$B$4-1)*100 -> 19.086399 | F7: =(Inputs!$B$21*Inputs!$B$9*(1+B7/100)*Inputs!$B$10/100+Inputs!$B$6)/Inputs!$B$5 -> 184.05937 | G7: =(Inputs!$B$21*C7+Inputs!$B$6)/Inputs!$B$5 -> 187.77094 | H7: =(EXP(LN(1+B7/100)-LN(1+Inputs!$B$18/100)-LN(1+Inputs!$B$19/100)-LN(1+Inputs!$B$20/100))-1)*100 -> 15.238812 | I7: 0.313
A8: Street FY27 $15,745m | B8: 10.6364 | C8: 5699.7 | D8: =((Inputs!$B$11+Inputs!$B$12*(B8+Inputs!$B$17))*Inputs!$B$7*(1+(B8+Inputs!$B$17)/100)*Inputs!$B$8/100+Inputs!$B$6)/Inputs!$B$5 -> 166.00778 | E8: =(D8/Inputs!$B$4-1)*100 -> -2.4573837 | F8: =(Inputs!$B$21*Inputs!$B$9*(1+B8/100)*Inputs!$B$10/100+Inputs!$B$6)/Inputs!$B$5 -> 173.59781 | G8: =(Inputs!$B$21*C8+Inputs!$B$6)/Inputs!$B$5 -> 173.59807 | H8: =(EXP(LN(1+B8/100)-LN(1+Inputs!$B$18/100)-LN(1+Inputs!$B$19/100)-LN(1+Inputs!$B$20/100))-1)*100 -> 8.0623547 | I8: 0.504
A9: Team base (WS29/30) $15,804m | B9: 11.0488 | C9: 5757.9 | D9: =((Inputs!$B$11+Inputs!$B$12*(B9+Inputs!$B$17))*Inputs!$B$7*(1+(B9+Inputs!$B$17)/100)*Inputs!$B$8/100+Inputs!$B$6)/Inputs!$B$5 -> 167.97828 | E9: =(D9/Inputs!$B$4-1)*100 -> -1.2995593 | F9: =(Inputs!$B$21*Inputs!$B$9*(1+B9/100)*Inputs!$B$10/100+Inputs!$B$6)/Inputs!$B$5 -> 174.185 | G9: =(Inputs!$B$21*C9+Inputs!$B$6)/Inputs!$B$5 -> 175.20662 | H9: =(EXP(LN(1+B9/100)-LN(1+Inputs!$B$18/100)-LN(1+Inputs!$B$19/100)-LN(1+Inputs!$B$20/100))-1)*100 -> 8.4651599 | I9: 0.493
A10: Team bear (WS29) $14,318m | B10: 0.6115 | C10: 4375 | D10: =((Inputs!$B$11+Inputs!$B$12*(B10+Inputs!$B$17))*Inputs!$B$7*(1+(B10+Inputs!$B$17)/100)*Inputs!$B$8/100+Inputs!$B$6)/Inputs!$B$5 -> 121.30786 | E10: =(D10/Inputs!$B$4-1)*100 -> -28.7221 | F10: =(Inputs!$B$21*Inputs!$B$9*(1+B10/100)*Inputs!$B$10/100+Inputs!$B$6)/Inputs!$B$5 -> 159.3239 | G10: =(Inputs!$B$21*C10+Inputs!$B$6)/Inputs!$B$5 -> 136.98576 | H10: =(EXP(LN(1+B10/100)-LN(1+Inputs!$B$18/100)-LN(1+Inputs!$B$19/100)-LN(1+Inputs!$B$20/100))-1)*100 -> -1.7293079 | I10: 0.75
A11: Team bull (WS29) $16,910m | B11: 18.8209 | C11: 6977.4 | D11: =((Inputs!$B$11+Inputs!$B$12*(B11+Inputs!$B$17))*Inputs!$B$7*(1+(B11+Inputs!$B$17)/100)*Inputs!$B$8/100+Inputs!$B$6)/Inputs!$B$5 -> 207.06004 | E11: =(D11/Inputs!$B$4-1)*100 -> 21.664044 | F11: =(Inputs!$B$21*Inputs!$B$9*(1+B11/100)*Inputs!$B$10/100+Inputs!$B$6)/Inputs!$B$5 -> 185.25127 | G11: =(Inputs!$B$21*C11+Inputs!$B$6)/Inputs!$B$5 -> 208.91139 | H11: =(EXP(LN(1+B11/100)-LN(1+Inputs!$B$18/100)-LN(1+Inputs!$B$19/100)-LN(1+Inputs!$B$20/100))-1)*100 -> 16.056436 | I11: 0.293

Sheet Print_5Nov
A1: 5 Nov 2026 print: expected day-1 excess reaction by scenario (workstream C's function) and the options-implied dispersion (B)
A2: Headline = S1, the pre-stated printed-nights-acceleration sign rule (post-2022, n 14; QQQ-excess close-to-close; a base rate, not multiplicity-robust). S2 (two-variable, post-hoc, n 16) is illustrative and flips sign with the Zacks $3,200m comparator. Expectations are conditional on the print's acceleration sign; unconditional under the nowcast band is about -2 to -2.5%. Decelerating prints gap about -5% and recover about +1.7% intraday, so the move is close-to-close and captured only by holding through the print.
A4: Scenario | B4: 3Q26 nights growth (%) | C4: Acceleration sign | D4: 4Q26 revenue guide midpoint ($M) | E4: Guide vs Street (%) | F4: E[day-1 excess return], S2 ex-reopening, illustrative (%) | G4: HEADLINE E[...], S1 post-2022 sign rule (%) | H4: E[...], S2 post-2022, illustrative (%) | I4: Options-implied event sd (%) | J4: Breakeven guide vs Street for zero E[r], S2 (%) | K4: Breakeven 4Q26 guide ($M)
A5: Team base (WS29/30) | B5: 9.9 | C5: =IF(B5>Inputs!$B$28,1,IF(B5<Inputs!$B$29,-1,0)) -> -1 | D5: 3111 | E5: =(D5/Inputs!$B$27-1)*100 -> -1.3633481 | F5: =Inputs!$B$30+Inputs!$B$31*C5+Inputs!$B$32*E5 -> -8.5329518 | G5: =Inputs!$B$33+Inputs!$B$34*C5 -> -6.1093 | H5: =-0.964+5.4638*C5+1.3225*E5 -> -8.2308279 | I5: =Inputs!$B$35 -> 0 | J5: =-(Inputs!$B$30+Inputs!$B$31*C5)/Inputs!$B$32 -> 2.779666 | K5: =Inputs!$B$27*(1+J5/100) -> 3241.6707
A6: Team base, ex-NA lap adopted | B6: 9.9 | C6: =IF(B6>Inputs!$B$28,1,IF(B6<Inputs!$B$29,-1,0)) -> -1 | D6: 3055 | E6: =(D6/Inputs!$B$27-1)*100 -> -3.1388713 | F6: =Inputs!$B$30+Inputs!$B$31*C6+Inputs!$B$32*E6 -> -12.189819 | G6: =Inputs!$B$33+Inputs!$B$34*C6 -> -6.1093 | H6: =-0.964+5.4638*C6+1.3225*E6 -> -10.578957 | I6: =Inputs!$B$35 -> 0 | J6: =-(Inputs!$B$30+Inputs!$B$31*C6)/Inputs!$B$32 -> 2.779666 | K6: =Inputs!$B$27*(1+J6/100) -> 3241.6707
A7: Q3 nowcast central (reviews index), 4Q26 at team revenue | B7: 9.75 | C7: =IF(B7>Inputs!$B$28,1,IF(B7<Inputs!$B$29,-1,0)) -> -1 | D7: 3107 | E7: =(D7/Inputs!$B$27-1)*100 -> -1.4901712 | F7: =Inputs!$B$30+Inputs!$B$31*C7+Inputs!$B$32*E7 -> -8.7941566 | G7: =Inputs!$B$33+Inputs!$B$34*C7 -> -6.1093 | H7: =-0.964+5.4638*C7+1.3225*E7 -> -8.3985514 | I7: =Inputs!$B$35 -> 0 | J7: =-(Inputs!$B$30+Inputs!$B$31*C7)/Inputs!$B$32 -> 2.779666 | K7: =Inputs!$B$27*(1+J7/100) -> 3241.6707
A8: Street (Bloomberg FA 4 Sep) | B8: 11.1 | C8: =IF(B8>Inputs!$B$28,1,IF(B8<Inputs!$B$29,-1,0)) -> 1 | D8: 3154 | E8: =(D8/Inputs!$B$27-1)*100 -> 0 | F8: =Inputs!$B$30+Inputs!$B$31*C8+Inputs!$B$32*E8 -> 1.993 | G8: =Inputs!$B$33+Inputs!$B$34*C8 -> 5.2053 | H8: =-0.964+5.4638*C8+1.3225*E8 -> 4.4998 | I8: =Inputs!$B$35 -> 0 | J8: =-(Inputs!$B$30+Inputs!$B$31*C8)/Inputs!$B$32 -> -0.96766362 | K8: =Inputs!$B$27*(1+J8/100) -> 3123.4799
A9: Management delivered | B9: 11.5 | C9: =IF(B9>Inputs!$B$28,1,IF(B9<Inputs!$B$29,-1,0)) -> 1 | D9: 3130 | E9: =(D9/Inputs!$B$27-1)*100 -> -0.76093849 | F9: =Inputs!$B$30+Inputs!$B$31*C9+Inputs!$B$32*E9 -> 0.42577108 | G9: =Inputs!$B$33+Inputs!$B$34*C9 -> 5.2053 | H9: =-0.964+5.4638*C9+1.3225*E9 -> 3.4934588 | I9: =Inputs!$B$35 -> 0 | J9: =-(Inputs!$B$30+Inputs!$B$31*C9)/Inputs!$B$32 -> -0.96766362 | K9: =Inputs!$B$27*(1+J9/100) -> 3123.4799
A10: Flat print: 3Q26 = 2Q26 rate, guide at Street | B10: 10.34 | C10: =IF(B10>Inputs!$B$28,1,IF(B10<Inputs!$B$29,-1,0)) -> 0 | D10: 3154 | E10: =(D10/Inputs!$B$27-1)*100 -> 0 | F10: =Inputs!$B$30+Inputs!$B$31*C10+Inputs!$B$32*E10 -> -1.866 | G10: =Inputs!$B$33+Inputs!$B$34*C10 -> -0.452 | H10: =-0.964+5.4638*C10+1.3225*E10 -> -0.964 | I10: =Inputs!$B$35 -> 0 | J10: =-(Inputs!$B$30+Inputs!$B$31*C10)/Inputs!$B$32 -> 0.90600117 | K10: =Inputs!$B$27*(1+J10/100) -> 3182.5753
A11: Accelerating print, guide 2% below Street | B11: 11 | C11: =IF(B11>Inputs!$B$28,1,IF(B11<Inputs!$B$29,-1,0)) -> 1 | D11: 3091 | E11: =(D11/Inputs!$B$27-1)*100 -> -1.9974635 | F11: =Inputs!$B$30+Inputs!$B$31*C11+Inputs!$B$32*E11 -> -2.1209759 | G11: =Inputs!$B$33+Inputs!$B$34*C11 -> 5.2053 | H11: =-0.964+5.4638*C11+1.3225*E11 -> 1.8581545 | I11: =Inputs!$B$35 -> 0 | J11: =-(Inputs!$B$30+Inputs!$B$31*C11)/Inputs!$B$32 -> -0.96766362 | K11: =Inputs!$B$27*(1+J11/100) -> 3123.4799
A12: Decelerating print, guide 3% above Street | B12: 9.9 | C12: =IF(B12>Inputs!$B$28,1,IF(B12<Inputs!$B$29,-1,0)) -> -1 | D12: 3249 | E12: =(D12/Inputs!$B$27-1)*100 -> 3.0120482 | F12: =Inputs!$B$30+Inputs!$B$31*C12+Inputs!$B$32*E12 -> 0.47861446 | G12: =Inputs!$B$33+Inputs!$B$34*C12 -> -6.1093 | H12: =-0.964+5.4638*C12+1.3225*E12 -> -2.4443663 | I12: =Inputs!$B$35 -> 0 | J12: =-(Inputs!$B$30+Inputs!$B$31*C12)/Inputs!$B$32 -> 2.779666 | K12: =Inputs!$B$27*(1+J12/100) -> 3241.6707
A13: 2Q26 replay: accelerating print, guide +2.6% vs Street | B13: 11 | C13: =IF(B13>Inputs!$B$28,1,IF(B13<Inputs!$B$29,-1,0)) -> 1 | D13: 3236 | E13: =(D13/Inputs!$B$27-1)*100 -> 2.5998732 | F13: =Inputs!$B$30+Inputs!$B$31*C13+Inputs!$B$32*E13 -> 7.3476988 | G13: =Inputs!$B$33+Inputs!$B$34*C13 -> 5.2053 | H13: =-0.964+5.4638*C13+1.3225*E13 -> 7.9381323 | I13: =Inputs!$B$35 -> 0 | J13: =-(Inputs!$B$30+Inputs!$B$31*C13)/Inputs!$B$32 -> -0.96766362 | K13: =Inputs!$B$27*(1+J13/100) -> 3123.4799

Sheet SellSide
A1: Sell-side tape (workstream D, 12 Sep 2026 pull, Goldman corrected to Neutral $165) and what each level requires at the fixed multiple
A3: Stat | B3: Target ($) | C3: Upside vs price (%) | D3: Implied EV / FY27 Delivered EBITDA (x) | E3: At 16.5x: required FY27 revenue ($M) | F3: At 16.5x: FY27 growth (%) | G3: At 16.5x: FY27 nights growth (%) | H3: Joint solve: FY27 growth, proportional (%)
A4: min | B4: 125 | C4: =(B4/Inputs!$B$4-1)*100 -> -26.552676 | D4: =(B4*Inputs!$B$5-Inputs!$B$6)/5800.957 -> 11.210564 | E4: =(B4*Inputs!$B$5-Inputs!$B$6)/Inputs!$B$21/(Inputs!$B$10/100) -> 10887.661 | F4: =(E4/Inputs!$B$9-1)*100 -> -23.49498 | G4: =(EXP(LN(1+F4/100)-LN(1+Inputs!$B$18/100)-LN(1+Inputs!$B$19/100)-LN(1+Inputs!$B$20/100))-1)*100 -> -25.274932 | H4: =(-(Inputs!$B$11/100+Inputs!$B$12)+SQRT((Inputs!$B$11/100+Inputs!$B$12)^2-4*(Inputs!$B$12/100)*(Inputs!$B$11-(B4*Inputs!$B$5-Inputs!$B$6)/(Inputs!$B$7*Inputs!$B$8/100))))/(2*(Inputs!$B$12/100))-Inputs!$B$17 -> 1.4949392
A5: p25 | B5: 165 | C5: =(B5/Inputs!$B$4-1)*100 -> -3.0495329 | D5: =(B5*Inputs!$B$5-Inputs!$B$6)/5800.957 -> 15.327126 | E5: =(B5*Inputs!$B$5-Inputs!$B$6)/Inputs!$B$21/(Inputs!$B$10/100) -> 14885.652 | F5: =(E5/Inputs!$B$9-1)*100 -> 4.5979564 | G5: =(EXP(LN(1+F5/100)-LN(1+Inputs!$B$18/100)-LN(1+Inputs!$B$19/100)-LN(1+Inputs!$B$20/100))-1)*100 -> 2.1644003 | H5: =(-(Inputs!$B$11/100+Inputs!$B$12)+SQRT((Inputs!$B$11/100+Inputs!$B$12)^2-4*(Inputs!$B$12/100)*(Inputs!$B$11-(B5*Inputs!$B$5-Inputs!$B$6)/(Inputs!$B$7*Inputs!$B$8/100))))/(2*(Inputs!$B$12/100))-Inputs!$B$17 -> 10.424639
A6: median | B6: 182.5 | C6: =(B6/Inputs!$B$4-1)*100 -> 7.2330924 | D6: =(B6*Inputs!$B$5-Inputs!$B$6)/5800.957 -> 17.128122 | E6: =(B6*Inputs!$B$5-Inputs!$B$6)/Inputs!$B$21/(Inputs!$B$10/100) -> 16634.773 | F6: =(E6/Inputs!$B$9-1)*100 -> 16.888616 | G6: =(EXP(LN(1+F6/100)-LN(1+Inputs!$B$18/100)-LN(1+Inputs!$B$19/100)-LN(1+Inputs!$B$20/100))-1)*100 -> 14.169108 | H6: =(-(Inputs!$B$11/100+Inputs!$B$12)+SQRT((Inputs!$B$11/100+Inputs!$B$12)^2-4*(Inputs!$B$12/100)*(Inputs!$B$11-(B6*Inputs!$B$5-Inputs!$B$6)/(Inputs!$B$7*Inputs!$B$8/100))))/(2*(Inputs!$B$12/100))-Inputs!$B$17 -> 14.023507
A7: mean | B7: 182.125 | C7: =(B7/Inputs!$B$4-1)*100 -> 7.0127505 | D7: =(B7*Inputs!$B$5-Inputs!$B$6)/5800.957 -> 17.089529 | E7: =(B7*Inputs!$B$5-Inputs!$B$6)/Inputs!$B$21/(Inputs!$B$10/100) -> 16597.292 | F7: =(E7/Inputs!$B$9-1)*100 -> 16.625245 | G7: =(EXP(LN(1+F7/100)-LN(1+Inputs!$B$18/100)-LN(1+Inputs!$B$19/100)-LN(1+Inputs!$B$20/100))-1)*100 -> 13.911864 | H7: =(-(Inputs!$B$11/100+Inputs!$B$12)+SQRT((Inputs!$B$11/100+Inputs!$B$12)^2-4*(Inputs!$B$12/100)*(Inputs!$B$11-(B7*Inputs!$B$5-Inputs!$B$6)/(Inputs!$B$7*Inputs!$B$8/100))))/(2*(Inputs!$B$12/100))-Inputs!$B$17 -> 13.94806
A8: p75 | B8: 200 | C8: =(B8/Inputs!$B$4-1)*100 -> 17.515718 | D8: =(B8*Inputs!$B$5-Inputs!$B$6)/5800.957 -> 18.929118 | E8: =(B8*Inputs!$B$5-Inputs!$B$6)/Inputs!$B$21/(Inputs!$B$10/100) -> 18383.894 | F8: =(E8/Inputs!$B$9-1)*100 -> 29.179276 | G8: =(EXP(LN(1+F8/100)-LN(1+Inputs!$B$18/100)-LN(1+Inputs!$B$19/100)-LN(1+Inputs!$B$20/100))-1)*100 -> 26.173816 | H8: =(-(Inputs!$B$11/100+Inputs!$B$12)+SQRT((Inputs!$B$11/100+Inputs!$B$12)^2-4*(Inputs!$B$12/100)*(Inputs!$B$11-(B8*Inputs!$B$5-Inputs!$B$6)/(Inputs!$B$7*Inputs!$B$8/100))))/(2*(Inputs!$B$12/100))-Inputs!$B$17 -> 17.469661
A9: max | B9: 220 | C9: =(B9/Inputs!$B$4-1)*100 -> 29.267289 | D9: =(B9*Inputs!$B$5-Inputs!$B$6)/5800.957 -> 20.987399 | E9: =(B9*Inputs!$B$5-Inputs!$B$6)/Inputs!$B$21/(Inputs!$B$10/100) -> 20382.89 | F9: =(E9/Inputs!$B$9-1)*100 -> 43.225744 | G9: =(EXP(LN(1+F9/100)-LN(1+Inputs!$B$18/100)-LN(1+Inputs!$B$19/100)-LN(1+Inputs!$B$20/100))-1)*100 -> 39.893482 | H9: =(-(Inputs!$B$11/100+Inputs!$B$12)+SQRT((Inputs!$B$11/100+Inputs!$B$12)^2-4*(Inputs!$B$12/100)*(Inputs!$B$11-(B9*Inputs!$B$5-Inputs!$B$6)/(Inputs!$B$7*Inputs!$B$8/100))))/(2*(Inputs!$B$12/100))-Inputs!$B$17 -> 21.243976
A12: Estimate dispersion (Zacks FY27, 13 estimates), on the Delivered FY26 base
A13: Estimate | B13: FY27 revenue ($M) | C13: FY27 growth (%) | D13: Implied nights growth (%) | E13: Joint-solve price ($)
A14: low | B14: 14990 | C14: =(B14/Inputs!$B$9-1)*100 -> 5.3311844 | D14: =(EXP(LN(1+C14/100)-LN(1+Inputs!$B$18/100)-LN(1+Inputs!$B$19/100)-LN(1+Inputs!$B$20/100))-1)*100 -> 2.8805692 | E14: =((Inputs!$B$11+Inputs!$B$12*(C14+Inputs!$B$17))*Inputs!$B$7*(1+(C14+Inputs!$B$17)/100)*Inputs!$B$8/100+Inputs!$B$6)/Inputs!$B$5 -> 141.58655
A15: consensus | B15: 15730 | C15: =(B15/Inputs!$B$9-1)*100 -> 10.530989 | D15: =(EXP(LN(1+C15/100)-LN(1+Inputs!$B$18/100)-LN(1+Inputs!$B$19/100)-LN(1+Inputs!$B$20/100))-1)*100 -> 7.9593965 | E15: =((Inputs!$B$11+Inputs!$B$12*(C15+Inputs!$B$17))*Inputs!$B$7*(1+(C15+Inputs!$B$17)/100)*Inputs!$B$8/100+Inputs!$B$6)/Inputs!$B$5 -> 165.50578
A16: high | B16: 16290 | C16: =(B16/Inputs!$B$9-1)*100 -> 14.465977 | D16: =(EXP(LN(1+C16/100)-LN(1+Inputs!$B$18/100)-LN(1+Inputs!$B$19/100)-LN(1+Inputs!$B$20/100))-1)*100 -> 11.802833 | E16: =((Inputs!$B$11+Inputs!$B$12*(C16+Inputs!$B$17))*Inputs!$B$7*(1+(C16+Inputs!$B$17)/100)*Inputs!$B$8/100+Inputs!$B$6)/Inputs!$B$5 -> 184.70627

Sheet Options
A1: Options market (workstream B; live chain 11 Sep close, Bloomberg 4 Sep for history). Values carried from B's CSVs.
A3: Item | B3: Value | C3: Label | D3: Note
A4: pull_time_utc | B4: 2026-09-12T04:49:30.183206+00:00 | C4: MEASURED | D4: yfinance, Friday 11 Sep 2026 close quotes
A5: spot | B5: 170.19 | C5: ANCHOR | D5: close 11 Sep 2026
A6: risk_free_used_pct | B6: 4 | C6: JUDGEMENT | D6: ^IRX 3.91% on 11 Sep; brief 4.0-4.2%
A7: first_post_print_expiry | B7: 2026-11-20 | C7: MEASURED | D7: no 6 Nov weekly listed; 15 days after the 5 Nov print
A8: straddle_20nov_170_mid_pct_spot | B8: 13.544 | C8: MEASURED | D8: mid of a 12.0-15.0 market (170 put quoted 8.85/12.30); TOTAL 70-day move, not the print
A9: straddle_20nov_model_atm_pct_spot | B9: 13.388 | C9: MEASURED | D9: smile-model ATM straddle at the forward
A10: straddle_20nov_0p85_rule_pct | B10: 11.51 | C10: MEASURED | D10: rule-of-thumb applied to a 70-day straddle: upper bound only, NOT the print move
A11: straddle_16oct_170_mid_pct_spot | B11: 7.727 | C11: MEASURED | D11: pre-print 35-day straddle
A12: atm_iv_16oct_pct | B12: 31.11 | C12: MEASURED | D12: own Black-76 IV from mids, smile at forward
A13: atm_iv_20nov_pct | B13: 38.42 | C13: MEASURED | D13: own
A14: atm_iv_12m_pct | B14: 39.52 | C14: MEASURED | D14: variance-interpolated Jun27/Dec27
A15: event_sd_pair_16oct_20nov_pct | B15: 9.88 | C15: MEASURED | D15: E = T_post (sig_post^2 - sig_pre^2); flat background; +/-1 vol pt on either leg gives 8.4..11.2
A16: event_sd_ls_one_print_pct | B16: 9.16 | C16: MEASURED | D16: 5 maturities, LOO 7.97..10.13
A17: event_sd_ls_all_sloped_bg_pct | B17: 9.73 | C17: MEASURED | D17: 11 maturities, 5 prints, background allowed to slope
A18: event_sd_two_post_pct | B18: 8.3 | C18: MEASURED | D18: 20 Nov vs 18 Dec, both contain the print
A19: event_sd_central_pct | B19: 9.5 (range 8.5-10.5; identified specs 8.3-11.0) | C19: JUDGEMENT | D19: about 0.7 pt of sd per vol pt of either leg; smile fit RMSE 0.5-0.7 pt
A20: event_exp_abs_move_central_pct | B20: 7.6 (range 6.8-8.4) | C20: JUDGEMENT | D20: 0.80 x sd
A21: event_sd_4sep_bbg_chain_pair_pct | B21: 9.77 | C21: MEASURED | D21: same method on the 4 Sep Bloomberg chain; within noise of the 11 Sep reading
A22: hist_mean_implied_sd_iv_crush_pct | B22: 10.47 | C22: MEASURED | D22: Bloomberg 30D ATM IV, print close vs reaction close, 23 prints; upper-bound style measure
A23: hist_mean_implied_sd_kink45_pct | B23: 8.51 | C23: MEASURED | D23: Bloomberg 30D vs 60D IV 45 days before each print
A24: hist_realised_raw_rms_pct | B24: 8.92 | C24: MEASURED | D24: raw close-to-close, 20_executable_returns entry_postclose_px / pre_close
A25: hist_realised_raw_mean_abs_pct | B25: 7.07 | C25: MEASURED | D25: same
A26: hist_realised_raw_median_abs_pct | B26: 6.87 | C26: MEASURED | D26: same
A27: hist_realised_raw_share_abs_ge_7pct | B27: 0.48 | C27: MEASURED | D27: same
A28: hist_realised_raw_share_abs_ge_10pct | B28: 0.35 | C28: MEASURED | D28: same
A29: hist_realised_raw_up_down | B29: 13 up / 10 down | C29: MEASURED | D29: same
A30: hist_realised_raw_rms_over_implied_crush | B30: 0.853 | C30: MEASURED | D30: 8.92 / 10.47
A31: hist_realised_excess_rms_pct | B31: 8.48 | C31: MEASURED | D31: QQQ-excess close-to-close (legacy_1d_pct); the series earlier notes used
A32: hist_realised_excess_mean_abs_pct | B32: 6.81 | C32: MEASURED | D32: same
A33: hist_realised_excess_median_abs_pct | B33: 5.14 | C33: MEASURED | D33: same
A34: hist_realised_excess_up_down | B34: 11 up / 12 down | C34: MEASURED | D34: same
A35: hist_realised_excess_rms_over_implied_crush | B35: 0.81 | C35: MEASURED | D35: 8.48 / 10.47
A36: nights_accel_split_raw | B36: 6 up / 2 down accel; 3 up / 8 down decel | C36: MEASURED | D36: threshold 0, n 8 / 11; base rate not model
A37: nights_accel_split_excess | B37: 6 up / 2 down accel; 1 up / 10 down decel | C37: MEASURED | D37: 1Q25 and 1Q26 flip sign once QQQ is subtracted; C's +/-0.25pt dead band moves 1Q22 and 3Q24 to flat
A38: rr25_20nov_volpts | B38: -3.47 | C38: MEASURED | D38: 25d call IV minus 25d put IV; negative = puts richer
A39: skew_90_110_20nov_volpts | B39: 3.31 | C39: MEASURED | D39: own method, 70d; cross-method vs BBG 30D history (median 4.4) is approximate, own method reads ~1 pt below BBG
A40: call10_over_put10_20nov_relative_to_flat | B40: 0.845 | C40: MEASURED | D40: market call/put ratio is 15.5% below the flat-smile ratio, i.e. the put is 1/0.845 = 1.18x richer relative to the call than under a flat smile
A41: p_above_spot_20nov_rnd | B41: 0.493 | C41: MEASURED | D41: risk-neutral
...

Sheet Comparison
A1: What is priced, by whom (FY27E, on the FY26 Delivered base; nights at ADR +3%, FX -0.6pp, take rate flat)
A3: Who / what | B3: Price ($) | C3: FY27 revenue growth (%) | D3: FY27 revenue ($M) | E3: FY27 adj. EBITDA ($M) | F3: FY27 nights growth (%) | G3: Implied EV / FY27 EBITDA (x) | H3: P(price above this in 12M, options RN) | I3: Expected 5 Nov day-1 reaction, S1 sign rule, conditional (%) | J3: Source
A4: Market: current price (joint solve, proportional mapping) | B4: =Market_Implied!A9 -> 170.19 | C4: =Market_Implied!I9 -> 11.509112 | D4: =Market_Implied!K9 -> 15869.2 | E4: =Market_Implied!L9 -> 5744.6503 | F4: =Market_Implied!O9 -> 8.9147626 | G4: =Market_Implied!N9 -> 16.016716 | H4: =Market_Implied!S9 -> 0.48 | J4: A
A5: Market: current price (joint solve, chained mapping) | B5: =Market_Implied!A9 -> 170.19 | C5: =Market_Implied!J9 -> 10.395696 | D5: =Inputs!$B$9*(1+C5/100) -> 15710.746 | E5: =D5*Inputs!$B$10/100 -> 5687.2901 | F5: =Market_Implied!P9 -> 7.8272513 | G5: =Market_Implied!D9/E5 -> 16.178255 | H5: =Market_Implied!S9 -> 0.48 | J5: A
A6: Market: current price (fixed 16.5x) | B6: =Market_Implied!A9 -> 170.19 | C6: =Market_Implied!Q9 -> 8.2430149 | D6: =Inputs!$B$9*(1+C6/100) -> 15404.391 | E6: =D6*Inputs!$B$10/100 -> 5576.3897 | F6: =Market_Implied!R9 -> 5.7246537 | G6: =Inputs!$B$21 -> 16.5 | H6: =Market_Implied!S9 -> 0.48 | J6: A fallback
A7: Options: 12M p25 (joint solve) | B7: =Market_Implied!A5 -> 125.5 | C7: =Market_Implied!I5 -> 1.6137058 | D7: =Market_Implied!K5 -> 14460.954 | E7: =Market_Implied!L5 -> 5234.8655 | F7: =Market_Implied!O5 -> -0.7504192 | G7: =Market_Implied!N5 -> 12.479881 | H7: =Market_Implied!S5 -> 0.741 | J7: B + A
A8: Options: 12M p50 (joint solve) | B8: =Market_Implied!A7 -> 163.8 | C8: =Market_Implied!I7 -> 10.171732 | D8: =Market_Implied!K7 -> 15678.873 | E8: =Market_Implied!L7 -> 5675.752 | F8: =Market_Implied!O7 -> 7.6084977 | G8: =Market_Implied!N7 -> 15.539016 | H8: =Market_Implied!S7 -> 0.517 | J8: B + A
A9: Options: 12M p75 (joint solve) | B9: =Market_Implied!A13 -> 213.9 | C9: =Market_Implied!I13 -> 20.110091 | D9: =Market_Implied!K13 -> 17093.231 | E9: =Market_Implied!L13 -> 6187.7496 | F9: =Market_Implied!O13 -> 17.315633 | G9: =Market_Implied!N13 -> 19.086955 | H9: =Market_Implied!S13 -> 0.263 | J9: B + A
A10: Sell-side: p25 target $165 (joint solve) | B10: =Market_Implied!A8 -> 165 | C10: =Market_Implied!I8 -> 10.424639 | D10: =Market_Implied!K8 -> 15714.865 | E10: =Market_Implied!L8 -> 5688.7811 | F10: =Market_Implied!O8 -> 7.8555206 | G10: =Market_Implied!N8 -> 15.629359 | H10: =Market_Implied!S8 -> 0.51 | J10: D + A
A11: Sell-side: mean target $179.5 (joint solve) | B11: =Market_Implied!A10 -> 179.5 | C11: =Market_Implied!I10 -> 13.417959 | D11: =Market_Implied!K10 -> 16140.853 | E11: =Market_Implied!L10 -> 5842.9889 | F11: =Market_Implied!O10 -> 10.779199 | G11: =Market_Implied!N10 -> 16.698389 | H11: =Market_Implied!S10 -> 0.428 | J11: D + A
A12: Sell-side: p75 target $197.5 (joint solve) | B12: =Market_Implied!A12 -> 197.5 | C12: =Market_Implied!I12 -> 16.985984 | D12: =Market_Implied!K12 -> 16648.63 | E12: =Market_Implied!L12 -> 6026.804 | F12: =Market_Implied!O12 -> 14.26421 | G12: =Market_Implied!N12 -> 17.972129 | H12: =Market_Implied!S12 -> 0.336 | J12: D + A
A13: Sell-side: top target $220 (joint solve) | B13: =Market_Implied!A14 -> 220 | C13: =Market_Implied!I14 -> 21.243976 | D13: =Market_Implied!K14 -> 17254.598 | E13: =Market_Implied!L14 -> 6246.1643 | F13: =Market_Implied!O14 -> 18.423137 | G13: =Market_Implied!N14 -> 19.491482 | H13: =Market_Implied!S14 -> 0.239 | J13: D + A
A14: Management literal | B14: =Cases!D5 -> 162.18994 | C14: =Cases!B5 -> 9.8311 | D14: =Inputs!$B$9*(1+Cases!B5/100) -> 15630.397 | E14: =Cases!C5 -> 5548.8 | F14: =Cases!H5 -> 7.2757907 | G14: =(Cases!D5*Inputs!$B$5-Inputs!$B$6)/Cases!C5 -> 15.721308 | H14: =Cases!I5 -> 0.527 | J14: management note / WS29 / A
A15: Management delivered | B15: =Cases!D6 -> 175.49354 | C15: =Cases!B6 -> 12.6021 | D15: =Inputs!$B$9*(1+Cases!B6/100) -> 16024.746 | E15: =Cases!C6 -> 5801 | F15: =Cases!H6 -> 9.9823211 | G15: =(Cases!D6*Inputs!$B$5-Inputs!$B$6)/Cases!C6 -> 16.406938 | H15: =Cases!I6 -> 0.45 | I15: =Print_5Nov!G9 -> 5.2053 | J15: management note / WS29 / A
A16: Management ambition | B16: =Cases!D7 -> 202.67314 | C16: =Cases!B7 -> 17.9838 | D16: =Inputs!$B$9*(1+Cases!B7/100) -> 16790.632 | E16: =Cases!C7 -> 6212.5 | F16: =Cases!H7 -> 15.238812 | G16: =(Cases!D7*Inputs!$B$5-Inputs!$B$6)/Cases!C7 -> 17.932051 | H16: =Cases!I7 -> 0.313 | J16: management note / WS29 / A
A17: Street FY27 $15,745m | B17: =Cases!D8 -> 166.00778 | C17: =Cases!B8 -> 10.6364 | D17: =Inputs!$B$9*(1+Cases!B8/100) -> 15745.001 | E17: =Cases!C8 -> 5699.7 | F17: =Cases!H8 -> 8.0623547 | G17: =(Cases!D8*Inputs!$B$5-Inputs!$B$6)/Cases!C8 -> 15.704975 | H17: =Cases!I8 -> 0.504 | I17: =Print_5Nov!G8 -> 5.2053 | J17: management note / WS29 / A
A18: Team base (WS29/30) $15,804m | B18: =Cases!D9 -> 167.97828 | C18: =Cases!B9 -> 11.0488 | D18: =Inputs!$B$9*(1+Cases!B9/100) -> 15803.691 | E18: =Cases!C9 -> 5757.9 | F18: =Cases!H9 -> 8.4651599 | G18: =(Cases!D9*Inputs!$B$5-Inputs!$B$6)/Cases!C9 -> 15.75054 | H18: =Cases!I9 -> 0.493 | I18: =Print_5Nov!G5 -> -6.1093 | J18: management note / WS29 / A
A19: Team bear (WS29) $14,318m | B19: =Cases!D10 -> 121.30786 | C19: =Cases!B10 -> 0.6115 | D19: =Inputs!$B$9*(1+Cases!B10/100) -> 14318.327 | E19: =Cases!C10 -> 4375 | F19: =Cases!H10 -> -1.7293079 | G19: =(Cases!D10*Inputs!$B$5-Inputs!$B$6)/Cases!C10 -> 14.360638 | H19: =Cases!I10 -> 0.75 | J19: management note / WS29 / A
A20: Team bull (WS29) $16,910m | B20: =Cases!D11 -> 207.06004 | C20: =Cases!B11 -> 18.8209 | D20: =Inputs!$B$9*(1+Cases!B11/100) -> 16909.762 | E20: =Cases!C11 -> 6977.4 | F20: =Cases!H11 -> 16.056436 | G20: =(Cases!D11*Inputs!$B$5-Inputs!$B$6)/Cases!C11 -> 16.341595 | H20: =Cases!I11 -> 0.293 | J20: management note / WS29 / A

Sheet Recon
A1: Excel (recalculated) vs Python mirror; max abs diff: | B1: 0.0013819095
A3: sheet | B3: key | C3: excel | D3: python | E3: diff
A4: Market_Implied | B4: 125.5:g_ntm | C4: 3.0347058 | D4: 3.0347058 | E4: 0
A5: Market_Implied | B5: 125.5:m_ntm | C5: 13.733226 | D5: 13.733226 | E5: 0
A6: Market_Implied | B6: 125.5:g27_prop | C6: 1.6137058 | D6: 1.6137058 | E6: -4.4408921e-16
A7: Market_Implied | B7: 125.5:g27_direct | C7: -10.319171 | D7: -10.319171 | E7: 0
A8: Market_Implied | B8: 125.5:rev27 | C8: 14460.954 | D8: 14460.954 | E8: 0
A9: Market_Implied | B9: 125.5:ebitda27 | C9: 5234.8655 | D9: 5234.8655 | E9: 0
A10: Market_Implied | B10: 125.5:eps27 | C10: 5.2878054 | D10: 5.2878054 | E10: 0
A11: Market_Implied | B11: 125.5:ev_fy27_ebitda | C11: 12.479881 | D11: 12.479881 | E11: 0
A12: Market_Implied | B12: 125.5:nights27_prop | C12: -0.7504192 | D12: -0.7504192 | E12: 0
A13: Market_Implied | B13: 125.5:nights27_direct | C13: -12.405668 | D13: -12.405668 | E13: 0
A14: Market_Implied | B14: 125.5:g27_fixed | C14: -23.143819 | D14: -23.143819 | E14: 0
A15: Market_Implied | B15: 125.5:nights27_fixed | C15: -24.93194 | D15: -24.93194 | E15: 0
... A178: Print_5Nov | B178: 2Q26 replay: accelerating print, guide +2.6% vs Street:E_S2_post2022 | C178: 7.9381323 | D178: 7.9381323 | E178: 0
