Workbook

Sheet Cover
A1: ABNB: the management-implied model
A3: Built 11 Sep 2026 by analysis/src/reverse_dcf/mgmt_implied_model.py. Rebuild with: py -3.13 analysis/src/reverse_dcf/mgmt_implied_model.py
A4: Question: if what management says is true, what is the stock worth? Three translations of the words into numbers, each on its own sheet:
A5: Mgmt_Literal - the guide at face value (range midpoints, floors as points, buckets at the low end; FY27 = the Feb-2027 guide on management's pattern)
A6: Mgmt_Delivered - the guide plus management's own cushion (revenue +1.8% vs midpoint, nights 1pt above the bucket, FY margin floor +70bp); FY27 = FY26 exit rate, margin flat
A7: Mgmt_Ambition - the 8 Sep 2026 CEO framing (accelerating everywhere, hotels 3x, take rate +20bp in FY27, margin 37%)
A8: Valuation - FY27E exit multiples (EV/EBITDA, P/E, EV/FCF; inputs) and a DCF / reverse DCF on management FCF
A9: Street - consensus as pulled (Bloomberg FA 4 Sep, Zacks 4 Sep, S&P Global 3 Sep) for comparison only
A10: Mgmt_Statements- what management is looking at by area, near and mid term, with the hit rate of each line
A11: Recon - Excel recalculated values vs the Python mirror (must be all zeros)
A12: Conventions: yellow = input, blue = reported history, black = formula. Every input carries its source in column P. Management is silent on all FY27 lines: FY27 inputs are the analyst's reading of the stated algorithm.
A13: Not in this workbook: line-by-line cost build (WS30/31), regional nights (WS10), the team's own forecasts (WS29 bridge), any market-implied case (next step).

Sheet Mgmt_Literal
A1: ABNB management-implied model: Guide literal
A2: Range midpoints, floors as points, buckets at their low end; FY27 = the guide management would give in Feb 2027 on its own pattern
A3: Yellow = input. Blue = reported history. Black = formula. Price $170.19 (11 Sep 2026). Built by analysis/src/reverse_dcf/mgmt_implied_model.py
A5: Line | B5: Unit | C5: 3Q25A | D5: 4Q25A | E5: 1Q26A | F5: 2Q26A | G5: 3Q26E | H5: 4Q26E | I5: 1Q27E | J5: 2Q27E | K5: 3Q27E | L5: 4Q27E | M5: FY25A | N5: FY26E | O5: FY27E | P5: Source / note
A6: A. INPUTS (yellow = management-derived driver; column P = source)
A7: Nights & Seats Booked growth | B7: y/y % | G7: 10 | H7: 8.5 | I7: 9 | J7: 9 | K7: 9 | L7: 9 | P7: 2Q26 letter: 3Q26 'low double-digit'; 4Q26 not guided (FY 'at least mid teens' revenue implies it); FY27 silent
A8: ADR ex-FX growth | B8: y/y % | G8: 3 | H8: 2.5 | I8: 2.5 | J8: 2.5 | K8: 2.5 | L8: 2.5 | P8: 2Q26 letter: 'moderate increase in ADR due to mix shift and price appreciation'; 1H26 ran +4%
A9: ADR FX effect | B9: pp | G9: 0.3 | H9: -0.4 | I9: -0.4 | J9: 0 | K9: 0.7 | L9: 0 | P9: WS05/WS29 EUR path fit; management does not guide ADR FX beyond 'significantly lower' (1Q26)
A10: Implied take rate, relative change | B10: y/y % | G10: 0 | H10: 0 | I10: 0 | J10: 0 | K10: 0 | L10: 0 | P10: 2Q26: 'relatively flat compared to 2025' after customer incentives; +1.5% = +20bp (Ambition only)
A11: Revenue FX after hedging | B11: pp | G11: 3 | H11: -0.4 | I11: -1 | J11: -0.8 | K11: -0.6 | L11: -0.1 | P11: 2Q26 letter: 3Q26 'approximate three percentage point FX tailwind after factoring in our hedging program'; later quarters WS29 fit
A12: Timing / other residual (revenue vs GBV x take rate) | B12: pp | G12: -1.0523 | H12: -0.5171 | I12: 0 | J12: 0 | K12: 0 | L12: 0 | P12: calibrated so 3Q26 revenue hits the guide midpoint (Literal) or midpoint +1.8% (Delivered); RNPL book-vs-stay timing
A13: Adj. EBITDA margin change | B13: y/y pts | G13: -0.6 | H13: 0.3467 | I13: -0.0051 | J13: -0.0051 | K13: -0.0051 | L13: -0.0051 | P13: 3Q26: 'down slightly compared to Q3 2025' (50.1%); 4Q26 solved so FY26 = floor (or floor + cushion); FY27 solved for the FY27 margin in row 1
A14: SBC growth | B14: y/y % | G14: 10 | H14: 10 | I14: 9 | J14: 9 | K14: 9 | L14: 9 | P14: 4Q25 letter: 'growth rate of SBC and headcount will be lower than 2025' (FY25 +13.1% letters basis); 1H26 +14.7% so H2 ~+10%
A15: D&A | B15: % revenue | G15: 0.65 | H15: 0.65 | I15: 0.65 | J15: 0.65 | K15: 0.65 | L15: 0.65 | P15: 0.6-0.8% of revenue since 2023
A16: Interest income | B16: $M | G16: 170 | H16: 165 | I16: 160 | J16: 160 | K16: 160 | L16: 160 | P16: $12.1bn cash + ST investments; 2Q26 $183M; falling rates
A17: Interest expense | B17: $M | G17: 31 | H17: 31 | I17: 31 | J17: 31 | K17: 31 | L17: 31 | P17: $2.5bn senior notes issued Mar 2026 at 4.40 / 4.65 / 5.25%
A18: Effective tax rate | B18: % | G18: 18 | H18: 18 | I18: 18 | J18: 18 | K18: 18 | L18: 18 | P18: 2Q26 letter 'high teens' FY26; OBBBA long-term 'mid-to-high teens' (2Q26 call); 1H26 17.1%
... A22: FCF / adj. EBITDA (seasonal) | B22: x | G22: 0.7 | H22: 0.7 | I22: 3.2 | J22: 1 | K22: 0.7 | L22: 0.7 | P22: prior-year quarter ratios 3Q25 0.66x, 4Q25 0.66x, 1Q26 3.28x, 2Q26 0.99x (the float builds in H1, unwinds in H2); annual FY24 1.14x, FY25 1.07x, LTM 1.05x; set so FY26 ~1.03x and FY27 ~1.01x as cash taxes rise, interest income falls and RNPL flattens unearned fees
A24: B. OPERATING BUILD
A25: Nights & Seats Booked | B25: M | C25: 133.6 | D25: 121.9 | E25: 156.2 | F25: 148.3 | G25: =C25*(1+G7/100) -> 146.96 | H25: =D25*(1+H7/100) -> 132.2615 | I25: =E25*(1+I7/100) -> 170.258 | J25: =F25*(1+J7/100) -> 161.647 | K25: =G25*(1+K7/100) -> 160.1864 | L25: =H25*(1+L7/100) -> 144.16504 | M25: 533 | N25: =E25+F25+G25+H25 -> 583.7215 | O25: =I25+J25+K25+L25 -> 636.25644 | P25: letters
A26: Gross Booking Value | B26: $M | C26: 22892 | D26: 20400 | E26: 29187 | F26: 27247 | G26: =C26*(1+G7/100)*(1+G8/100)*(1+G9/100) -> 26014.446 | H26: =D26*(1+H7/100)*(1+H8/100)*(1+H9/100) -> 22596.601 | I26: =E26*(1+I7/100)*(1+I8/100)*(1+I9/100) -> 32478.739 | J26: =F26*(1+J7/100)*(1+J8/100)*(1+J9/100) -> 30441.711 | K26: =G26*(1+K7/100)*(1+K8/100)*(1+K9/100) -> 29268.092 | L26: =H26*(1+L7/100)*(1+L8/100)*(1+L9/100) -> 25246.052 | M26: 91292 | N26: =E26+F26+G26+H26 -> 105045.05 | O26: =I26+J26+K26+L26 -> 117434.59 | P26: letters / Bloomberg FA (unrounded 3Q25, 1Q26, 2Q26)
A27: ADR (GBV / nights) | B27: $ | C27: =C26/C25 -> 171.34731 | D27: =D26/D25 -> 167.35029 | E27: =E26/E25 -> 186.85659 | F27: =F26/F25 -> 183.72893 | G27: =G26/G25 -> 177.01719 | H27: =H26/H25 -> 170.84791 | I27: =I26/I25 -> 190.7619 | J27: =J26/J25 -> 188.32215 | ... O27: =O26/O25 -> 184.57117
A28: Revenue | B28: $M | C28: 4095 | D28: 2778 | E28: 2678 | F28: 3608 | G28: =C28*(1+G7/100)*(1+G8/100)*(1+G10/100)*(1+(G11+G12)/100) -> 4730.0012 | H28: =D28*(1+H7/100)*(1+H8/100)*(1+H10/100)*(1+(H11+H12)/100) -> 3061.1496 | I28: =E28*(1+I7/100)*(1+I8/100)*(1+I10/100)*(1+(I11+I12)/100) -> 2962.0755 | J28: =F28*(1+J7/100)*(1+J8/100)*(1+J10/100)*(1+(J11+J12)/100) -> 3998.7897 | K28: =G28*(1+K7/100)*(1+K8/100)*(1+K10/100)*(1+(K11+K12)/100) -> 5252.8862 | L28: =H28*(1+L7/100)*(1+L8/100)*(1+L10/100)*(1+(L11+L12)/100) -> 3416.6493 | M28: 12241 | N28: =E28+F28+G28+H28 -> 14077.151 | O28: =I28+J28+K28+L28 -> 15630.401 | P28: letters
A29: Implied take rate | B29: % | C29: =C28/C26*100 -> 17.888345 | D29: =D28/D26*100 -> 13.617647 | E29: =E28/E26*100 -> 9.1753178 | F29: =F28/F26*100 -> 13.241825 | G29: =G28/G26*100 -> 18.18221 | H29: =H28/H26*100 -> 13.546947 | I29: =I28/I26*100 -> 9.1200448 | J29: =J28/J26*100 -> 13.13589 | ... O29: =O28/O26*100 -> 13.309878 | P29: FY25 13.41%; guided 'relatively flat' for FY26
A30: Adj. EBITDA margin | B30: % | C30: =C31/C28*100 -> 50.08547 | D30: =D31/D28*100 -> 28.293737 | E30: =E31/E28*100 -> 19.380134 | F30: =F31/F28*100 -> 34.950111 | G30: =C30+G13 -> 49.48547 | H30: =D30+H13 -> 28.640437 | I30: =E30+I13 -> 19.375034 | J30: =F30+J13 -> 34.945011 | K30: =G30+K13 -> 49.48037 | L30: =H30+L13 -> 28.635337 | M30: =M31/M28*100 -> 35.103341 | N30: =N31/N28*100 -> 35.50001 | O30: =O31/O28*100 -> 35.500032
A31: Adj. EBITDA | B31: $M | C31: 2051 | D31: 786 | E31: 519 | F31: 1261 | G31: =G28*G30/100 -> 2340.6633 | H31: =H28*H30/100 -> 876.72661 | I31: =I28*I30/100 -> 573.90316 | J31: =J28*J30/100 -> 1397.3775 | K31: =K28*K30/100 -> 2599.1476 | L31: =L28*L30/100 -> 978.36903 | M31: 4297 | N31: =E31+F31+G31+H31 -> 4997.3899 | O31: =I31+J31+K31+L31 -> 5548.7972 | P31: letters
A32: Stock-based compensation | B32: $M | C32: 399 | D32: 400 | E32: 410 | F32: 487 | G32: =C32*(1+G14/100) -> 438.9 | H32: =D32*(1+H14/100) -> 440 | I32: =E32*(1+I14/100) -> 446.9 | J32: =F32*(1+J14/100) -> 530.83 | K32: =G32*(1+K14/100) -> 478.401 | L32: =H32*(1+L14/100) -> 479.6 | M32: 1581 | N32: =E32+F32+G32+H32 -> 1775.9 | O32: =I32+J32+K32+L32 -> 1935.731 | P32: letters (adj. EBITDA reconciliation)
A33: D&A | B33: $M | C33: 22 | D33: 23 | E33: 22 | F33: 17 | G33: =G28*G15/100 -> 30.745008 | H33: =H28*H15/100 -> 19.897472 | I33: =I28*I15/100 -> 19.253491 | J33: =J28*J15/100 -> 25.992133 | K33: =K28*K15/100 -> 34.143761 | L33: =L28*L15/100 -> 22.208221 | M33: 91 | N33: =E33+F33+G33+H33 -> 89.64248 | O33: =I33+J33+K33+L33 -> 101.59761 | P33: Bloomberg FA / 10-Q
A34: Operating income (GAAP; adj. EBITDA less SBC less D&A) | B34: $M | C34: 1599 | D34: 193 | E34: 166 | F34: 744 | G34: =G31-G32-G33 -> 1871.0183 | H34: =H31-H32-H33 -> 416.82913 | I34: =I31-I32-I33 -> 107.74967 | J34: =J31-J32-J33 -> 840.55536 | K34: =K31-K32-K33 -> 2086.6028 | L34: =L31-L32-L33 -> 476.56081 | M34: 2320 | N34: =E34+F34+G34+H34 -> 3197.8474 | O34: =I34+J34+K34+L34 -> 3511.4686 | P34: history backed out of pretax income so the P&L ties to reported net income; other add-backs sit here
A35: Interest income | B35: $M | C35: 180 | D35: 162 | E35: 155 | F35: 183 | G35: =G16 -> 170 | H35: =H16 -> 165 | I35: =I16 -> 160 | J35: =J16 -> 160 | K35: =K16 -> 160 | L35: =L16 -> 160 | M35: 705 | N35: =E35+F35+G35+H35 -> 673 | O35: =I35+J35+K35+L35 -> 640 | P35: Bloomberg FA
A36: Interest expense | B36: $M | C36: 0 | D36: 0 | E36: 0 | F36: 37 | G36: =G17 -> 31 | H36: =H17 -> 31 | I36: =I17 -> 31 | J36: =J17 -> 31 | K36: =K17 -> 31 | L36: =L17 -> 31 | M36: 0 | N36: =E36+F36+G36+H36 -> 99 | O36: =I36+J36+K36+L36 -> 124 | P36: Bloomberg FA
A37: Other income (expense), net | B37: $M | C37: 13 | D37: 38 | E37: -40 | F37: 7 | G37: 0 | H37: 0 | I37: 0 | J37: 0 | K37: 0 | L37: 0 | M37: 112 | N37: =E37+F37+G37+H37 -> -33 | O37: =I37+J37+K37+L37 -> 0 | P37: Bloomberg FA; zero forecast
A38: Pretax income | B38: $M | C38: =C34+C35-C36+C37 -> 1792 | D38: =D34+D35-D36+D37 -> 393 | E38: =E34+E35-E36+E37 -> 281 | F38: =F34+F35-F36+F37 -> 897 | G38: =G34+G35-G36+G37 -> 2010.0183 | H38: =H34+H35-H36+H37 -> 550.82913 | I38: =I34+I35-I36+I37 -> 236.74967 | J38: =J34+J35-J36+J37 -> 969.55536 | ... M38: =M34+M35-M36+M37 -> 3137 | N38: =E38+F38+G38+H38 -> 3738.8474 | O38: =I38+J38+K38+L38 -> 4027.4686
A39: Effective tax rate | B39: % | C39: =C40/C38*100 -> 23.325893 | D39: =D40/D38*100 -> 13.231552 | E39: =E40/E38*100 -> 43.060498 | F39: =F40/F38*100 -> 9.0301003 | G39: =G18 -> 18 | H39: =H18 -> 18 | I39: =I18 -> 18 | J39: =J18 -> 18 | K39: =K18 -> 18 | L39: =L18 -> 18 | M39: =M40/M38*100 -> 19.955371 | N39: =N40/N38*100 -> 17.731468 | O39: =O40/O38*100 -> 18
A40: Income tax | B40: $M | C40: 418 | D40: 52 | E40: 121 | F40: 81 | G40: =G38*G39/100 -> 361.8033 | H40: =H38*H39/100 -> 99.149244 | I40: =I38*I39/100 -> 42.61494 | J40: =J38*J39/100 -> 174.51996 | K40: =K38*K39/100 -> 398.8085 | L40: =L38*L39/100 -> 109.00095 | M40: 626 | N40: =E40+F40+G40+H40 -> 662.95254 | O40: =I40+J40+K40+L40 -> 724.94435 | P40: letters; 2Q26 includes a $77M prior-year benefit
A41: Net income (GAAP) | B41: $M | C41: =C38-C40 -> 1374 | D41: =D38-D40 -> 341 | E41: =E38-E40 -> 160 | F41: =F38-F40 -> 816 | G41: =G38-G40 -> 1648.215 | H41: =H38-H40 -> 451.67989 | I41: =I38-I40 -> 194.13473 | J41: =J38-J40 -> 795.0354 | ... M41: =M38-M40 -> 2511 | N41: =E41+F41+G41+H41 -> 3075.8949 | O41: =I41+J41+K41+L41 -> 3302.5243 | P41: letters
A42: Diluted weighted-average shares | B42: M | C42: 621 | D42: 613 | E42: 608 | F42: 597 | G42: =F42-G19/G20+G21 -> 592.43042 | H42: =G42-H19/H20+H21 -> 587.93401 | I42: =H42-I19/I20+I21 -> 583.50988 | J42: =I42-J19/J20+J21 -> 579.15719 | K42: =J42-K19/K20+K21 -> 574.87507 | L42: =K42-L19/L20+L21 -> 570.66271 | M42: 623 | N42: =AVERAGE(E42:H42) -> 596.34111 | O42: =AVERAGE(I42:L42) -> 577.05121 | P42: 10-Q; forecast = prior less buyback / price plus net RSU issuance
A43: Diluted EPS (GAAP) | B43: $ | C43: =C41/C42 -> 2.2125604 | D43: =D41/D42 -> 0.55628059 | E43: =E41/E42 -> 0.26315789 | F43: =F41/F42 -> 1.3668342 | G43: =G41/G42 -> 2.7821242 | H43: =H41/H42 -> 0.7682493 | I43: =I41/I42 -> 0.33270169 | J43: =J41/J42 -> 1.3727455 | ... O43: =O41/O42 -> 5.7231043 | P43: Street 'adjusted' EPS for ABNB is GAAP-basis (Bloomberg FA 2Q26 1.37 = GAAP)
A44: Free cash flow | B44: $M | C44: 1349 | D44: 521 | E44: 1704 | F44: 1253 | G44: =G31*G22 -> 1638.4643 | H44: =H31*H22 -> 613.70862 | I44: =I31*I22 -> 1836.4901 | J44: =J31*J22 -> 1397.3775 | K44: =K31*K22 -> 1819.4033 | L44: =L31*L22 -> 684.85832 | M44: 4613 | N44: =E44+F44+G44+H44 -> 5209.1729 | O44: =I44+J44+K44+L44 -> 5738.1292 | P44: letters; forecast = adj. EBITDA x conversion (annual-grade; quarterly seasonality of the float is not modelled)
A45: Share repurchases | B45: $M | C45: 877 | D45: 1095 | E45: 1088 | F45: 1051 | G45: =G19 -> 1050 | H45: =H19 -> 1050 | I45: =I19 -> 1050 | J45: =J19 -> 1050 | K45: =K19 -> 1050 | L45: =L19 -> 1050 | M45: 3789 | N45: =E45+F45+G45+H45 -> 4239 | O45: =I45+J45+K45+L45 -> 4200 | P45: letters
...

Sheet Mgmt_Delivered
A1: ABNB management-implied model: Guide as delivered
A2: Guide plus management's own cushion: revenue +1.8% vs midpoint, nights 1pt above the bucket top, FY margin floor +70bp; FY27 holds the FY26 exit rate with margin flat (reinvest-the-efficiencies rule)
A3: Yellow = input. Blue = reported history. Black = formula. Price $170.19 (11 Sep 2026). Built by analysis/src/reverse_dcf/mgmt_implied_model.py
A5: Line | B5: Unit | C5: 3Q25A | D5: 4Q25A | E5: 1Q26A | F5: 2Q26A | G5: 3Q26E | H5: 4Q26E | I5: 1Q27E | J5: 2Q27E | K5: 3Q27E | L5: 4Q27E | M5: FY25A | N5: FY26E | O5: FY27E | P5: Source / note
A6: A. INPUTS (yellow = management-derived driver; column P = source)
A7: Nights & Seats Booked growth | B7: y/y % | G7: 11.5 | H7: 10.5 | I7: 10 | J7: 10 | K7: 10 | L7: 10 | P7: 2Q26 letter: 3Q26 'low double-digit'; 4Q26 not guided (FY 'at least mid teens' revenue implies it); FY27 silent
A8: ADR ex-FX growth | B8: y/y % | G8: 3.5 | H8: 3 | I8: 3 | J8: 3 | K8: 3 | L8: 3 | P8: 2Q26 letter: 'moderate increase in ADR due to mix shift and price appreciation'; 1H26 ran +4%
A9: ADR FX effect | B9: pp | G9: 0.3 | H9: -0.4 | I9: -0.4 | J9: 0 | K9: 0.7 | L9: 0 | P9: WS05/WS29 EUR path fit; management does not guide ADR FX beyond 'significantly lower' (1Q26)
A10: Implied take rate, relative change | B10: y/y % | G10: 0 | H10: 0 | I10: 0 | J10: 0 | K10: 0 | L10: 0 | P10: 2Q26: 'relatively flat compared to 2025' after customer incentives; +1.5% = +20bp (Ambition only)
A11: Revenue FX after hedging | B11: pp | G11: 3 | H11: -0.4 | I11: -1 | J11: -0.8 | K11: -0.6 | L11: -0.1 | P11: 2Q26 letter: 3Q26 'approximate three percentage point FX tailwind after factoring in our hedging program'; later quarters WS29 fit
A12: Timing / other residual (revenue vs GBV x take rate) | B12: pp | G12: -1.1081 | H12: -0.6 | I12: 0 | J12: 0 | K12: 0 | L12: 0 | P12: calibrated so 3Q26 revenue hits the guide midpoint (Literal) or midpoint +1.8% (Delivered); RNPL book-vs-stay timing
A13: Adj. EBITDA margin change | B13: y/y pts | G13: -0.1 | H13: 2.5309 | I13: -0.0074 | J13: -0.0074 | K13: -0.0074 | L13: -0.0074 | P13: 3Q26: 'down slightly compared to Q3 2025' (50.1%); 4Q26 solved so FY26 = floor (or floor + cushion); FY27 solved for the FY27 margin in row 1
A14: SBC growth | B14: y/y % | G14: 10 | H14: 10 | I14: 9 | J14: 9 | K14: 9 | L14: 9 | P14: 4Q25 letter: 'growth rate of SBC and headcount will be lower than 2025' (FY25 +13.1% letters basis); 1H26 +14.7% so H2 ~+10%
A15: D&A | B15: % revenue | G15: 0.65 | H15: 0.65 | I15: 0.65 | J15: 0.65 | K15: 0.65 | L15: 0.65 | P15: 0.6-0.8% of revenue since 2023
A16: Interest income | B16: $M | G16: 170 | H16: 165 | I16: 160 | J16: 160 | K16: 160 | L16: 160 | P16: $12.1bn cash + ST investments; 2Q26 $183M; falling rates
A17: Interest expense | B17: $M | G17: 31 | H17: 31 | I17: 31 | J17: 31 | K17: 31 | L17: 31 | P17: $2.5bn senior notes issued Mar 2026 at 4.40 / 4.65 / 5.25%
A18: Effective tax rate | B18: % | G18: 18 | H18: 18 | I18: 18 | J18: 18 | K18: 18 | L18: 18 | P18: 2Q26 letter 'high teens' FY26; OBBBA long-term 'mid-to-high teens' (2Q26 call); 1H26 17.1%
... A22: FCF / adj. EBITDA (seasonal) | B22: x | G22: 0.7 | H22: 0.7 | I22: 3.2 | J22: 1 | K22: 0.7 | L22: 0.7 | P22: prior-year quarter ratios 3Q25 0.66x, 4Q25 0.66x, 1Q26 3.28x, 2Q26 0.99x (the float builds in H1, unwinds in H2); annual FY24 1.14x, FY25 1.07x, LTM 1.05x; set so FY26 ~1.03x and FY27 ~1.01x as cash taxes rise, interest income falls and RNPL flattens unearned fees
A24: B. OPERATING BUILD
A25: Nights & Seats Booked | B25: M | C25: 133.6 | D25: 121.9 | E25: 156.2 | F25: 148.3 | G25: =C25*(1+G7/100) -> 148.964 | H25: =D25*(1+H7/100) -> 134.6995 | I25: =E25*(1+I7/100) -> 171.82 | J25: =F25*(1+J7/100) -> 163.13 | K25: =G25*(1+K7/100) -> 163.8604 | L25: =H25*(1+L7/100) -> 148.16945 | M25: 533 | N25: =E25+F25+G25+H25 -> 588.1635 | O25: =I25+J25+K25+L25 -> 646.97985 | P25: letters
A26: Gross Booking Value | B26: $M | C26: 22892 | D26: 20400 | E26: 29187 | F26: 27247 | G26: =C26*(1+G7/100)*(1+G8/100)*(1+G9/100) -> 26497.194 | H26: =D26*(1+H7/100)*(1+H8/100)*(1+H9/100) -> 23125.387 | I26: =E26*(1+I7/100)*(1+I8/100)*(1+I9/100) -> 32936.596 | J26: =F26*(1+J7/100)*(1+J8/100)*(1+J9/100) -> 30870.851 | K26: =G26*(1+K7/100)*(1+K8/100)*(1+K9/100) -> 30231.47 | L26: =H26*(1+L7/100)*(1+L8/100)*(1+L9/100) -> 26201.063 | M26: 91292 | N26: =E26+F26+G26+H26 -> 106056.58 | O26: =I26+J26+K26+L26 -> 120239.98 | P26: letters / Bloomberg FA (unrounded 3Q25, 1Q26, 2Q26)
A27: ADR (GBV / nights) | B27: $ | C27: =C26/C25 -> 171.34731 | D27: =D26/D25 -> 167.35029 | E27: =E26/E25 -> 186.85659 | F27: =F26/F25 -> 183.72893 | G27: =G26/G25 -> 177.87649 | H27: =H26/H25 -> 171.68131 | I27: =I26/I25 -> 191.69244 | J27: =J26/J25 -> 189.2408 | ... O27: =O26/O25 -> 185.84811
A28: Revenue | B28: $M | C28: 4095 | D28: 2778 | E28: 2678 | F28: 3608 | G28: =C28*(1+G7/100)*(1+G8/100)*(1+G10/100)*(1+(G11+G12)/100) -> 4815.1385 | H28: =D28*(1+H7/100)*(1+H8/100)*(1+H10/100)*(1+(H11+H12)/100) -> 3130.1629 | I28: =E28*(1+I7/100)*(1+I8/100)*(1+I10/100)*(1+(I11+I12)/100) -> 3003.8323 | J28: =F28*(1+J7/100)*(1+J8/100)*(1+J10/100)*(1+(J11+J12)/100) -> 4055.1611 | K28: =G28*(1+K7/100)*(1+K8/100)*(1+K10/100)*(1+(K11+K12)/100) -> 5422.8186 | L28: =H28*(1+L7/100)*(1+L8/100)*(1+L10/100)*(1+(L11+L12)/100) -> 3542.9281 | M28: 12241 | N28: =E28+F28+G28+H28 -> 14231.301 | O28: =I28+J28+K28+L28 -> 16024.74 | P28: letters
A29: Implied take rate | B29: % | C29: =C28/C26*100 -> 17.888345 | D29: =D28/D26*100 -> 13.617647 | E29: =E28/E26*100 -> 9.1753178 | F29: =F28/F26*100 -> 13.241825 | G29: =G28/G26*100 -> 18.172258 | H29: =H28/H26*100 -> 13.535613 | I29: =I28/I26*100 -> 9.1200448 | J29: =J28/J26*100 -> 13.13589 | ... O29: =O28/O26*100 -> 13.327298 | P29: FY25 13.41%; guided 'relatively flat' for FY26
A30: Adj. EBITDA margin | B30: % | C30: =C31/C28*100 -> 50.08547 | D30: =D31/D28*100 -> 28.293737 | E30: =E31/E28*100 -> 19.380134 | F30: =F31/F28*100 -> 34.950111 | G30: =C30+G13 -> 49.98547 | H30: =D30+H13 -> 30.824637 | I30: =E30+I13 -> 19.372734 | J30: =F30+J13 -> 34.942711 | K30: =G30+K13 -> 49.97807 | L30: =H30+L13 -> 30.817237 | M30: =M31/M28*100 -> 35.103341 | N30: =N31/N28*100 -> 36.199999 | O30: =O31/O28*100 -> 36.200027
A31: Adj. EBITDA | B31: $M | C31: 2051 | D31: 786 | E31: 519 | F31: 1261 | G31: =G28*G30/100 -> 2406.8696 | H31: =H28*H30/100 -> 964.86133 | I31: =I28*I30/100 -> 581.92445 | J31: =J28*J30/100 -> 1416.9832 | K31: =K28*K30/100 -> 2710.2201 | L31: =L28*L30/100 -> 1091.8325 | M31: 4297 | N31: =E31+F31+G31+H31 -> 5151.731 | O31: =I31+J31+K31+L31 -> 5800.9603 | P31: letters
A32: Stock-based compensation | B32: $M | C32: 399 | D32: 400 | E32: 410 | F32: 487 | G32: =C32*(1+G14/100) -> 438.9 | H32: =D32*(1+H14/100) -> 440 | I32: =E32*(1+I14/100) -> 446.9 | J32: =F32*(1+J14/100) -> 530.83 | K32: =G32*(1+K14/100) -> 478.401 | L32: =H32*(1+L14/100) -> 479.6 | M32: 1581 | N32: =E32+F32+G32+H32 -> 1775.9 | O32: =I32+J32+K32+L32 -> 1935.731 | P32: letters (adj. EBITDA reconciliation)
A33: D&A | B33: $M | C33: 22 | D33: 23 | E33: 22 | F33: 17 | G33: =G28*G15/100 -> 31.2984 | H33: =H28*H15/100 -> 20.346059 | I33: =I28*I15/100 -> 19.52491 | J33: =J28*J15/100 -> 26.358547 | K33: =K28*K15/100 -> 35.248321 | L33: =L28*L15/100 -> 23.029033 | M33: 91 | N33: =E33+F33+G33+H33 -> 90.644459 | O33: =I33+J33+K33+L33 -> 104.16081 | P33: Bloomberg FA / 10-Q
A34: Operating income (GAAP; adj. EBITDA less SBC less D&A) | B34: $M | C34: 1599 | D34: 193 | E34: 166 | F34: 744 | G34: =G31-G32-G33 -> 1936.6712 | H34: =H31-H32-H33 -> 504.51527 | I34: =I31-I32-I33 -> 115.49954 | J34: =J31-J32-J33 -> 859.79467 | K34: =K31-K32-K33 -> 2196.5708 | L34: =L31-L32-L33 -> 589.20349 | M34: 2320 | N34: =E34+F34+G34+H34 -> 3351.1865 | O34: =I34+J34+K34+L34 -> 3761.0685 | P34: history backed out of pretax income so the P&L ties to reported net income; other add-backs sit here
A35: Interest income | B35: $M | C35: 180 | D35: 162 | E35: 155 | F35: 183 | G35: =G16 -> 170 | H35: =H16 -> 165 | I35: =I16 -> 160 | J35: =J16 -> 160 | K35: =K16 -> 160 | L35: =L16 -> 160 | M35: 705 | N35: =E35+F35+G35+H35 -> 673 | O35: =I35+J35+K35+L35 -> 640 | P35: Bloomberg FA
A36: Interest expense | B36: $M | C36: 0 | D36: 0 | E36: 0 | F36: 37 | G36: =G17 -> 31 | H36: =H17 -> 31 | I36: =I17 -> 31 | J36: =J17 -> 31 | K36: =K17 -> 31 | L36: =L17 -> 31 | M36: 0 | N36: =E36+F36+G36+H36 -> 99 | O36: =I36+J36+K36+L36 -> 124 | P36: Bloomberg FA
A37: Other income (expense), net | B37: $M | C37: 13 | D37: 38 | E37: -40 | F37: 7 | G37: 0 | H37: 0 | I37: 0 | J37: 0 | K37: 0 | L37: 0 | M37: 112 | N37: =E37+F37+G37+H37 -> -33 | O37: =I37+J37+K37+L37 -> 0 | P37: Bloomberg FA; zero forecast
A38: Pretax income | B38: $M | C38: =C34+C35-C36+C37 -> 1792 | D38: =D34+D35-D36+D37 -> 393 | E38: =E34+E35-E36+E37 -> 281 | F38: =F34+F35-F36+F37 -> 897 | G38: =G34+G35-G36+G37 -> 2075.6712 | H38: =H34+H35-H36+H37 -> 638.51527 | I38: =I34+I35-I36+I37 -> 244.49954 | J38: =J34+J35-J36+J37 -> 988.79467 | ... M38: =M34+M35-M36+M37 -> 3137 | N38: =E38+F38+G38+H38 -> 3892.1865 | O38: =I38+J38+K38+L38 -> 4277.0685
A39: Effective tax rate | B39: % | C39: =C40/C38*100 -> 23.325893 | D39: =D40/D38*100 -> 13.231552 | E39: =E40/E38*100 -> 43.060498 | F39: =F40/F38*100 -> 9.0301003 | G39: =G18 -> 18 | H39: =H18 -> 18 | I39: =I18 -> 18 | J39: =J18 -> 18 | K39: =K18 -> 18 | L39: =L18 -> 18 | M39: =M40/M38*100 -> 19.955371 | N39: =N40/N38*100 -> 17.742047 | O39: =O40/O38*100 -> 18
A40: Income tax | B40: $M | C40: 418 | D40: 52 | E40: 121 | F40: 81 | G40: =G38*G39/100 -> 373.62082 | H40: =H38*H39/100 -> 114.93275 | I40: =I38*I39/100 -> 44.009917 | J40: =J38*J39/100 -> 177.98304 | K40: =K38*K39/100 -> 418.60274 | L40: =L38*L39/100 -> 129.27663 | M40: 626 | N40: =E40+F40+G40+H40 -> 690.55357 | O40: =I40+J40+K40+L40 -> 769.87232 | P40: letters; 2Q26 includes a $77M prior-year benefit
A41: Net income (GAAP) | B41: $M | C41: =C38-C40 -> 1374 | D41: =D38-D40 -> 341 | E41: =E38-E40 -> 160 | F41: =F38-F40 -> 816 | G41: =G38-G40 -> 1702.0504 | H41: =H38-H40 -> 523.58253 | I41: =I38-I40 -> 200.48962 | J41: =J38-J40 -> 810.81163 | ... M41: =M38-M40 -> 2511 | N41: =E41+F41+G41+H41 -> 3201.6329 | O41: =I41+J41+K41+L41 -> 3507.1961 | P41: letters
A42: Diluted weighted-average shares | B42: M | C42: 621 | D42: 613 | E42: 608 | F42: 597 | G42: =F42-G19/G20+G21 -> 592.43042 | H42: =G42-H19/H20+H21 -> 587.93401 | I42: =H42-I19/I20+I21 -> 583.50988 | J42: =I42-J19/J20+J21 -> 579.15719 | K42: =J42-K19/K20+K21 -> 574.87507 | L42: =K42-L19/L20+L21 -> 570.66271 | M42: 623 | N42: =AVERAGE(E42:H42) -> 596.34111 | O42: =AVERAGE(I42:L42) -> 577.05121 | P42: 10-Q; forecast = prior less buyback / price plus net RSU issuance
A43: Diluted EPS (GAAP) | B43: $ | C43: =C41/C42 -> 2.2125604 | D43: =D41/D42 -> 0.55628059 | E43: =E41/E42 -> 0.26315789 | F43: =F41/F42 -> 1.3668342 | G43: =G41/G42 -> 2.8729963 | H43: =H41/H42 -> 0.89054642 | I43: =I41/I42 -> 0.3435925 | J43: =J41/J42 -> 1.3999854 | ... O43: =O41/O42 -> 6.0777901 | P43: Street 'adjusted' EPS for ABNB is GAAP-basis (Bloomberg FA 2Q26 1.37 = GAAP)
A44: Free cash flow | B44: $M | C44: 1349 | D44: 521 | E44: 1704 | F44: 1253 | G44: =G31*G22 -> 1684.8087 | H44: =H31*H22 -> 675.40293 | I44: =I31*I22 -> 1862.1582 | J44: =J31*J22 -> 1416.9832 | K44: =K31*K22 -> 1897.1541 | L44: =L31*L22 -> 764.28277 | M44: 4613 | N44: =E44+F44+G44+H44 -> 5317.2117 | O44: =I44+J44+K44+L44 -> 5940.5783 | P44: letters; forecast = adj. EBITDA x conversion (annual-grade; quarterly seasonality of the float is not modelled)
A45: Share repurchases | B45: $M | C45: 877 | D45: 1095 | E45: 1088 | F45: 1051 | G45: =G19 -> 1050 | H45: =H19 -> 1050 | I45: =I19 -> 1050 | J45: =J19 -> 1050 | K45: =K19 -> 1050 | L45: =L19 -> 1050 | M45: 3789 | N45: =E45+F45+G45+H45 -> 4239 | O45: =I45+J45+K45+L45 -> 4200 | P45: letters
...

Sheet Mgmt_Ambition
A1: ABNB management-implied model: Management ambition
A2: The 8 Sep 2026 CEO framing: 'almost every market is accelerating', hotels 3x homes, India +60%, sponsored listings 'a straight shot to $1bn'; take rate +20bp in FY27, margin drifting to 37%
A3: Yellow = input. Blue = reported history. Black = formula. Price $170.19 (11 Sep 2026). Built by analysis/src/reverse_dcf/mgmt_implied_model.py
A5: Line | B5: Unit | C5: 3Q25A | D5: 4Q25A | E5: 1Q26A | F5: 2Q26A | G5: 3Q26E | H5: 4Q26E | I5: 1Q27E | J5: 2Q27E | K5: 3Q27E | L5: 4Q27E | M5: FY25A | N5: FY26E | O5: FY27E | P5: Source / note
A6: A. INPUTS (yellow = management-derived driver; column P = source)
A7: Nights & Seats Booked growth | B7: y/y % | G7: 12.5 | H7: 12 | I7: 12 | J7: 12 | K7: 12 | L7: 12 | P7: 2Q26 letter: 3Q26 'low double-digit'; 4Q26 not guided (FY 'at least mid teens' revenue implies it); FY27 silent
A8: ADR ex-FX growth | B8: y/y % | G8: 4 | H8: 3.5 | I8: 3 | J8: 3 | K8: 3 | L8: 3 | P8: 2Q26 letter: 'moderate increase in ADR due to mix shift and price appreciation'; 1H26 ran +4%
A9: ADR FX effect | B9: pp | G9: 0.3 | H9: -0.4 | I9: -0.4 | J9: 0 | K9: 0.7 | L9: 0 | P9: WS05/WS29 EUR path fit; management does not guide ADR FX beyond 'significantly lower' (1Q26)
A10: Implied take rate, relative change | B10: y/y % | G10: 0 | H10: 0 | I10: 1.5 | J10: 1.5 | K10: 1.5 | L10: 1.5 | P10: 2Q26: 'relatively flat compared to 2025' after customer incentives; +1.5% = +20bp (Ambition only)
A11: Revenue FX after hedging | B11: pp | G11: 3 | H11: -0.4 | I11: -1 | J11: -0.8 | K11: -0.6 | L11: -0.1 | P11: 2Q26 letter: 3Q26 'approximate three percentage point FX tailwind after factoring in our hedging program'; later quarters WS29 fit
A12: Timing / other residual (revenue vs GBV x take rate) | B12: pp | G12: -1.1 | H12: -0.6 | I12: 0.5 | J12: 0.5 | K12: 0.5 | L12: 0.5 | P12: calibrated so 3Q26 revenue hits the guide midpoint (Literal) or midpoint +1.8% (Delivered); RNPL book-vs-stay timing
A13: Adj. EBITDA margin change | B13: y/y pts | G13: 0.3 | H13: 3.077 | I13: 0.4921 | J13: 0.4921 | K13: 0.4921 | L13: 0.4921 | P13: 3Q26: 'down slightly compared to Q3 2025' (50.1%); 4Q26 solved so FY26 = floor (or floor + cushion); FY27 solved for the FY27 margin in row 1
A14: SBC growth | B14: y/y % | G14: 10 | H14: 10 | I14: 8 | J14: 8 | K14: 8 | L14: 8 | P14: 4Q25 letter: 'growth rate of SBC and headcount will be lower than 2025' (FY25 +13.1% letters basis); 1H26 +14.7% so H2 ~+10%
A15: D&A | B15: % revenue | G15: 0.65 | H15: 0.65 | I15: 0.65 | J15: 0.65 | K15: 0.65 | L15: 0.65 | P15: 0.6-0.8% of revenue since 2023
A16: Interest income | B16: $M | G16: 170 | H16: 165 | I16: 160 | J16: 160 | K16: 160 | L16: 160 | P16: $12.1bn cash + ST investments; 2Q26 $183M; falling rates
A17: Interest expense | B17: $M | G17: 31 | H17: 31 | I17: 31 | J17: 31 | K17: 31 | L17: 31 | P17: $2.5bn senior notes issued Mar 2026 at 4.40 / 4.65 / 5.25%
A18: Effective tax rate | B18: % | G18: 18 | H18: 18 | I18: 18 | J18: 18 | K18: 18 | L18: 18 | P18: 2Q26 letter 'high teens' FY26; OBBBA long-term 'mid-to-high teens' (2Q26 call); 1H26 17.1%
... A22: FCF / adj. EBITDA (seasonal) | B22: x | G22: 0.7 | H22: 0.7 | I22: 3.2 | J22: 1 | K22: 0.7 | L22: 0.7 | P22: prior-year quarter ratios 3Q25 0.66x, 4Q25 0.66x, 1Q26 3.28x, 2Q26 0.99x (the float builds in H1, unwinds in H2); annual FY24 1.14x, FY25 1.07x, LTM 1.05x; set so FY26 ~1.03x and FY27 ~1.01x as cash taxes rise, interest income falls and RNPL flattens unearned fees
A24: B. OPERATING BUILD
A25: Nights & Seats Booked | B25: M | C25: 133.6 | D25: 121.9 | E25: 156.2 | F25: 148.3 | G25: =C25*(1+G7/100) -> 150.3 | H25: =D25*(1+H7/100) -> 136.528 | I25: =E25*(1+I7/100) -> 174.944 | J25: =F25*(1+J7/100) -> 166.096 | K25: =G25*(1+K7/100) -> 168.336 | L25: =H25*(1+L7/100) -> 152.91136 | M25: 533 | N25: =E25+F25+G25+H25 -> 591.328 | O25: =I25+J25+K25+L25 -> 662.28736 | P25: letters
A26: Gross Booking Value | B26: $M | C26: 22892 | D26: 20400 | E26: 29187 | F26: 27247 | G26: =C26*(1+G7/100)*(1+G8/100)*(1+G9/100) -> 26863.991 | H26: =D26*(1+H7/100)*(1+H8/100)*(1+H9/100) -> 23553.089 | I26: =E26*(1+I7/100)*(1+I8/100)*(1+I9/100) -> 33535.443 | J26: =F26*(1+J7/100)*(1+J8/100)*(1+J9/100) -> 31432.139 | K26: =G26*(1+K7/100)*(1+K8/100)*(1+K9/100) -> 31207.232 | L26: =H26*(1+L7/100)*(1+L8/100)*(1+L9/100) -> 27170.844 | M26: 91292 | N26: =E26+F26+G26+H26 -> 106851.08 | O26: =I26+J26+K26+L26 -> 123345.66 | P26: letters / Bloomberg FA (unrounded 3Q25, 1Q26, 2Q26)
A27: ADR (GBV / nights) | B27: $ | C27: =C26/C25 -> 171.34731 | D27: =D26/D25 -> 167.35029 | E27: =E26/E25 -> 186.85659 | F27: =F26/F25 -> 183.72893 | G27: =G26/G25 -> 178.7358 | H27: =H26/H25 -> 172.51472 | I27: =I26/I25 -> 191.69244 | J27: =J26/J25 -> 189.2408 | ... O27: =O26/O25 -> 186.2419
A28: Revenue | B28: $M | C28: 4095 | D28: 2778 | E28: 2678 | F28: 3608 | G28: =C28*(1+G7/100)*(1+G8/100)*(1+G10/100)*(1+(G11+G12)/100) -> 4882.1818 | H28: =D28*(1+H7/100)*(1+H8/100)*(1+H10/100)*(1+(H11+H12)/100) -> 3188.055 | I28: =E28*(1+I7/100)*(1+I8/100)*(1+I10/100)*(1+(I11+I12)/100) -> 3120.0025 | J28: =F28*(1+J7/100)*(1+J8/100)*(1+J10/100)*(1+(J11+J12)/100) -> 4211.9478 | K28: =G28*(1+K7/100)*(1+K8/100)*(1+K10/100)*(1+(K11+K12)/100) -> 5710.8497 | L28: =H28*(1+L7/100)*(1+L8/100)*(1+L10/100)*(1+(L11+L12)/100) -> 3747.838 | M28: 12241 | N28: =E28+F28+G28+H28 -> 14356.237 | O28: =I28+J28+K28+L28 -> 16790.638 | P28: letters
A29: Implied take rate | B29: % | C29: =C28/C26*100 -> 17.888345 | D29: =D28/D26*100 -> 13.617647 | E29: =E28/E26*100 -> 9.1753178 | F29: =F28/F26*100 -> 13.241825 | G29: =G28/G26*100 -> 18.173703 | H29: =H28/H26*100 -> 13.535613 | I29: =I28/I26*100 -> 9.3035972 | J29: =J28/J26*100 -> 13.400131 | ... O29: =O28/O26*100 -> 13.612671 | P29: FY25 13.41%; guided 'relatively flat' for FY26
A30: Adj. EBITDA margin | B30: % | C30: =C31/C28*100 -> 50.08547 | D30: =D31/D28*100 -> 28.293737 | E30: =E31/E28*100 -> 19.380134 | F30: =F31/F28*100 -> 34.950111 | G30: =C30+G13 -> 50.38547 | H30: =D30+H13 -> 31.370737 | I30: =E30+I13 -> 19.872234 | J30: =F30+J13 -> 35.442211 | K30: =G30+K13 -> 50.87757 | L30: =H30+L13 -> 31.862837 | M30: =M31/M28*100 -> 35.103341 | N30: =N31/N28*100 -> 36.500001 | O30: =O31/O28*100 -> 36.999968
A31: Adj. EBITDA | B31: $M | C31: 2051 | D31: 786 | E31: 519 | F31: 1261 | G31: =G28*G30/100 -> 2459.9103 | H31: =H28*H30/100 -> 1000.1163 | I31: =I28*I30/100 -> 620.01421 | J31: =J28*J30/100 -> 1492.8074 | K31: =K28*K30/100 -> 2905.5416 | L31: =L28*L30/100 -> 1194.1675 | M31: 4297 | N31: =E31+F31+G31+H31 -> 5240.0266 | O31: =I31+J31+K31+L31 -> 6212.5307 | P31: letters
A32: Stock-based compensation | B32: $M | C32: 399 | D32: 400 | E32: 410 | F32: 487 | G32: =C32*(1+G14/100) -> 438.9 | H32: =D32*(1+H14/100) -> 440 | I32: =E32*(1+I14/100) -> 442.8 | J32: =F32*(1+J14/100) -> 525.96 | K32: =G32*(1+K14/100) -> 474.012 | L32: =H32*(1+L14/100) -> 475.2 | M32: 1581 | N32: =E32+F32+G32+H32 -> 1775.9 | O32: =I32+J32+K32+L32 -> 1917.972 | P32: letters (adj. EBITDA reconciliation)
A33: D&A | B33: $M | C33: 22 | D33: 23 | E33: 22 | F33: 17 | G33: =G28*G15/100 -> 31.734182 | H33: =H28*H15/100 -> 20.722358 | I33: =I28*I15/100 -> 20.280016 | J33: =J28*J15/100 -> 27.37766 | K33: =K28*K15/100 -> 37.120523 | L33: =L28*L15/100 -> 24.360947 | M33: 91 | N33: =E33+F33+G33+H33 -> 91.45654 | O33: =I33+J33+K33+L33 -> 109.13915 | P33: Bloomberg FA / 10-Q
A34: Operating income (GAAP; adj. EBITDA less SBC less D&A) | B34: $M | C34: 1599 | D34: 193 | E34: 166 | F34: 744 | G34: =G31-G32-G33 -> 1989.2761 | H34: =H31-H32-H33 -> 539.39398 | I34: =I31-I32-I33 -> 156.9342 | J34: =J31-J32-J33 -> 939.46975 | K34: =K31-K32-K33 -> 2394.409 | L34: =L31-L32-L33 -> 694.60655 | M34: 2320 | N34: =E34+F34+G34+H34 -> 3438.6701 | O34: =I34+J34+K34+L34 -> 4185.4195 | P34: history backed out of pretax income so the P&L ties to reported net income; other add-backs sit here
A35: Interest income | B35: $M | C35: 180 | D35: 162 | E35: 155 | F35: 183 | G35: =G16 -> 170 | H35: =H16 -> 165 | I35: =I16 -> 160 | J35: =J16 -> 160 | K35: =K16 -> 160 | L35: =L16 -> 160 | M35: 705 | N35: =E35+F35+G35+H35 -> 673 | O35: =I35+J35+K35+L35 -> 640 | P35: Bloomberg FA
A36: Interest expense | B36: $M | C36: 0 | D36: 0 | E36: 0 | F36: 37 | G36: =G17 -> 31 | H36: =H17 -> 31 | I36: =I17 -> 31 | J36: =J17 -> 31 | K36: =K17 -> 31 | L36: =L17 -> 31 | M36: 0 | N36: =E36+F36+G36+H36 -> 99 | O36: =I36+J36+K36+L36 -> 124 | P36: Bloomberg FA
A37: Other income (expense), net | B37: $M | C37: 13 | D37: 38 | E37: -40 | F37: 7 | G37: 0 | H37: 0 | I37: 0 | J37: 0 | K37: 0 | L37: 0 | M37: 112 | N37: =E37+F37+G37+H37 -> -33 | O37: =I37+J37+K37+L37 -> 0 | P37: Bloomberg FA; zero forecast
A38: Pretax income | B38: $M | C38: =C34+C35-C36+C37 -> 1792 | D38: =D34+D35-D36+D37 -> 393 | E38: =E34+E35-E36+E37 -> 281 | F38: =F34+F35-F36+F37 -> 897 | G38: =G34+G35-G36+G37 -> 2128.2761 | H38: =H34+H35-H36+H37 -> 673.39398 | I38: =I34+I35-I36+I37 -> 285.9342 | J38: =J34+J35-J36+J37 -> 1068.4697 | ... M38: =M34+M35-M36+M37 -> 3137 | N38: =E38+F38+G38+H38 -> 3979.6701 | O38: =I38+J38+K38+L38 -> 4701.4195
A39: Effective tax rate | B39: % | C39: =C40/C38*100 -> 23.325893 | D39: =D40/D38*100 -> 13.231552 | E39: =E40/E38*100 -> 43.060498 | F39: =F40/F38*100 -> 9.0301003 | G39: =G18 -> 18 | H39: =H18 -> 18 | I39: =I18 -> 18 | J39: =J18 -> 18 | K39: =K18 -> 18 | L39: =L18 -> 18 | M39: =M40/M38*100 -> 19.955371 | N39: =N40/N38*100 -> 17.747718 | O39: =O40/O38*100 -> 18
A40: Income tax | B40: $M | C40: 418 | D40: 52 | E40: 121 | F40: 81 | G40: =G38*G39/100 -> 383.0897 | H40: =H38*H39/100 -> 121.21092 | I40: =I38*I39/100 -> 51.468155 | J40: =J38*J39/100 -> 192.32455 | K40: =K38*K39/100 -> 454.21363 | L40: =L38*L39/100 -> 148.24918 | M40: 626 | N40: =E40+F40+G40+H40 -> 706.30061 | O40: =I40+J40+K40+L40 -> 846.25551 | P40: letters; 2Q26 includes a $77M prior-year benefit
A41: Net income (GAAP) | B41: $M | C41: =C38-C40 -> 1374 | D41: =D38-D40 -> 341 | E41: =E38-E40 -> 160 | F41: =F38-F40 -> 816 | G41: =G38-G40 -> 1745.1864 | H41: =H38-H40 -> 552.18307 | I41: =I38-I40 -> 234.46604 | J41: =J38-J40 -> 876.14519 | ... M41: =M38-M40 -> 2511 | N41: =E41+F41+G41+H41 -> 3273.3695 | O41: =I41+J41+K41+L41 -> 3855.164 | P41: letters
A42: Diluted weighted-average shares | B42: M | C42: 621 | D42: 613 | E42: 608 | F42: 597 | G42: =F42-G19/G20+G21 -> 592.43042 | H42: =G42-H19/H20+H21 -> 587.93401 | I42: =H42-I19/I20+I21 -> 583.50988 | J42: =I42-J19/J20+J21 -> 579.15719 | K42: =J42-K19/K20+K21 -> 574.87507 | L42: =K42-L19/L20+L21 -> 570.66271 | M42: 623 | N42: =AVERAGE(E42:H42) -> 596.34111 | O42: =AVERAGE(I42:L42) -> 577.05121 | P42: 10-Q; forecast = prior less buyback / price plus net RSU issuance
A43: Diluted EPS (GAAP) | B43: $ | C43: =C41/C42 -> 2.2125604 | D43: =D41/D42 -> 0.55628059 | E43: =E41/E42 -> 0.26315789 | F43: =F41/F42 -> 1.3668342 | G43: =G41/G42 -> 2.9458082 | H43: =H41/H42 -> 0.93919226 | I43: =I41/I42 -> 0.40182017 | J43: =J41/J42 -> 1.5127934 | ... O43: =O41/O42 -> 6.6808005 | P43: Street 'adjusted' EPS for ABNB is GAAP-basis (Bloomberg FA 2Q26 1.37 = GAAP)
A44: Free cash flow | B44: $M | C44: 1349 | D44: 521 | E44: 1704 | F44: 1253 | G44: =G31*G22 -> 1721.9372 | H44: =H31*H22 -> 700.08144 | I44: =I31*I22 -> 1984.0455 | J44: =J31*J22 -> 1492.8074 | K44: =K31*K22 -> 2033.8791 | L44: =L31*L22 -> 835.91725 | M44: 4613 | N44: =E44+F44+G44+H44 -> 5379.0186 | O44: =I44+J44+K44+L44 -> 6346.6492 | P44: letters; forecast = adj. EBITDA x conversion (annual-grade; quarterly seasonality of the float is not modelled)
A45: Share repurchases | B45: $M | C45: 877 | D45: 1095 | E45: 1088 | F45: 1051 | G45: =G19 -> 1050 | H45: =H19 -> 1050 | I45: =I19 -> 1050 | J45: =J19 -> 1050 | K45: =K19 -> 1050 | L45: =L19 -> 1050 | M45: 3789 | N45: =E45+F45+G45+H45 -> 4239 | O45: =I45+J45+K45+L45 -> 4200 | P45: letters
...

Sheet Valuation
A1: Management-implied target prices (12-month, FY27E exit)
A2: Target = (multiple x FY27E metric + end-FY27 net cash) / end-FY27 diluted shares; P/E lens uses FY27E GAAP EPS directly. Multiples are inputs (yellow).
A4: Share price | B4: 170.19 | C4: 11 Sep 2026 close
A5: Diluted shares now (M) | B5: 597 | C5: 2Q26 diluted weighted average
A6: Net cash ex float now ($M) | B6: 9593 | C6: 30 Jun 2026: $12,069M cash + ST investments less $2,476M notes
A7: Market cap ($M) | B7: =B4*B5 -> 101603.43
A8: Enterprise value ($M) | B8: =B7-B6 -> 92010.43
A10: FY27E metric | B10: Guide literal | C10: Guide as delivered | D10: Management ambition | E10: Street (Zacks / S&P, 3-4 Sep 2026)
A11: Revenue ($M) | B11: =Mgmt_Literal!O28 -> 15630.401 | C11: =Mgmt_Delivered!O28 -> 16024.74 | D11: =Mgmt_Ambition!O28 -> 16790.638 | E11: 15745 | F11: Zacks $15,730M / S&P $15,760M
A12: Adj. EBITDA ($M) | B12: =Mgmt_Literal!O31 -> 5548.7972 | C12: =Mgmt_Delivered!O31 -> 5800.9603 | D12: =Mgmt_Ambition!O31 -> 6212.5307
A13: Adj. EBITDA margin (%) | B13: =Mgmt_Literal!O30 -> 35.500032 | C13: =Mgmt_Delivered!O30 -> 36.200027 | D13: =Mgmt_Ambition!O30 -> 36.999968
A14: GAAP EPS ($) | B14: =Mgmt_Literal!O43 -> 5.7231043 | C14: =Mgmt_Delivered!O43 -> 6.0777901 | D14: =Mgmt_Ambition!O43 -> 6.6808005 | E14: 6.08 | F14: Zacks $6.02 / S&P $6.14
A15: FCF ($M) | B15: =Mgmt_Literal!O44 -> 5738.1292 | C15: =Mgmt_Delivered!O44 -> 5940.5783 | D15: =Mgmt_Ambition!O44 -> 6346.6492
A16: SBC ($M) | B16: =Mgmt_Literal!O32 -> 1935.731 | C16: =Mgmt_Delivered!O32 -> 1935.731 | D16: =Mgmt_Ambition!O32 -> 1917.972
A17: Net cash, end-FY27 ($M) | B17: =Mgmt_Literal!O47 -> 10298.181 | C17: =Mgmt_Delivered!O47 -> 10608.669 | D17: =Mgmt_Ambition!O47 -> 11082.763
A18: Diluted shares, 4Q27 (M) | B18: =Mgmt_Literal!L42 -> 570.66271 | C18: =Mgmt_Delivered!L42 -> 570.66271 | D18: =Mgmt_Ambition!L42 -> 570.66271
A19: FY26E revenue ($M) | B19: =Mgmt_Literal!N28 -> 14077.151 | C19: =Mgmt_Delivered!N28 -> 14231.301 | D19: =Mgmt_Ambition!N28 -> 14356.237 | E19: 14130 | F19: Zacks $14,100M / S&P $14,160M
A20: FY26E adj. EBITDA ($M) | B20: =Mgmt_Literal!N31 -> 4997.3899 | C20: =Mgmt_Delivered!N31 -> 5151.731 | D20: =Mgmt_Ambition!N31 -> 5240.0266
A21: FY26E GAAP EPS ($) | B21: =Mgmt_Literal!N43 -> 5.1579454 | C21: =Mgmt_Delivered!N43 -> 5.3687946 | D21: =Mgmt_Ambition!N43 -> 5.4890891 | E21: 5.255 | F21: Zacks $5.23 / S&P $5.28
A23: What $170.19 pays for each case today
A24: EV / FY26E adj. EBITDA (x) | B24: =$B$8/B20 -> 18.411697 | C24: =$B$8/C20 -> 17.8601 | D24: =$B$8/D20 -> 17.559153
A25: EV / FY27E adj. EBITDA (x) | B25: =$B$8/B12 -> 16.582049 | C25: =$B$8/C12 -> 15.861241 | D25: =$B$8/D12 -> 14.810459
A26: P / FY26E EPS (x) | B26: =$B$4/B21 -> 32.995696 | C26: =$B$4/C21 -> 31.699853 | D26: =$B$4/D21 -> 31.005144 | E26: =$B$4/E21 -> 32.386299
A27: P / FY27E EPS (x) | B27: =$B$4/B14 -> 29.737358 | C27: =$B$4/C14 -> 28.001954 | D27: =$B$4/D14 -> 25.474492 | E27: =$B$4/E14 -> 27.991776
A28: EV / FY27E FCF (x) | B28: =$B$8/B15 -> 16.034918 | C28: =$B$8/C15 -> 15.488464 | D28: =$B$8/D15 -> 14.497482
A29: FY27E FCF yield on market cap (%) | B29: =B15/$B$7*100 -> 5.6475743 | C29: =C15/$B$7*100 -> 5.8468285 | D29: =D15/$B$7*100 -> 6.2464911
A32: Multiples (inputs) | B32: Low | C32: Mid | D32: High | E32: Rationale
A33: EV / FY27E adj. EBITDA | B33: 13.5 | C33: 16.5 | D33: 18.5 | E33: WS12 recommendation: ABNB's own multiple vs growth 2023-26, 19-name cross-section, fade DCF all land 13.5-18.5x; today 16-18x
A34: P / FY27E GAAP EPS | B34: 22 | C34: 27 | D34: 30 | E34: ABNB at $170 = 28x Street FY27 EPS; 2023-26 LTM GAAP P/E 25-40x; BKNG 16x, NFLX 21x, UBER 18x NTM
A35: EV / FY27E FCF | B35: 14 | C35: 17 | D35: 20 | E35: WS12 haircut set 11.3/14.3/17.3x lifted for FCF running 2-7% above adj. EBITDA; today ~16x FY27E
A38: Target price ($ / share, FY27E exit) | B38: Guide literal | C38: Guide as delivered | D38: Management ambition | E38: Street FY27 (P/E lens only) | F38: Upside vs price, Delivered case
A39: EV / FY27E adj. EBITDA x Low | B39: =($B$33*B12+B17)/B18 -> 149.31227 | C39: =($B$33*C12+C17)/C18 -> 155.8217 | D39: =($B$33*D12+D17)/D18 -> 166.38888 | F39: =C39/$B$4-1 -> -0.084425061
A40: EV / FY27E adj. EBITDA x Mid | B40: =($C$33*B12+B17)/B18 -> 178.48255 | C40: =($C$33*C12+C17)/C18 -> 186.31761 | D40: =($C$33*D12+D17)/D18 -> 199.04843 | F40: =C40/$B$4-1 -> 0.094762399
A41: EV / FY27E adj. EBITDA x High | B41: =($D$33*B12+B17)/B18 -> 197.9294 | C41: =($D$33*C12+C17)/C18 -> 206.64822 | D41: =($D$33*D12+D17)/D18 -> 220.82147 | F41: =C41/$B$4-1 -> 0.21422071
A42: P / FY27E GAAP EPS x Low | B42: =$B$34*B14 -> 125.90829 | C42: =$B$34*C14 -> 133.71138 | D42: =$B$34*D14 -> 146.97761 | E42: =$B$34*E14 -> 133.76 | F42: =C42/$B$4-1 -> -0.21434055
A43: P / FY27E GAAP EPS x Mid | B43: =$C$34*B14 -> 154.52382 | C43: =$C$34*C14 -> 164.10033 | D43: =$C$34*D14 -> 180.38161 | E43: =$C$34*E14 -> 164.16 | F43: =C43/$B$4-1 -> -0.035781581
A44: P / FY27E GAAP EPS x High | B44: =$D$34*B14 -> 171.69313 | C44: =$D$34*C14 -> 182.3337 | D44: =$D$34*D14 -> 200.42401 | E44: =$D$34*E14 -> 182.4 | F44: =C44/$B$4-1 -> 0.071353799
A45: EV / FY27E FCF x Low | B45: =($B$35*B15+B17)/B18 -> 158.81884 | C45: =($B$35*C15+C17)/C18 -> 164.32958 | D45: =($B$35*D15+D17)/D18 -> 175.12245 | F45: =C45/$B$4-1 -> -0.034434557
A46: EV / FY27E FCF x Mid | B46: =($C$35*B15+B17)/B18 -> 188.98445 | C46: =($C$35*C15+C17)/C18 -> 195.55947 | D46: =($C$35*D15+D17)/D18 -> 208.48708 | F46: =C46/$B$4-1 -> 0.1490656
A47: EV / FY27E FCF x High | B47: =($D$35*B15+B17)/B18 -> 219.15006 | C47: =($D$35*C15+C17)/C18 -> 226.78937 | D47: =($D$35*D15+D17)/D18 -> 241.8517 | F47: =C47/$B$4-1 -> 0.33256576
...

Sheet Street
A1: Consensus as pulled (comparison column, not an input)
A3: Item | B3: Value | C3: Source
A4: 3Q26E revenue ($M) | B4: 4743.7 | C4: Bloomberg FA consensus PDF (OneDrive, pulled 4 Sep 2026); Zacks $4,740M (7 est.)
A5: 3Q26E nights (M) | B5: 148.91 | C5: Bloomberg FA; +11.1% y/y
A6: 3Q26E GBV ($M) | B6: 26352.9 | C6: Bloomberg FA; +15.1%
A7: 3Q26E ADR ($) | B7: 177.02 | C7: Bloomberg FA; +3.3%
A8: 3Q26E take rate (%) | B8: 18 | C8: Bloomberg FA
A9: 3Q26E adj. EBITDA ($M) | B9: 2359.9 | C9: Bloomberg FA; margin 49.7%
A10: 3Q26E FCF ($M) | B10: 1969.9 | C10: Bloomberg FA
A11: 3Q26E diluted EPS ($) | B11: 2.88 | C11: Bloomberg FA 2.86-2.88; Zacks 2.87 (11 est., 2.52-3.28)
A12: 4Q26E revenue ($M) | B12: 3154 | C12: Bloomberg FA; Zacks $3,200M (10 est., 3,050-3,700)
A13: 4Q26E nights (M) | B13: 134.19 | C13: Bloomberg FA; +10.1%
A14: 4Q26E GBV ($M) | B14: 22992.9 | C14: Bloomberg FA; +12.7%
A15: 4Q26E ADR ($) | B15: 171.29 | C15: Bloomberg FA; +2.3%
... A24: Share price ($) | B24: 170.19 | C24: 11 Sep 2026

Sheet Mgmt_Statements
A1: What management is looking at, by area: near term (3Q26 / FY26), mid term (FY27+), how it enters the Delivered case, and how reliable that line has been
A3: Area | B3: Near term: what they said (3Q26 / FY26) | C3: Mid term: what they said (FY27 and beyond) | D3: Number used (Delivered case) | E3: Track record of this line | F3: Source
A4: Nights & Seats Booked | B4: 3Q26 'low double-digit growth'; FY26 'accelerated pace of Nights and Seats Booked we've observed'; 2Q26 +10.3% with every region up, expansion markets ~2x core, first-time bookers +11% (highest in four years), app nights +23% = 64% of total | C4: No number. 8 Sep: 'almost every market is accelerating', 'four of the five countries [70% of the business] are accelerating', India +60%; core business 'could probably be double the size' | D4: 3Q26 +11.5%, 4Q26 +10.5%, FY27 +10.0% | E4: Bucket guides: 3 of 3 since 4Q25 printed ABOVE the range (+1 to +5pts). Directional guides 92% met (n=13) | F4: 2Q26 letter p.6; 2Q26 call; Communacopia 8 Sep 2026
A5: ADR | B5: 3Q26 'moderate increase in ADR due to mix shift and price appreciation'; 2Q26 +5% (+4% ex-FX), 'noticeable strength in North America and Europe'; bedroom nights +12% vs nights +10% (larger homes keep growing fastest) | C5: AI pricing model 'one of the biggest single levers for growth', 'many multiples bigger than RNPL' -> aimed at affordability, i.e. it argues for LOWER host prices over time, not higher; ADR ex-FX above ~3% is mix, not price | D5: ex-FX +3.5% 3Q26, +3.0% thereafter; FX +0.3 / -0.4 / -0.4 / 0 / +0.7 / 0 pp | E5: ADR floors/points 16 of 18 met or beaten | F5: 2Q26 letter p.10; 2Q26 call (pricing answer)
A6: GBV | B6: 3Q26 'mid teens' (nights low double digits + moderate ADR); 2Q26 +16% (+15% ex-FX); RNPL >20% of GBV, eligibility expanded in July | C6: 'approaching $100 billion in GBV' (8 Sep); FY25 was $91.3bn, FY26 lands ~$106bn in the Delivered case | D6: 3Q26 +15.4%, 4Q26 +13.4%, FY27 +13.3% | E6: Bucket guides beaten by 4-6pts in all three cases since 4Q25 | F6: 2Q26 letter; Communacopia
A7: Take rate / monetisation | B7: FY26 'relatively flat compared to 2025' (13.41%) after RNPL timing and 'higher customer incentives related to new businesses'; 'absent these incentives... slightly higher'; 3Q26 'relatively in-line'; single fee to be completed by year-end (half of listings already) | C7: Sponsored listings 'a pretty easy straight shot to $1 billion incremental high margin revenue' (8 Sep, undated); travel insurance 'very high margin... does quite well'; advertising deferred behind AI search | D7: flat in Literal/Delivered; +20bp FY27 in Ambition | E7: The weak line: 59% kept (n=17). FY25 promised +20bp, printed -16bp. 1Q26 'lift full-year take rate' withdrawn at 2Q26 | F7: 2Q26 call prepared remarks; 31a S165/S166/S110
A8: Cancellations / RNPL | B8: Not disclosed. Nights and GBV are reported net of cancellations. RNPL defers payment to near check-in; 2Q26: 'absent RNPL... unearned fees would have grown y/y'; 1Q26 letter predicted unearned fees higher y/y in 3Q26 (forward-testable on 5 Nov). 1Q26: Middle East cancellations cost ~1pt of nights | C8: Nothing. The team's own RNPL ledger (overnight2 D) models a -0.1 to -1.4pt cancellation drag on 3Q26/4Q26 nights; management has never sized it | D8: Inside the -0.6 to -1.1pp timing residual | E8: n/a (never guided) | F8: 2Q26 call CFO; 1Q26 letter; docs/overnight2/SYNTHESIS.md
A9: Revenue | B9: 3Q26 $4.69-4.77bn (+15-17%) incl. ~3pp FX after hedging; FY26 'at least mid teens' (raised from 'low double digits' in Feb and 'low-to-mid teens' in May) | C9: No FY27 number ('I'm not going to give you a specific guide for 2027 and beyond'). Pattern: Feb guide is a floor, raised twice, printed 1-3pp above | D9: 3Q26 $4,815M (+17.6%), 4Q26 $3,131M (+12.7%), FY26 $14.23bn (+16.3%), FY27 $15.99bn (+12.4%) | E9: 19 of 19 quarterly ranges beaten at the midpoint (median +2.5%, last eight +1.8%); 15 of 19 above the top | F9: 2Q26 letter p.6; 02_guidance_ledger.csv
A10: FX | B10: ~3pp tailwind to 3Q26 revenue after hedging (was 0 / +3 / +4 in 4Q25-2Q26); ADR FX 'significantly lower in Q2 than Q1' | C10: Silent; hedging programme unchanged. Consensus EUR path turns FX to a -0.4 to -1.0pp headwind from 4Q26 | D10: WS29 schedule | E10: FX statements 100% kept but they only ever guide one quarter | F10: 2Q26 letter; 28_fx-hedge-disclosures.md
A11: Adj. EBITDA margin | B11: FY26 'at least 35.5%' (raised from 'stable' -> '>=35%' -> '>=35.5%'); 3Q26 'down slightly compared to Q3 2025' (50.1%) 'due to timing of investments'; 2Q26 printed 35.0% (+1.3pts) on ops & support and product-dev efficiency, offset by S&M | C11: 'There's a relative floor in our ability to continue to invest against that' (2Q26); 'we basically have remained pretty steady, 35% margins' (8 Sep); rule: find variable-cost efficiencies every year and reinvest most of them | D11: 3Q26 50.0%, 4Q26 30.8%, FY26 36.2%, FY27 36.2% | E11: Total-margin statements 91% kept (n=43). Floors beaten by +140bp (FY24), +60bp (FY25). Floor becomes a point ('approximately X') at the Q3 print | F11: 2Q26 letter; 31a note
A12: Cost lines | B12: Cost of revenue 'scale somewhat linearly'; ops & support cost per booking -16% y/y (AI resolves ~45% of tickets); product dev: 'we don't need to grow our head count at levels that we did in the past'; S&M: 'where you will see some incremental investment'; AI spend: guidance 'assumes a material increase' (unsized) | C12: No FY27 line has a number. Brand marketing is fixed per market ('surgical topper' for performance); hotels build-out unbudgeted; services are partnerships ('we do not see a big incurring of cost') | D12: Not modelled line by line here (margin is the policy variable per 31a); WS30/31 hold the line build | E12: Ops & support 100% kept (n=13); brand marketing 63% (n=35); product dev 60%; SBC 40% | F12: 31a_mgmt-margin-statements.md
A13: SBC / share count | B13: FY26 SBC growth 'lower than 2025'; 1H26 +14.7%; 37.8M RSUs + 5.7M options outstanding; diluted WA 597M in 2Q26 (-4.6% y/y) | C13: Silent; the SBC-equals-headcount promise was withdrawn at 4Q25 | D13: SBC +10% H2-26, +9% FY27; shares -4.5M/q net | E13: SBC guides 40% kept (n=5) | F13: 4Q25 letter; 2Q26 10-Q
A14: Capital return | B14: $1.1bn repurchased in 2Q26, $2.1bn in 1H26; $3.4bn authorisation remaining (2Q26 call); 'returning capital to shareholders remains a core component' | C14: Nothing beyond the authorisation; at the current pace it is exhausted by ~2Q27, so a new programme is the likely 4Q26/1Q27 announcement | D14: $1,050M/q through FY27 ($4.2bn/yr) | E14: FY24 $3.4bn, FY25 $3.8bn delivered; never guided | F14: 2Q26 call CFO; 10-Q
... A19: Regulation | B19: Not in guidance. 2Q26 letter: usual risk-factor language only | C19: Nothing | D19: Zero; the team's regulatory Monte Carlo (PR #15) is the only quantification | E19: n/a | F19: regulatory package, PR #19

Sheet Recon
A1: Excel (recalculated) vs Python mirror; max abs diff: | B1: 0.0067673114
A3: scenario | B3: period | C3: line | D3: excel | E3: python | F3: diff
A4: Literal | B4: 3Q26 | C4: nights | D4: 146.96 | E4: 146.96 | F4: 0
A5: Literal | B5: 3Q26 | C5: gbv | D5: 26014.446 | E5: 26014.446 | F5: 0
A6: Literal | B6: 3Q26 | C6: adr | D6: 177.01719 | E6: 177.01719 | F6: 0
A7: Literal | B7: 3Q26 | C7: rev | D7: 4730.0012 | E7: 4730 | F7: 0.001170895
A8: Literal | B8: 3Q26 | C8: take | D8: 18.18221 | E8: 18.182205 | F8: 4.5009415e-06
A9: Literal | B9: 3Q26 | C9: margin | D9: 49.48547 | E9: 49.48547 | F9: 0
A10: Literal | B10: 3Q26 | C10: ebitda | D10: 2340.6633 | E10: 2340.6627 | F10: 0.00057942289
A11: Literal | B11: 3Q26 | C11: sbc | D11: 438.9 | E11: 438.9 | F11: 0
A12: Literal | B12: 3Q26 | C12: da | D12: 30.745008 | E12: 30.745 | F12: 7.6108175e-06
A13: Literal | B13: 3Q26 | C13: opinc | D13: 1871.0183 | E13: 1871.0177 | F13: 0.00057181208
A14: Literal | B14: 3Q26 | C14: pretax | D14: 2010.0183 | E14: 2010.0177 | F14: 0.00057181208
A15: Literal | B15: 3Q26 | C15: tax | D15: 361.8033 | E15: 361.80319 | F15: 0.00010292617
... A411: Ambition | B411: FY27 | C411: netcash | D411: 11082.763 | E411: 11082.769 | F411: -0.0066569714
