Workbook
Name Scenario: Inputs!$B$4
Name SharePrice: Inputs!$F$8
Name CostOfEquity: Inputs!$F$11
Name ExitMultiple: Inputs!$F$14

Sheet Inputs
A1: ABNB driver model - Inputs
A2: Overnight run 6-7 Sep 2026 (workstream 13). Yellow cells are inputs; everything downstream is a live formula. The other hard numbers in the file are the History actuals table, the external Street / Card bars (each with its vendor and date) and the Recon sheet's Python-mirror column. Sources name the workstream that supplied the value.
A4: SCENARIO SELECTOR (1 = Bear, 2 = Base, 3 = Bull) | B4: 2 | G4: Drives the Active column here and the Active column on Valuation (sections 1-4) and Card_5Nov. All three scenarios are computed in full on Revenue / Costs / Cash, so the Bear / Base / Bull columns never move when this cell changes.
A6: A. VALUATION AND CONTROL INPUTS
A7: Parameter | B7: Unit | C7: Bear | D7: Base | E7: Bull | F7: Active | G7: Source
A8: Share price (4 Sep 2026 close) | B8: $ | C8: 181.94 | D8: 181.94 | E8: 181.94 | F8: =CHOOSE(Inputs!$B$4,C8,D8,E8) | G8: Close 4 Sep 2026
A9: Net cash ex float, 30 Jun 2026 ($M) | B9: $M | C9: 9593 | D9: 9593 | E9: 9593 | F9: =CHOOSE(Inputs!$B$4,C9,D9,E9) | G9: WS12; 2Q26 XBRL. Funds held for clients ($12,224M) excluded
A10: Diluted shares, 2Q26 (M) | B10: M | C10: 597 | D10: 597 | E10: 597 | F10: =CHOOSE(Inputs!$B$4,C10,D10,E10) | G10: 2Q26 diluted weighted-average (XBRL)
A11: Cost of equity | C11: 0.115 | D11: 0.105 | E11: 0.103 | F11: =CHOOSE(Inputs!$B$4,C11,D11,E11) | G11: WS09 10.5-11.5% (Rf 4.78% + beta 1.2-1.3 x ERP 4.5-5.5%); WS12 CAPM 10.3%
A12: Terminal growth | C12: 0.025 | D12: 0.03 | E12: 0.03 | F12: =CHOOSE(Inputs!$B$4,C12,D12,E12) | G12: WS12 2.5-3.0%
A13: DCF start growth (year-1 FCF growth, fades to terminal) | C13: 0 | D13: 0.09 | E13: 0.15 | F13: =CHOOSE(Inputs!$B$4,C13,D13,E13) | G13: a round number just under the model's own FY2026E-FY2028E FCF CAGR of 9.9%, clipped to 0-15%. A ten-year fade started from a single scenario year's FCF growth (-21% bear, +26% bull) is an extrapolation artefact, not a valuation
A14: Exit EV / FY27E adj. EBITDA (x) | B14: x | C14: 13.5 | D14: 16.5 | E14: 18.5 | F14: =CHOOSE(Inputs!$B$4,C14,D14,E14) | G14: WS12 12_exit_multiple_recommendation.csv (time-series / cross-section / intrinsic blend)
A15: Exit EV / FY27E FCF (x) | B15: x | C15: 11.3 | D15: 14.3 | E15: 17.3 | F15: =CHOOSE(Inputs!$B$4,C15,D15,E15) | G15: 5 Sep set (15/19/23x) rescaled by WS12's 0.75x haircut to the EBITDA multiple
A16: Exit P / FY27E SBC-adj. FCF (x) | B16: x | C16: 15 | D16: 19.5 | E16: 24 | F16: =CHOOSE(Inputs!$B$4,C16,D16,E16) | G16: same 0.75x haircut on the 5 Sep 20/26/32x
A17: Exit P / FY27E earnings proxy (x) | B17: x | C17: 15 | D17: 19.5 | E17: 24 | F17: =CHOOSE(Inputs!$B$4,C17,D17,E17) | G17: same 0.75x haircut on the 5 Sep 20/26/32x
A18: RSU tax withholding, % of SBC | C18: 0.35 | D18: 0.35 | E18: 0.35 | F18: =CHOOSE(Inputs!$B$4,C18,D18,E18) | G18: FY2025 withholding $561M on SBC $1,581M = 35.5%
A19: Share price growth used for buyback/issuance math | C19: 0.05 | D19: 0.05 | E19: 0.05 | F19: =CHOOSE(Inputs!$B$4,C19,D19,E19) | G19: 5 Sep convention: buybacks and RSU issuance at a price rising 5% a year
A20: Incremental EBITDA margin on new-business revenue | C20: 0.7 | D20: 0.7 | E20: 0.7 | F20: =CHOOSE(Inputs!$B$4,C20,D20,E20) | G20: incremental margin on sponsored listings and Services; ads near 100%, Services lower
A21: Adj. EBITDA margin cap | C21: 0.38 | D21: 0.38 | E21: 0.38 | F21: =CHOOSE(Inputs!$B$4,C21,D21,E21) | G21: WS07: the realistic adj. EBITDA ceiling is 38%, against BKNG's five-year EBITDA-proxy range of 30.0-37.4%. Binds only in the bull case
A22: DCF fade period (years) | B22: yrs | C22: 10 | D22: 10 | E22: 10 | F22: =CHOOSE(Inputs!$B$4,C22,D22,E22) | G22: 5 Sep reverse-DCF convention: 10-year fade to terminal. LAYOUT-FIXED: the DCF grid on Valuation section 3 is ten written-out rows, so changing this cell does not resize the grid and has no effect on any output
A24: B. ANNUAL DRIVERS BY FISCAL YEAR
A25: FY2026E driver | B25: Unit | C25: Bear | D25: Base | E25: Bull | F25: Active | G25: Source
A26: Take rate change vs prior year (bps) | B26: bps | C26: -5 | D26: 0 | E26: 5 | F26: =CHOOSE(Inputs!$B$4,C26,D26,E26) | G26: WS07 lever; management guided FY26 take rate flat (2Q26 call)
A27: Cost of revenue per $ GBV, y/y change | B27: y/y | C27: 0.005 | D27: 0 | E27: -0.005 | F27: =CHOOSE(Inputs!$B$4,C27,D27,E27) | G27: WS07 lever; 2Q26 10-Q merchant fees and chargebacks
A28: Operations & support cash per night, y/y change | B28: y/y | C28: -0.04 | D28: -0.05 | E28: -0.06 | F28: =CHOOSE(Inputs!$B$4,C28,D28,E28) | G28: WS07 lever; 1H26 -3.8%, support cost per booking -16%
A29: Product development cash (ex-SBC), y/y growth | B29: y/y | C29: 0.115 | D29: 0.11 | E29: 0.105 | F29: =CHOOSE(Inputs!$B$4,C29,D29,E29) | G29: WS07 lever; 1H26 +11%
A30: Brand & performance marketing, y/y growth | B30: y/y | C30: 0.28 | D30: 0.25 | E30: 0.23 | F30: =CHOOSE(Inputs!$B$4,C30,D30,E30) | G30: WS07 lever; 1H26 brand+performance +32%
A31: Field operations & policy cash (new-business investment), y/y growth | B31: y/y | C31: 0.2 | D31: 0.18 | E31: 0.16 | F31: =CHOOSE(Inputs!$B$4,C31,D31,E31) | G31: WS07 lever; field ops +24% in 1H26
A32: G&A cash, y/y growth | B32: y/y | C32: 0.03 | D32: 0.02 | E32: 0 | F32: =CHOOSE(Inputs!$B$4,C32,D32,E32) | G32: WS07 lever; 1H26 +1%
A33: D&A + other add-backs, % of revenue | B33: % rev | C33: 0.009 | D33: 0.009 | E33: 0.009 | F33: =CHOOSE(Inputs!$B$4,C33,D33,E33) | G33: WS07 lever
A34: SBC, y/y growth | B34: y/y | C34: 0.16 | D34: 0.13 | E34: 0.1 | F34: =CHOOSE(Inputs!$B$4,C34,D34,E34) | G34: WS07 lever; 1H26 +14.7%, guided below FY25
A35: Interest income ($M) | B35: $M | C35: 620 | D35: 660 | E35: 700 | F35: =CHOOSE(Inputs!$B$4,C35,D35,E35) | G35: WS07 lever; $12.1bn cash + ST investments
A36: Interest expense ($M) | B36: $M | C36: 125 | D36: 120 | E36: 115 | F36: =CHOOSE(Inputs!$B$4,C36,D36,E36) | G36: WS07 lever; $2.5bn notes at 4.40-5.25%
A37: Cash taxes, % of revenue | B37: % rev | C37: 0.035 | D37: 0.026 | E37: 0.02 | F37: =CHOOSE(Inputs!$B$4,C37,D37,E37) | G37: WS07 lever; FY25 cash taxes 1.9% of revenue
... A46: D&A, % of revenue | B46: % rev | C46: 0.007 | D46: 0.007 | E46: 0.007 | F46: =CHOOSE(Inputs!$B$4,C46,D46,E46) | G46: WS07; D&A 0.6-0.8% of revenue since 2023
A48: FY2027E driver | B48: Unit | C48: Bear | D48: Base | E48: Bull | F48: Active | G48: Source
A49: Take rate change vs prior year (bps) | B49: bps | C49: -15 | D49: 0 | E49: 15 | F49: =CHOOSE(Inputs!$B$4,C49,D49,E49) | G49: WS07 lever; single fee vs the 6-10% direct-link pilot (WS11)
A50: Cost of revenue per $ GBV, y/y change | B50: y/y | C50: 0.015 | D50: 0 | E50: -0.01 | F50: =CHOOSE(Inputs!$B$4,C50,D50,E50) | G50: WS07 lever
A51: Operations & support cash per night, y/y change | B51: y/y | C51: -0.02 | D51: -0.05 | E51: -0.07 | F51: =CHOOSE(Inputs!$B$4,C51,D51,E51) | G51: WS07 lever
A52: Product development cash (ex-SBC), y/y growth | B52: y/y | C52: 0.09 | D52: 0.1 | E52: 0.1 | F52: =CHOOSE(Inputs!$B$4,C52,D52,E52) | G52: WS07 lever
...

Sheet History
A1: History - quarterly KPIs and cost lines, 1Q21 to 2Q26
A2: Source: data/processed/overnight/02_kpi_panel_quarterly.csv (WS02), data/processed/abnb_capital_return_quarterly.csv. Actuals, not formulas.
A4: Quarter | B4: Nights & experiences booked (M) | C4: GBV ($M) | D4: ADR ($) | E4: Revenue ($M) | F4: Take rate (%) | G4: Adj. EBITDA ($M) | H4: Adj. EBITDA margin (%) | I4: SBC ($M) | J4: FCF ($M) | K4: Buybacks ($M) | L4: RSU tax withholding ($M) | M4: Diluted WA shares (M) | N4: Net income ($M) | O4: Cost of revenue, GAAP ($M) | P4: Ops & support, GAAP ($M) | Q4: Product development, GAAP ($M) | R4: Sales & marketing, GAAP ($M) | S4: G&A, GAAP ($M) | T4: Cost of revenue, cash ($M) | U4: Ops & support, cash ($M) | V4: Product development, cash ($M) | W4: Sales & marketing, cash ($M) | X4: G&A, cash ($M)
A5: 1Q21 | B5: 64.4 | C5: 10300 | D5: 159.82 | E5: 887 | F5: 8.61 | G5: -59 | H5: -6.7 | I5: 229.5 | J5: 598.7 | L5: 130.4 | M5: 601 | N5: -1172.2 | O5: 254.5 | P5: 185.4 | Q5: 363.1 | R5: 229.1 | S5: 189.8 | T5: 254.5 | U5: 174 | V5: 219.4 | W5: 203.2 | X5: 141.3
A6: 2Q21 | B6: 83.1 | C6: 13400 | D6: 161.45 | E6: 1335 | F6: 9.96 | G6: 217 | H6: 16.3 | I6: 232.9 | J6: 782 | L6: 8.5 | M6: 611.7 | N6: -68.2 | O6: 294.4 | P6: 208.1 | Q6: 349.7 | R6: 315.3 | S6: 218.3 | T6: 294.4 | U6: 193.9 | V6: 205.9 | W6: 291.2 | X6: 167.6
A7: 3Q21 | B7: 79.7 | C7: 11900 | D7: 149.15 | E7: 2237 | F7: 18.8 | G7: 1101 | H7: 49.2 | I7: 210.8 | J7: 529.2 | L7: 15.7 | M7: 681.9 | N7: 833.9 | O7: 311.6 | P7: 228.3 | Q7: 344.4 | R7: 290.9 | S7: 210.7 | T7: 311.6 | U7: 217.1 | V7: 213.1 | W7: 267.2 | X7: 166
A8: 4Q21 | B8: 73.4 | C8: 11300 | D8: 153.61 | E8: 1532 | F8: 13.56 | G8: 333 | H8: 21.7 | I8: 225.9 | J8: 378.1 | K8: 0 | L8: 22.4 | M8: 569.4 | N8: 54.5 | O8: 295.5 | P8: 225.1 | Q8: 367.8 | R8: 350.7 | S8: 217.2 | T8: 295.5 | U8: 213.4 | V8: 241.5 | W8: 324.4 | X8: 155.8
A9: 1Q22 | B9: 102.1 | C9: 17200 | D9: 168.07 | E9: 1509 | F9: 8.77 | G9: 229 | H9: 15.2 | I9: 195 | J9: 1196 | K9: 0 | L9: 205 | M9: 635 | N9: -19 | O9: 363 | P9: 232.7 | Q9: 363 | R9: 345 | S9: 210 | T9: 363 | U9: 221 | V9: 245.1 | W9: 323.8 | X9: 165.9
A10: 2Q22 | B10: 103.7 | C10: 17000 | D10: 163.74 | E10: 2104 | F10: 12.38 | G10: 711 | H10: 33.8 | I10: 247 | J10: 796 | K10: 0 | L10: 140 | M10: 684 | N10: 379 | O10: 390 | P10: 258 | Q10: 375 | R10: 379 | S10: 244 | T10: 390 | U10: 241.1 | V10: 230.1 | W10: 349.9 | X10: 187.8
A11: 3Q22 | B11: 99.7 | C11: 15600 | D11: 156.44 | E11: 2884 | F11: 18.49 | G11: 1457 | H11: 50.5 | I11: 234 | J11: 958 | K11: 1000 | L11: 146 | M11: 680 | N11: 1214 | O11: 401 | P11: 290 | Q11: 366 | R11: 384 | S11: 240 | T11: 401 | U11: 272.1 | V11: 230.1 | W11: 356.6 | X11: 186.9
A12: 4Q22 | B12: 88.2 | C12: 13500 | D12: 152.81 | E12: 1902 | F12: 14.09 | G12: 506 | H12: 26.6 | I12: 254 | J12: 455 | K12: 500 | L12: 116 | M12: 721 | N12: 319.1 | O12: 345 | P12: 260 | Q12: 398 | R12: 408 | S12: 256 | T12: 345 | U12: 243 | V12: 249 | W12: 372 | X12: 204
A13: 1Q23 | B13: 121.1 | C13: 20400 | D13: 168.43 | E13: 1818 | F13: 8.91 | G13: 262 | H13: 14.4 | I13: 240 | J13: 1581 | K13: 493 | L13: 151 | M13: 670 | N13: 117 | O13: 428 | P13: 282 | Q13: 420 | R13: 450 | S13: 243 | T13: 428 | U13: 267 | V13: 271 | W13: 422 | X13: 195
A14: 2Q23 | B14: 115.1 | C14: 19100 | D14: 166.01 | E14: 2484 | F14: 13.01 | G14: 819 | H14: 33 | I14: 304 | J14: 900 | K14: 507 | L14: 721 | M14: 665 | N14: 650 | O14: 432 | P14: 317 | Q14: 451 | R14: 486 | S14: 275 | T14: 432 | U14: 298 | V14: 260 | W14: 450 | X14: 217
A15: 3Q23 | B15: 113.2 | C15: 18300 | D15: 161.38 | E15: 3397 | F15: 18.56 | G15: 1834 | H15: 54 | I15: 286 | J15: 1310 | K15: 500 | L15: 151 | M15: 660 | N15: 4374 | O15: 459 | P15: 316 | Q15: 419 | R15: 403 | S15: 304 | T15: 459 | U15: 299 | V15: 244 | W15: 370 | X15: 243
A16: 4Q23 | B16: 98.8 | C16: 15500 | D16: 156.73 | E16: 2218 | F16: 14.31 | G16: 738 | H16: 33.3 | I16: 270 | J16: 46 | K16: 752 | L16: 201 | M16: 653 | N16: -349.2 | O16: 384 | P16: 271 | Q16: 432 | R16: 424 | S16: 1203 | T16: 384 | U16: 254 | V16: 253 | W16: 391 | X16: 1142
A17: 1Q24 | B17: 132.6 | C17: 22900 | D17: 172.88 | E17: 2142 | F17: 9.35 | G17: 424 | H17: 19.8 | I17: 295 | J17: 1909 | K17: 750 | L17: 155 | M17: 654 | N17: 264 | O17: 480 | P17: 285 | Q17: 475 | R17: 514 | S17: 287 | T17: 480 | U17: 266 | V17: 290 | W17: 479 | X17: 231
A18: 2Q24 | B18: 125.1 | C18: 21200 | D18: 169.53 | E18: 2748 | F18: 12.96 | G18: 894 | H18: 32.5 | I18: 382 | J18: 1043 | K18: 749 | L18: 154 | M18: 649 | N18: 555 | O18: 506 | P18: 338 | Q18: 519 | R18: 573 | S18: 315 | T18: 506 | U18: 314 | V18: 280 | W18: 527 | X18: 242
A19: 3Q24 | B19: 122.8 | C19: 20100 | D19: 163.64 | E19: 3732 | F19: 18.57 | G19: 1958 | H19: 52.5 | I19: 362 | J19: 1074 | K19: 1093 | L19: 113 | M19: 642 | N19: 1368 | O19: 465 | P19: 369 | Q19: 524 | R19: 514 | S19: 335 | T19: 465 | U19: 347 | V19: 294 | W19: 471 | X19: 268
... A26: 2Q26 | B26: 148.3 | C26: 27200 | D26: 183.73 | E26: 3608 | F26: 13.26 | G26: 1261 | H26: 35 | I26: 487 | J26: 1253 | K26: 1051 | L26: 165 | M26: 597 | N26: 816 | O26: 633 | P26: 361 | Q26: 672 | R26: 875 | S26: 309 | T26: 633 | U26: 323 | V26: 374 | W26: 808 | X26: 225
A28: MODEL ANCHORS - the actuals the forecast grows off (formulas over the table above)
A29: Item | B29: Value | C29: Source / formula
A30: FY2025 nights (M) | B30: =B21+B22+B23+B24
A31: FY2025 GBV ($M) | B31: =C21+C22+C23+C24
A32: FY2025 revenue ($M) | B32: =E21+E22+E23+E24
A33: FY2025 ADR ($) | B33: =History!$B$31/History!$B$30
A34: FY2025 take rate | B34: =History!$B$32/History!$B$31
A35: FY2025 adj. EBITDA ($M) | B35: =G21+G22+G23+G24
A36: FY2025 SBC ($M) | B36: =I21+I22+I23+I24
A37: FY2025 cost of revenue, cash ($M) | B37: 2086 | C37: WS07 actuals()
A38: FY2025 ops & support, cash ($M) | B38: 1237 | C38: WS07 actuals()
A39: FY2025 product development, cash ($M) | B39: 1337 | C39: WS07 actuals()
A40: FY2025 brand & performance marketing ($M) | B40: 1595 | C40: WS07 07_cost_lines_per_night.csv
A41: FY2025 field operations & policy, cash ($M) | B41: 781 | C41: S&M cash less brand & performance
A42: FY2025 G&A, cash ($M) | B42: 1069 | C42: WS07 actuals()
A43: FY2025 new-business revenue outside GBV x take ($M) | B43: 12 | C43: WS11: Services $12M; sponsored listings did not exist
A44: 1H2026 nights (M) | B44: =B25+B26 | C44: actual
A45: 1H2026 GBV ($M) | B45: =C25+C26 | C45: actual
A46: 1H2026 revenue ($M) | B46: =E25+E26 | C46: actual
A47: 1H2026 FCF ($M) | B47: =J25+J26 | C47: actual
A48: 1H2026 buybacks ($M) | B48: =K25+K26 | C48: actual
...

Sheet Revenue
A1: Revenue build - quarterly 3Q26 to 4Q27 and annual FY2026E to FY2028E
A2: nights by region x ADR (ex-FX x FX) = GBV; revenue = GBV x take rate x the FX timing wedge, plus new business outside GBV. FY2026 = 1H26 actual + 3Q26 + 4Q26.
A4: BEAR CASE
A5: Line | B5: Unit | C5: 3Q26 | D5: 4Q26 | E5: 1Q27 | F5: 2Q27 | G5: 3Q27 | H5: 4Q27 | I5: FY2026E | J5: FY2027E | K5: FY2028E
A6: Prior-year nights, North America | B6: M | C6: =History!$B$51*History!$B$56 | D6: =History!$B$60*History!$B$65 | E6: =History!$B$69*History!$B$74 | F6: =History!$B$78*History!$B$83 | G6: =C18 | H6: =D18
A7: Prior-year nights, EMEA | B7: M | C7: =History!$B$51*History!$B$57 | D7: =History!$B$60*History!$B$66 | E7: =History!$B$69*History!$B$75 | F7: =History!$B$78*History!$B$84 | G7: =C19 | H7: =D19
A8: Prior-year nights, Latin America | B8: M | C8: =History!$B$51*History!$B$58 | D8: =History!$B$60*History!$B$67 | E8: =History!$B$69*History!$B$76 | F8: =History!$B$78*History!$B$85 | G8: =C20 | H8: =D20
A9: Prior-year nights, Asia Pacific | B9: M | C9: =History!$B$51*History!$B$59 | D9: =History!$B$60*History!$B$68 | E9: =History!$B$69*History!$B$77 | F9: =History!$B$78*History!$B$86 | G9: =C21 | H9: =D21
A10: Nights growth, North America | B10: y/y | C10: =Inputs!$C$100/100 | D10: =Inputs!$C$108/100 | E10: =Inputs!$C$116/100 | F10: =Inputs!$C$124/100 | G10: =Inputs!$C$132/100 | H10: =Inputs!$C$140/100
A11: Nights growth, EMEA | B11: y/y | C11: =Inputs!$C$101/100 | D11: =Inputs!$C$109/100 | E11: =Inputs!$C$117/100 | F11: =Inputs!$C$125/100 | G11: =Inputs!$C$133/100 | H11: =Inputs!$C$141/100
A12: Nights growth, Latin America | B12: y/y | C12: =Inputs!$C$102/100 | D12: =Inputs!$C$110/100 | E12: =Inputs!$C$118/100 | F12: =Inputs!$C$126/100 | G12: =Inputs!$C$134/100 | H12: =Inputs!$C$142/100
A13: Nights growth, Asia Pacific | B13: y/y | C13: =Inputs!$C$103/100 | D13: =Inputs!$C$111/100 | E13: =Inputs!$C$119/100 | F13: =Inputs!$C$127/100 | G13: =Inputs!$C$135/100 | H13: =Inputs!$C$143/100
A14: Regulatory drag, North America | B14: pp | C14: =Inputs!$C$43*Inputs!$C$151/100 | D14: =Inputs!$C$43*Inputs!$C$151/100 | E14: =Inputs!$C$66*Inputs!$C$155/100 | F14: =Inputs!$C$66*Inputs!$C$155/100 | G14: =Inputs!$C$66*Inputs!$C$155/100 | H14: =Inputs!$C$66*Inputs!$C$155/100 | K14: =Inputs!$C$89*Inputs!$C$159/100
A15: Regulatory drag, EMEA | B15: pp | C15: =Inputs!$C$43*Inputs!$C$152/100 | D15: =Inputs!$C$43*Inputs!$C$152/100 | E15: =Inputs!$C$66*Inputs!$C$156/100 | F15: =Inputs!$C$66*Inputs!$C$156/100 | G15: =Inputs!$C$66*Inputs!$C$156/100 | H15: =Inputs!$C$66*Inputs!$C$156/100 | K15: =Inputs!$C$89*Inputs!$C$160/100
A16: Regulatory drag, Latin America | B16: pp | C16: =Inputs!$C$43*Inputs!$C$153/100 | D16: =Inputs!$C$43*Inputs!$C$153/100 | E16: =Inputs!$C$66*Inputs!$C$157/100 | F16: =Inputs!$C$66*Inputs!$C$157/100 | G16: =Inputs!$C$66*Inputs!$C$157/100 | H16: =Inputs!$C$66*Inputs!$C$157/100 | K16: =Inputs!$C$89*Inputs!$C$161/100
A17: Regulatory drag, Asia Pacific | B17: pp | C17: =Inputs!$C$43*Inputs!$C$154/100 | D17: =Inputs!$C$43*Inputs!$C$154/100 | E17: =Inputs!$C$66*Inputs!$C$158/100 | F17: =Inputs!$C$66*Inputs!$C$158/100 | G17: =Inputs!$C$66*Inputs!$C$158/100 | H17: =Inputs!$C$66*Inputs!$C$158/100 | K17: =Inputs!$C$89*Inputs!$C$162/100
A18: Nights, North America | B18: M | C18: =C6*(1+C10-C14) | D18: =D6*(1+D10-D14) | E18: =E6*(1+E10-E14) | F18: =F6*(1+F10-F14) | G18: =G6*(1+G10-G14) | H18: =H6*(1+H10-H14) | I18: =D18/D22*I22 | J18: =SUM(E18:H18) | K18: =J18/J22*K22
A19: Nights, EMEA | B19: M | C19: =C7*(1+C11-C15) | D19: =D7*(1+D11-D15) | E19: =E7*(1+E11-E15) | F19: =F7*(1+F11-F15) | G19: =G7*(1+G11-G15) | H19: =H7*(1+H11-H15) | I19: =D19/D22*I22 | J19: =SUM(E19:H19) | K19: =J19/J22*K22
A20: Nights, Latin America | B20: M | C20: =C8*(1+C12-C16) | D20: =D8*(1+D12-D16) | E20: =E8*(1+E12-E16) | F20: =F8*(1+F12-F16) | G20: =G8*(1+G12-G16) | H20: =H8*(1+H12-H16) | I20: =D20/D22*I22 | J20: =SUM(E20:H20) | K20: =J20/J22*K22
A21: Nights, Asia Pacific | B21: M | C21: =C9*(1+C13-C17) | D21: =D9*(1+D13-D17) | E21: =E9*(1+E13-E17) | F21: =F9*(1+F13-F17) | G21: =G9*(1+G13-G17) | H21: =H9*(1+H13-H17) | I21: =D21/D22*I22 | J21: =SUM(E21:H21) | K21: =J21/J22*K22
A22: Nights & experiences booked | B22: M | C22: =C18+C19+C20+C21 | D22: =D18+D19+D20+D21 | E22: =E18+E19+E20+E21 | F22: =F18+F19+F20+F21 | G22: =G18+G19+G20+G21 | H22: =H18+H19+H20+H21 | I22: =History!$B$44+C22+D22 | J22: =SUM(E22:H22) | K22: =J22*(1+Inputs!$C$93-J18/J22*K14-J19/J22*K15-J20/J22*K16-J21/J22*K17)
A23: Nights growth | B23: y/y | C23: =C22/History!$B$51-1 | D23: =D22/History!$B$60-1 | E23: =E22/History!$B$69-1 | F23: =F22/History!$B$78-1 | G23: =G22/C22-1 | H23: =H22/D22-1 | I23: =I22/History!$B$30-1 | J23: =J22/I22-1 | K23: =K22/J22-1
A24: ADR ex-FX growth | B24: y/y | C24: =Inputs!$C$104/100 | D24: =Inputs!$C$112/100 | E24: =Inputs!$C$120/100 | F24: =Inputs!$C$128/100 | G24: =Inputs!$C$136/100 | H24: =Inputs!$C$144/100 | K24: =Inputs!$C$94
A25: FX effect on ADR | B25: pp | C25: =Inputs!$C$106/100 | D25: =Inputs!$C$114/100 | E25: =Inputs!$C$122/100 | F25: =Inputs!$C$130/100 | G25: =Inputs!$C$138/100 | H25: =Inputs!$C$146/100 | K25: =Inputs!$C$96
A26: ADR | B26: $ | C26: =History!$B$53*(1+C24)*(1+C25) | D26: =History!$B$62*(1+D24)*(1+D25) | E26: =History!$B$71*(1+E24)*(1+E25) | F26: =History!$B$80*(1+F24)*(1+F25) | G26: =C26*(1+G24)*(1+G25) | H26: =D26*(1+H24)*(1+H25) | I26: =I28/I22 | J26: =J28/J22 | K26: =K28/K22
A27: ADR growth (reported) | B27: y/y | C27: =C26/History!$B$53-1 | D27: =D26/History!$B$62-1 | E27: =E26/History!$B$71-1 | F27: =F26/History!$B$80-1 | G27: =G26/C26-1 | H27: =H26/D26-1 | I27: =I26/History!$B$33-1 | J27: =J26/I26-1 | K27: =K26/J26-1
A28: Gross booking value | B28: $M | C28: =C22*C26 | D28: =D22*D26 | E28: =E22*E26 | F28: =F22*F26 | G28: =G22*G26 | H28: =H22*H26 | I28: =History!$B$45+C28+D28 | J28: =SUM(E28:H28) | K28: =K22*J26*(1+K24)*(1+K25)
A29: GBV growth | B29: y/y | C29: =C28/History!$B$52-1 | D29: =D28/History!$B$61-1 | E29: =E28/History!$B$70-1 | F29: =F28/History!$B$79-1 | G29: =G28/C28-1 | H29: =H28/D28-1 | I29: =I28/History!$B$31-1 | J29: =J28/I28-1 | K29: =K28/J28-1
A30: Take rate, assumed (prior-year quarter + bps) | B30: % | C30: =History!$B$55+Inputs!$C$26/10000 | D30: =History!$B$64+Inputs!$C$26/10000 | E30: =History!$B$73+Inputs!$C$49/10000 | F30: =History!$B$82+Inputs!$C$49/10000 | G30: =C30+Inputs!$C$49/10000 | H30: =D30+Inputs!$C$49/10000 | I30: =(History!$B$46+C28*C30+D28*D30)/I28 | J30: =(E28*E30+F28*F30+G28*G30+H28*H30)/J28 | K30: =J30+Inputs!$C$72/10000
A31: FX effect on revenue (lagged) | B31: pp | C31: =Inputs!$C$105/100 | D31: =Inputs!$C$113/100 | E31: =Inputs!$C$121/100 | F31: =Inputs!$C$129/100 | G31: =Inputs!$C$137/100 | H31: =Inputs!$C$145/100 | K31: =Inputs!$C$95
A32: FX timing wedge (revenue FX less ADR FX) | B32: pp | C32: =(1+C31)/(1+C25)-1 | D32: =(1+D31)/(1+D25)-1 | E32: =(1+E31)/(1+E25)-1 | F32: =(1+F31)/(1+F25)-1 | G32: =(1+G31)/(1+G25)-1 | H32: =(1+H31)/(1+H25)-1 | K32: =(1+K31)/(1+K25)-1
A33: Core revenue (GBV x take x wedge) | B33: $M | C33: =C28*C30*(1+C32) | D33: =D28*D30*(1+D32) | E33: =E28*E30*(1+E32) | F33: =F28*F30*(1+F32) | G33: =G28*G30*(1+G32) | H33: =H28*H30*(1+H32) | I33: =History!$B$46+C33+D33 | J33: =SUM(E33:H33) | K33: =K28*K30*(1+K32)
A34: Implied reported take rate (core revenue / GBV) | B34: % | C34: =C33/C28 | D34: =D33/D28 | E34: =E33/E28 | F34: =F33/F28 | G34: =G33/G28 | H34: =H33/H28 | I34: =I33/I28 | J34: =J33/J28 | K34: =K33/K28
A35: New business outside GBV x take, incremental | B35: $M | C35: =I35*C33/(C33+D33) | D35: =I35*D33/(C33+D33) | E35: =J35*E33/SUM(E33:H33) | F35: =J35*F33/SUM(E33:H33) | G35: =J35*G33/SUM(E33:H33) | H35: =J35*H33/SUM(E33:H33) | I35: =Inputs!$C$41-History!$B$43*I33/History!$B$32 | J35: =Inputs!$C$64-History!$B$43*J33/History!$B$32 | K35: =Inputs!$C$87-History!$B$43*K33/History!$B$32
A36: REVENUE | B36: $M | C36: =C33+C35 | D36: =D33+D35 | E36: =E33+E35 | F36: =F33+F35 | G36: =G33+G35 | H36: =H33+H35 | I36: =I33+I35 | J36: =J33+J35 | K36: =K33+K35
A37: Revenue growth | B37: y/y | C37: =C36/History!$B$54-1 | D37: =D36/History!$B$63-1 | E37: =E36/History!$B$72-1 | F37: =F36/History!$B$81-1 | G37: =G36/C36-1 | H37: =H36/D36-1 | I37: =I36/History!$B$32-1 | J37: =J36/I36-1 | K37: =K36/J36-1
A38: Seasonal margin spread vs FY2026 (2027 quarters) | B38: pts | E38: =History!$B$99-Costs!$D$22 | F38: =History!$B$100-Costs!$D$22 | G38: =Inputs!$C$107/100-Costs!$D$22 | H38: =Inputs!$C$115/100-Costs!$D$22
A39: Correction so the 2027 quarters reproduce the FY2027 margin | B39: pts | E39: =-(E38*E36+F38*F36+G38*G36+H38*H36)/SUM(E36:H36) | F39: =-(E38*E36+F38*F36+G38*G36+H38*H36)/SUM(E36:H36) | G39: =-(E38*E36+F38*F36+G38*G36+H38*H36)/SUM(E36:H36) | H39: =-(E38*E36+F38*F36+G38*G36+H38*H36)/SUM(E36:H36)
A40: Adj. EBITDA margin | B40: % | C40: =Inputs!$C$107/100 | D40: =Inputs!$C$115/100 | E40: =Costs!$E$22+E38+E39 | F40: =Costs!$E$22+F38+F39 | G40: =Costs!$E$22+G38+G39 | H40: =Costs!$E$22+H38+H39 | I40: =Costs!$D$22 | J40: =Costs!$E$22 | K40: =Costs!$F$22
A41: Adj. EBITDA | B41: $M | C41: =C36*C40 | D41: =D36*D40 | E41: =E36*E40 | F41: =F36*F40 | G41: =G36*G40 | H41: =H36*H40 | I41: =Costs!$D$21 | J41: =Costs!$E$21 | K41: =Costs!$F$21
...

Sheet Costs
A1: Cost stack, adj. EBITDA and net income - lever by lever
A2: Mechanics from WS07 07_margin_lever_model.py: cost of revenue on GBV dollars, operations & support on nights, the rest on cash growth rates.
A4: BEAR CASE
A5: Line | B5: Unit | C5: FY2025A | D5: FY2026E | E5: FY2027E | F5: FY2028E
A6: Revenue | B6: $M | C6: =History!$B$32 | D6: =Revenue!$I$36 | E6: =Revenue!$J$36 | F6: =Revenue!$K$36
A7: GBV | B7: $M | C7: =History!$B$31 | D7: =Revenue!$I$28 | E7: =Revenue!$J$28 | F7: =Revenue!$K$28
A8: Nights | B8: M | C8: =History!$B$30 | D8: =Revenue!$I$22 | E8: =Revenue!$J$22 | F8: =Revenue!$K$22
A9: Cost of revenue, cash | B9: $M | C9: =History!$B$37 | D9: =C9/C7*(1+Inputs!$C$27)*D7 | E9: =D9/D7*(1+Inputs!$C$50)*E7 | F9: =E9/E7*(1+Inputs!$C$73)*F7
A10: Operations & support, cash | B10: $M | C10: =History!$B$38 | D10: =C10/C8*(1+Inputs!$C$28)*D8 | E10: =D10/D8*(1+Inputs!$C$51)*E8 | F10: =E10/E8*(1+Inputs!$C$74)*F8
A11: Product development, cash (ex-SBC) | B11: $M | C11: =History!$B$39 | D11: =C11*(1+Inputs!$C$29) | E11: =D11*(1+Inputs!$C$52) | F11: =E11*(1+Inputs!$C$75)
A12: Brand & performance marketing | B12: $M | C12: =History!$B$40 | D12: =C12*(1+Inputs!$C$30) | E12: =D12*(1+Inputs!$C$53) | F12: =E12*(1+Inputs!$C$76)
A13: Field operations & policy, cash | B13: $M | C13: =History!$B$41 | D13: =C13*(1+Inputs!$C$31) | E13: =D13*(1+Inputs!$C$54) | F13: =E13*(1+Inputs!$C$77)
A14: G&A, cash | B14: $M | C14: =History!$B$42 | D14: =C14*(1+Inputs!$C$32) | E14: =D14*(1+Inputs!$C$55) | F14: =E14*(1+Inputs!$C$78)
A15: New-business cost of the incremental revenue | B15: $M | C15: =0 | D15: =Revenue!$I$35*(1-Inputs!$C$20) | E15: =Revenue!$J$35*(1-Inputs!$C$20) | F15: =Revenue!$K$35*(1-Inputs!$C$20)
A16: AI referral cost | B16: $M | C16: =0 | D16: =D6*Inputs!$C$40 | E16: =E6*Inputs!$C$63 | F16: =F6*Inputs!$C$86
A17: Total cash costs | B17: $M | C17: =C9+C10+C11+C12+C13+C14+C15+C16 | D17: =D9+D10+D11+D12+D13+D14+D15+D16 | E17: =E9+E10+E11+E12+E13+E14+E15+E16 | F17: =F9+F10+F11+F12+F13+F14+F15+F16
A18: D&A and other add-backs | B18: $M | C18: =History!$B$109 | D18: =D6*Inputs!$C$33 | E18: =E6*Inputs!$C$56 | F18: =F6*Inputs!$C$79
A19: Adj. EBITDA before the WS07 38% ceiling | B19: $M | C19: =History!$B$35 | D19: =D6-D17+D18 | E19: =E6-E17+E18 | F19: =F6-F17+F18
A20: Margin before the ceiling | B20: % | C20: =C19/C6 | D20: =D19/D6 | E20: =E19/E6 | F20: =F19/F6
A21: ADJUSTED EBITDA (capped at the WS07 ceiling) | B21: $M | C21: =History!$B$35 | D21: =MIN(D19,D6*Inputs!$C$21) | E21: =MIN(E19,E6*Inputs!$C$21) | F21: =MIN(F19,F6*Inputs!$C$21)
A22: Adj. EBITDA margin | B22: % | C22: =C21/C6 | D22: =D21/D6 | E22: =E21/E6 | F22: =F21/F6
A23: Stock-based compensation | B23: $M | C23: =History!$B$36 | D23: =C23*(1+Inputs!$C$34) | E23: =D23*(1+Inputs!$C$57) | F23: =E23*(1+Inputs!$C$80)
A24: SBC, % of revenue | B24: % | C24: =C23/C6 | D24: =D23/D6 | E24: =E23/E6 | F24: =F23/F6
A25: D&A | B25: $M | C25: =History!$B$108 | D25: =D6*Inputs!$C$46 | E25: =E6*Inputs!$C$69 | F25: =F6*Inputs!$C$92
A26: GAAP operating income | B26: $M | D26: =D21-D23-D18 | E26: =E21-E23-E18 | F26: =F21-F23-F18
A27: GAAP operating margin | B27: % | D27: =D26/D6 | E27: =E26/E6 | F27: =F26/F6
A28: Interest income | B28: $M | C28: =History!$B$110 | D28: =Inputs!$C$35 | E28: =Inputs!$C$58 | F28: =Inputs!$C$81
A29: Interest expense | B29: $M | C29: =History!$B$111 | D29: =Inputs!$C$36 | E29: =Inputs!$C$59 | F29: =Inputs!$C$82
A30: Pre-tax income | B30: $M | D30: =D26+D28-D29 | E30: =E26+E28-E29 | F30: =F26+F28-F29
A31: Effective tax rate | B31: % | D31: =Inputs!$C$39 | E31: =Inputs!$C$62 | F31: =Inputs!$C$85
A32: Net income | B32: $M | D32: =D30*(1-D31) | E32: =E30*(1-E31) | F32: =F30*(1-F31)
A34: BASE CASE
A35: Line | B35: Unit | C35: FY2025A | D35: FY2026E | E35: FY2027E | F35: FY2028E
A36: Revenue | B36: $M | C36: =History!$B$32 | D36: =Revenue!$I$77 | E36: =Revenue!$J$77 | F36: =Revenue!$K$77
A37: GBV | B37: $M | C37: =History!$B$31 | D37: =Revenue!$I$69 | E37: =Revenue!$J$69 | F37: =Revenue!$K$69
A38: Nights | B38: M | C38: =History!$B$30 | D38: =Revenue!$I$63 | E38: =Revenue!$J$63 | F38: =Revenue!$K$63
A39: Cost of revenue, cash | B39: $M | C39: =History!$B$37 | D39: =C39/C37*(1+Inputs!$D$27)*D37 | E39: =D39/D37*(1+Inputs!$D$50)*E37 | F39: =E39/E37*(1+Inputs!$D$73)*F37
A40: Operations & support, cash | B40: $M | C40: =History!$B$38 | D40: =C40/C38*(1+Inputs!$D$28)*D38 | E40: =D40/D38*(1+Inputs!$D$51)*E38 | F40: =E40/E38*(1+Inputs!$D$74)*F38
A41: Product development, cash (ex-SBC) | B41: $M | C41: =History!$B$39 | D41: =C41*(1+Inputs!$D$29) | E41: =D41*(1+Inputs!$D$52) | F41: =E41*(1+Inputs!$D$75)
A42: Brand & performance marketing | B42: $M | C42: =History!$B$40 | D42: =C42*(1+Inputs!$D$30) | E42: =D42*(1+Inputs!$D$53) | F42: =E42*(1+Inputs!$D$76)
...

Sheet Cash
A1: Free cash flow, buybacks and the share-count path
A2: FCF bridge from WS07. Share count: buybacks and RSU issuance at a price growing 5% a year, 35% of SBC withheld for tax. Both roll-forwards start from the same 2Q26 actual (net cash $9,593M, 597M diluted shares) and both consume the SAME flows: for FY2026 only the 2H26 buyback (FY26 less the 1H26 actual $2,139M) and only 2H26 SBC (FY26 less the 1H26 actual $897M); FY2027 and FY2028 take the full year. WS17 finding 3 (the FY2026 share roll applied the FULL-YEAR buyback and SBC to a 30 Jun 2026 count, double-counting the 1H26 repurchase and understating FY2026E shares by 8.55M) was fixed by WS18 here and in 13_driver_model.py. See research/notes/overnight/18_corrections-applied.md.
A4: BEAR CASE
A5: Line | B5: Unit | C5: FY2025A | D5: FY2026E | E5: FY2027E | F5: FY2028E
A6: Adjusted EBITDA | B6: $M | C6: =Costs!$C$21 | D6: =Costs!$D$21 | E6: =Costs!$E$21 | F6: =Costs!$F$21
A7: + Interest income | B7: $M | C7: =History!$B$110 | D7: =Costs!$D$28 | E7: =Costs!$E$28 | F7: =Costs!$F$28
A8: - Interest expense | B8: $M | C8: =-History!$B$111 | D8: =-Costs!$D$29 | E8: =-Costs!$E$29 | F8: =-Costs!$F$29
A9: + Other income / (expense) | B9: $M | C9: =History!$B$112 | D9: =0 | E9: =0 | F9: =0
A10: - Cash taxes | B10: $M | C10: =History!$B$113 | D10: =-Costs!$D$6*Inputs!$C$37 | E10: =-Costs!$E$6*Inputs!$C$60 | F10: =-Costs!$F$6*Inputs!$C$83
A11: + Change in unearned fees | B11: $M | C11: =History!$B$114 | D11: =Costs!$D$6*Inputs!$C$38 | E11: =Costs!$E$6*Inputs!$C$61 | F11: =Costs!$F$6*Inputs!$C$84
A12: + Working-capital residual | B12: $M | C12: =History!$B$115 | D12: =Costs!$D$6*Inputs!$C$45 | E12: =Costs!$E$6*Inputs!$C$68 | F12: =Costs!$F$6*Inputs!$C$91
A13: - Capex | B13: $M | C13: =History!$B$116 | D13: =-Costs!$D$6*Inputs!$C$44 | E13: =-Costs!$E$6*Inputs!$C$67 | F13: =-Costs!$F$6*Inputs!$C$90
A14: FREE CASH FLOW | B14: $M | C14: =C6+C7+C8+C9+C10+C11+C12+C13 | D14: =D6+D7+D8+D9+D10+D11+D12+D13 | E14: =E6+E7+E8+E9+E10+E11+E12+E13 | F14: =F6+F7+F8+F9+F10+F11+F12+F13
A15: FCF margin | B15: % | C15: =C14/History!$B$32 | D15: =D14/Costs!$D$6 | E15: =E14/Costs!$E$6 | F15: =F14/Costs!$F$6
A16: FCF / adj. EBITDA | B16: % | C16: =C14/C6 | D16: =D14/D6 | E16: =E14/E6 | F16: =F14/F6
A17: SBC | B17: $M | C17: =History!$B$36 | D17: =Costs!$D$23 | E17: =Costs!$E$23 | F17: =Costs!$F$23
A18: SBC-ADJUSTED FCF | B18: $M | C18: =C14-C17 | D18: =D14-D17 | E18: =E14-E17 | F18: =F14-F17
A19: SBC-adjusted FCF margin | B19: % | D19: =D18/Costs!$D$6 | E19: =E18/Costs!$E$6 | F19: =F18/Costs!$F$6
A20: Share price used for buybacks and issuance | B20: $ | C20: =Inputs!$C$8 | D20: =Inputs!$C$8*(1+Inputs!$C$19)^0 | E20: =Inputs!$C$8*(1+Inputs!$C$19)^1 | F20: =Inputs!$C$8*(1+Inputs!$C$19)^2
A21: Buybacks | B21: $M | C21: =History!$B$117 | D21: =Inputs!$C$42 | E21: =Inputs!$C$65 | F21: =Inputs!$C$88
A22: RSU tax withholding | B22: $M | C22: =History!$B$118 | D22: =D17*Inputs!$C$18 | E22: =E17*Inputs!$C$18 | F22: =F17*Inputs!$C$18
A23: Diluted shares, period end (FY2025A col = the 2Q26 actual) | B23: M | C23: =Inputs!$C$10 | D23: =C23-(D21-History!$B$48)/D20+(D17-History!$B$50)/D20*(1-Inputs!$C$18) | E23: =D23-E21/E20+E17/E20*(1-Inputs!$C$18) | F23: =E23-F21/F20+F17/F20*(1-Inputs!$C$18)
A24: FCF per share | B24: $ | D24: =D14/D23 | E24: =E14/E23 | F24: =F14/F23
A25: SBC-adjusted FCF per share | B25: $ | D25: =D18/D23 | E25: =E18/E23 | F25: =F18/F23
A26: Earnings proxy per share (net income / shares) | B26: $ | D26: =Costs!$D$32/D23 | E26: =Costs!$E$32/E23 | F26: =Costs!$F$32/F23
A27: Net cash ex float, period end (FY2025A col = the 30 Jun 2026 actual) | B27: $M | C27: =Inputs!$C$9 | D27: =C27+(D14-History!$B$47)-(D21-History!$B$48)-(D22-History!$B$49) | E27: =D27+E14-E21-E22 | F27: =E27+F14-F21-F22
A29: BASE CASE
A30: Line | B30: Unit | C30: FY2025A | D30: FY2026E | E30: FY2027E | F30: FY2028E
A31: Adjusted EBITDA | B31: $M | C31: =Costs!$C$51 | D31: =Costs!$D$51 | E31: =Costs!$E$51 | F31: =Costs!$F$51
A32: + Interest income | B32: $M | C32: =History!$B$110 | D32: =Costs!$D$58 | E32: =Costs!$E$58 | F32: =Costs!$F$58
A33: - Interest expense | B33: $M | C33: =-History!$B$111 | D33: =-Costs!$D$59 | E33: =-Costs!$E$59 | F33: =-Costs!$F$59
A34: + Other income / (expense) | B34: $M | C34: =History!$B$112 | D34: =0 | E34: =0 | F34: =0
A35: - Cash taxes | B35: $M | C35: =History!$B$113 | D35: =-Costs!$D$36*Inputs!$D$37 | E35: =-Costs!$E$36*Inputs!$D$60 | F35: =-Costs!$F$36*Inputs!$D$83
A36: + Change in unearned fees | B36: $M | C36: =History!$B$114 | D36: =Costs!$D$36*Inputs!$D$38 | E36: =Costs!$E$36*Inputs!$D$61 | F36: =Costs!$F$36*Inputs!$D$84
A37: + Working-capital residual | B37: $M | C37: =History!$B$115 | D37: =Costs!$D$36*Inputs!$D$45 | E37: =Costs!$E$36*Inputs!$D$68 | F37: =Costs!$F$36*Inputs!$D$91
A38: - Capex | B38: $M | C38: =History!$B$116 | D38: =-Costs!$D$36*Inputs!$D$44 | E38: =-Costs!$E$36*Inputs!$D$67 | F38: =-Costs!$F$36*Inputs!$D$90
A39: FREE CASH FLOW | B39: $M | C39: =C31+C32+C33+C34+C35+C36+C37+C38 | D39: =D31+D32+D33+D34+D35+D36+D37+D38 | E39: =E31+E32+E33+E34+E35+E36+E37+E38 | F39: =F31+F32+F33+F34+F35+F36+F37+F38
A40: FCF margin | B40: % | C40: =C39/History!$B$32 | D40: =D39/Costs!$D$36 | E40: =E39/Costs!$E$36 | F40: =F39/Costs!$F$36
A41: FCF / adj. EBITDA | B41: % | C41: =C39/C31 | D41: =D39/D31 | E41: =E39/E31 | F41: =F39/F31
A42: SBC | B42: $M | C42: =History!$B$36 | D42: =Costs!$D$53 | E42: =Costs!$E$53 | F42: =Costs!$F$53
...

Sheet Valuation
A1: Valuation - exit multiples, DCF, football field, reverse DCF
A2: Exit multiples from WS12; cost of equity from WS09/WS12. Every price is a live formula off Costs and Cash.
A4: 1. FY2027E BASIS
A5: Item | B5: Bear | C5: Base | D5: Bull | E5: Active (Inputs!B4)
A6: Adj. EBITDA, FY2027E ($M) | B6: =Costs!$E$21 | C6: =Costs!$E$51 | D6: =Costs!$E$81 | E6: =CHOOSE(Inputs!$B$4,B6,C6,D6)
A7: FCF, FY2027E ($M) | B7: =Cash!$E$14 | C7: =Cash!$E$39 | D7: =Cash!$E$64 | E7: =CHOOSE(Inputs!$B$4,B7,C7,D7)
A8: SBC-adjusted FCF, FY2027E ($M) | B8: =Cash!$E$18 | C8: =Cash!$E$43 | D8: =Cash!$E$68 | E8: =CHOOSE(Inputs!$B$4,B8,C8,D8)
A9: Earnings proxy per share, FY2027E ($) | B9: =Cash!$E$26 | C9: =Cash!$E$51 | D9: =Cash!$E$76 | E9: =CHOOSE(Inputs!$B$4,B9,C9,D9)
A10: Net cash ex float, FY2027E ($M) | B10: =Cash!$E$27 | C10: =Cash!$E$52 | D10: =Cash!$E$77 | E10: =CHOOSE(Inputs!$B$4,B10,C10,D10)
A11: Diluted shares, FY2027E (M) | B11: =Cash!$E$23 | C11: =Cash!$E$48 | D11: =Cash!$E$73 | E11: =CHOOSE(Inputs!$B$4,B11,C11,D11)
A12: Adj. EBITDA, FY2028E ($M) | B12: =Costs!$F$21 | C12: =Costs!$F$51 | D12: =Costs!$F$81 | E12: =CHOOSE(Inputs!$B$4,B12,C12,D12)
A13: Net cash ex float, FY2028E ($M) | B13: =Cash!$F$27 | C13: =Cash!$F$52 | D13: =Cash!$F$77 | E13: =CHOOSE(Inputs!$B$4,B13,C13,D13)
A14: Diluted shares, FY2028E (M) | B14: =Cash!$F$23 | C14: =Cash!$F$48 | D14: =Cash!$F$73 | E14: =CHOOSE(Inputs!$B$4,B14,C14,D14)
A15: FCF, FY2028E ($M) | B15: =Cash!$F$14 | C15: =Cash!$F$39 | D15: =Cash!$F$64 | E15: =CHOOSE(Inputs!$B$4,B15,C15,D15)
A17: 2. PRICE PER LENS
A18: Lens | B18: Bear | C18: Base | D18: Bull | E18: Active (Inputs!B4) | F18: Multiple source
A19: EV / adj. EBITDA, FY2027E | B19: =(Inputs!$C$14*B6+B10)/B11 | C19: =(Inputs!$D$14*C6+C10)/C11 | D19: =(Inputs!$E$14*D6+D10)/D11 | E19: =CHOOSE(Inputs!$B$4,B19,C19,D19) | F19: WS12 13.5 / 16.5 / 18.5x
A20: EV / FCF, FY2027E | B20: =(Inputs!$C$15*B7+B10)/B11 | C20: =(Inputs!$D$15*C7+C10)/C11 | D20: =(Inputs!$E$15*D7+D10)/D11 | E20: =CHOOSE(Inputs!$B$4,B20,C20,D20) | F20: 5 Sep 15/19/23x rescaled by WS12's 0.75x haircut
A21: P / SBC-adjusted FCF, FY2027E | B21: =Inputs!$C$16*B8/B11 | C21: =Inputs!$D$16*C8/C11 | D21: =Inputs!$E$16*D8/D11 | E21: =CHOOSE(Inputs!$B$4,B21,C21,D21) | F21: same 0.75x haircut on 20/26/32x
A22: P / earnings proxy, FY2027E | B22: =Inputs!$C$17*B9 | C22: =Inputs!$D$17*C9 | D22: =Inputs!$E$17*D9 | E22: =CHOOSE(Inputs!$B$4,B22,C22,D22) | F22: same
A23: EV / adj. EBITDA, FY2028E (discounted 1 yr at the cost of equity) | B23: =(Inputs!$C$14*B12+B13)/B14/(1+Inputs!$C$11) | C23: =(Inputs!$D$14*C12+C13)/C14/(1+Inputs!$D$11) | D23: =(Inputs!$E$14*D12+D13)/D14/(1+Inputs!$E$11) | E23: =CHOOSE(Inputs!$B$4,B23,C23,D23) | F23: WS12 multiples on the FY28 basis, discounted to the ~Sep-2027 target date
A24: Sensitivity (not in the football field): EV / adj. EBITDA, FY2028E, UNDISCOUNTED (value as of end-FY2028) | B24: =(Inputs!$C$14*B12+B13)/B14 | C24: =(Inputs!$D$14*C12+C13)/C14 | D24: =(Inputs!$E$14*D12+D13)/D14 | E24: =CHOOSE(Inputs!$B$4,B24,C24,D24) | F24: date-mixing sensitivity; see model/assumptions.md
A26: 3. DCF ON FY2027E FCF - 10-year fade to terminal growth, discounted at the cost of equity | H26: start growth = the 'DCF start growth' input, fading linearly to terminal growth
A27: Year | B27: Bear: FCF ($M) | C27: Base: FCF ($M) | D27: Bull: FCF ($M) | E27: Bear: PV ($M) | F27: Base: PV ($M) | G27: Bull: PV ($M)
A28: 1 | B28: =B7*(1+(Inputs!$C$13+(Inputs!$C$12-Inputs!$C$13)*($A28-1)/9)) | C28: =C7*(1+(Inputs!$D$13+(Inputs!$D$12-Inputs!$D$13)*($A28-1)/9)) | D28: =D7*(1+(Inputs!$E$13+(Inputs!$E$12-Inputs!$E$13)*($A28-1)/9)) | E28: =B28/(1+Inputs!$C$11)^$A28 | F28: =C28/(1+Inputs!$D$11)^$A28 | G28: =D28/(1+Inputs!$E$11)^$A28
A29: 2 | B29: =B28*(1+(Inputs!$C$13+(Inputs!$C$12-Inputs!$C$13)*($A29-1)/9)) | C29: =C28*(1+(Inputs!$D$13+(Inputs!$D$12-Inputs!$D$13)*($A29-1)/9)) | D29: =D28*(1+(Inputs!$E$13+(Inputs!$E$12-Inputs!$E$13)*($A29-1)/9)) | E29: =B29/(1+Inputs!$C$11)^$A29 | F29: =C29/(1+Inputs!$D$11)^$A29 | G29: =D29/(1+Inputs!$E$11)^$A29
A30: 3 | B30: =B29*(1+(Inputs!$C$13+(Inputs!$C$12-Inputs!$C$13)*($A30-1)/9)) | C30: =C29*(1+(Inputs!$D$13+(Inputs!$D$12-Inputs!$D$13)*($A30-1)/9)) | D30: =D29*(1+(Inputs!$E$13+(Inputs!$E$12-Inputs!$E$13)*($A30-1)/9)) | E30: =B30/(1+Inputs!$C$11)^$A30 | F30: =C30/(1+Inputs!$D$11)^$A30 | G30: =D30/(1+Inputs!$E$11)^$A30
A31: 4 | B31: =B30*(1+(Inputs!$C$13+(Inputs!$C$12-Inputs!$C$13)*($A31-1)/9)) | C31: =C30*(1+(Inputs!$D$13+(Inputs!$D$12-Inputs!$D$13)*($A31-1)/9)) | D31: =D30*(1+(Inputs!$E$13+(Inputs!$E$12-Inputs!$E$13)*($A31-1)/9)) | E31: =B31/(1+Inputs!$C$11)^$A31 | F31: =C31/(1+Inputs!$D$11)^$A31 | G31: =D31/(1+Inputs!$E$11)^$A31
A32: 5 | B32: =B31*(1+(Inputs!$C$13+(Inputs!$C$12-Inputs!$C$13)*($A32-1)/9)) | C32: =C31*(1+(Inputs!$D$13+(Inputs!$D$12-Inputs!$D$13)*($A32-1)/9)) | D32: =D31*(1+(Inputs!$E$13+(Inputs!$E$12-Inputs!$E$13)*($A32-1)/9)) | E32: =B32/(1+Inputs!$C$11)^$A32 | F32: =C32/(1+Inputs!$D$11)^$A32 | G32: =D32/(1+Inputs!$E$11)^$A32
A33: 6 | B33: =B32*(1+(Inputs!$C$13+(Inputs!$C$12-Inputs!$C$13)*($A33-1)/9)) | C33: =C32*(1+(Inputs!$D$13+(Inputs!$D$12-Inputs!$D$13)*($A33-1)/9)) | D33: =D32*(1+(Inputs!$E$13+(Inputs!$E$12-Inputs!$E$13)*($A33-1)/9)) | E33: =B33/(1+Inputs!$C$11)^$A33 | F33: =C33/(1+Inputs!$D$11)^$A33 | G33: =D33/(1+Inputs!$E$11)^$A33
A34: 7 | B34: =B33*(1+(Inputs!$C$13+(Inputs!$C$12-Inputs!$C$13)*($A34-1)/9)) | C34: =C33*(1+(Inputs!$D$13+(Inputs!$D$12-Inputs!$D$13)*($A34-1)/9)) | D34: =D33*(1+(Inputs!$E$13+(Inputs!$E$12-Inputs!$E$13)*($A34-1)/9)) | E34: =B34/(1+Inputs!$C$11)^$A34 | F34: =C34/(1+Inputs!$D$11)^$A34 | G34: =D34/(1+Inputs!$E$11)^$A34
A35: 8 | B35: =B34*(1+(Inputs!$C$13+(Inputs!$C$12-Inputs!$C$13)*($A35-1)/9)) | C35: =C34*(1+(Inputs!$D$13+(Inputs!$D$12-Inputs!$D$13)*($A35-1)/9)) | D35: =D34*(1+(Inputs!$E$13+(Inputs!$E$12-Inputs!$E$13)*($A35-1)/9)) | E35: =B35/(1+Inputs!$C$11)^$A35 | F35: =C35/(1+Inputs!$D$11)^$A35 | G35: =D35/(1+Inputs!$E$11)^$A35
A36: 9 | B36: =B35*(1+(Inputs!$C$13+(Inputs!$C$12-Inputs!$C$13)*($A36-1)/9)) | C36: =C35*(1+(Inputs!$D$13+(Inputs!$D$12-Inputs!$D$13)*($A36-1)/9)) | D36: =D35*(1+(Inputs!$E$13+(Inputs!$E$12-Inputs!$E$13)*($A36-1)/9)) | E36: =B36/(1+Inputs!$C$11)^$A36 | F36: =C36/(1+Inputs!$D$11)^$A36 | G36: =D36/(1+Inputs!$E$11)^$A36
A37: 10 | B37: =B36*(1+(Inputs!$C$13+(Inputs!$C$12-Inputs!$C$13)*($A37-1)/9)) | C37: =C36*(1+(Inputs!$D$13+(Inputs!$D$12-Inputs!$D$13)*($A37-1)/9)) | D37: =D36*(1+(Inputs!$E$13+(Inputs!$E$12-Inputs!$E$13)*($A37-1)/9)) | E37: =B37/(1+Inputs!$C$11)^$A37 | F37: =C37/(1+Inputs!$D$11)^$A37 | G37: =D37/(1+Inputs!$E$11)^$A37
A38: Terminal value (Gordon), discounted | E38: =B37*(1+Inputs!$C$12)/(Inputs!$C$11-Inputs!$C$12)/(1+Inputs!$C$11)^$A37 | F38: =C37*(1+Inputs!$D$12)/(Inputs!$D$11-Inputs!$D$12)/(1+Inputs!$D$11)^$A37 | G38: =D37*(1+Inputs!$E$12)/(Inputs!$E$11-Inputs!$E$12)/(1+Inputs!$E$11)^$A37
A39: Enterprise value ($M) | E39: =SUM(E28:E37)+E38 | F39: =SUM(F28:F37)+F38 | G39: =SUM(G28:G37)+G38
A40: DCF value per share ($) | B40: =(E39+B10)/B11 | C40: =(F39+C10)/C11 | D40: =(G39+D10)/D11 | E40: =CHOOSE(Inputs!$B$4,B40,C40,D40) | H40: column E on this row is the Active (Inputs!B4) selection, not a PV
A42: 4. FOOTBALL FIELD AND IMPLIED UPSIDE
A43: Measure | B43: Bear | C43: Base | D43: Bull | E43: Active (Inputs!B4)
A44: Football field: Low | B44: =MIN(B19,B20,B21,B22,B23,B40) | C44: =MIN(C19,C20,C21,C22,C23,C40) | D44: =MIN(D19,D20,D21,D22,D23,D40) | E44: =CHOOSE(Inputs!$B$4,B44,C44,D44)
...

Sheet Street
A1: Street consensus versus our base case
A2: Consensus from WS04 04_current_consensus.csv (Zacks and S&P Global Market Intelligence, 3-4 Sep 2026). The bull case has to differ from these, not from LTM actuals.
A4: Line | B4: Street | C4: n / range | D4: Our base | E4: Delta ($ or x) | F4: Delta (%) | G4: Vendor
A5: FY2026 revenue ($M) | B5: 14100 | C5: 8 est, 13,960-14,210 | D5: =Revenue!$I$77 | E5: =D5-B5 | F5: =D5/B5-1 | G5: Zacks 4 Sep 26
A6: FY2026 revenue ($M), second source | B6: 14160 | C6: 43 est, 13,800-14,300 | D6: =Revenue!$I$77 | E6: =D6-B6 | F6: =D6/B6-1 | G6: S&P Global 3 Sep 26
A7: FY2026 adj. EPS ($) | B7: 5.23 | C7: 13 est, 4.85-5.74 | D7: =Cash!$D$51 | E7: =D7-B7 | F7: =D7/B7-1 | G7: Zacks 4 Sep 26
A8: FY2026 FCF ($M) | B8: 5350 | C8: - | D8: =Cash!$D$39 | E8: =D8-B8 | F8: =D8/B8-1 | G8: S&P Global 3 Sep 26
A9: FY2027 revenue ($M) | B9: 15730 | C9: 13 est, 14,990-16,290 | D9: =Revenue!$J$77 | E9: =D9-B9 | F9: =D9/B9-1 | G9: Zacks 4 Sep 26
A10: FY2027 revenue ($M), second source | B10: 15760 | C10: 43 est | D10: =Revenue!$J$77 | E10: =D10-B10 | F10: =D10/B10-1 | G10: S&P Global 3 Sep 26
A11: FY2027 adj. EPS ($) | B11: 6.02 | C11: 13 est, 5.35-6.80 | D11: =Cash!$E$51 | E11: =D11-B11 | F11: =D11/B11-1 | G11: Zacks 4 Sep 26
A12: 3Q2026 revenue ($M) | B12: 4740 | C12: 7 est, 4,720-4,770 | D12: =Revenue!$C$77 | E12: =D12-B12 | F12: =D12/B12-1 | G12: Zacks 4 Sep 26
A13: 3Q2026 adj. EPS ($) | B13: 2.87 | C13: 11 est, 2.52-3.28 | G13: Zacks 4 Sep 26
A14: 4Q2026 revenue ($M) | B14: 3200 | C14: 10 est, 3,050-3,700 | D14: =Revenue!$D$77 | E14: =D14-B14 | F14: =D14/B14-1 | G14: Zacks 4 Sep 26
A15: Mean price target ($) | B15: 178.96 | C15: 46 analysts, 125-220 | D15: =Valuation!$C$46 | E15: =D15-B15 | F15: =D15/B15-1 | G15: S&P Global / TipRanks 3 Sep 26
A17: Historical beat behaviour (WS02, WS04) - how to read our base against the guide
A18: Median revenue beat vs guide midpoint, all 19 guided prints | B18: 0.0252 | G18: WS02 02_guidance_cushion_series.csv
A19: Median revenue beat vs guide midpoint, last 8 prints | B19: 0.0179 | G19: WS02; the cushion has halved
A20: Median revenue beat vs Street, post-2022 (n 14) | B20: 0.017 | G20: WS04 04_consensus_at_print.csv
A21: Probability the print lands above the top of the guide range | B21: 0.78947368 | G21: WS02: 15 of 19
A22: Day-1 excess return explained by the beat | B22: 0.04 | G22: WS04 / the 5 Sep note: R-squared 0.04, LOO negative
A23: 20-day drift zero-crossing, nights surprise vs Street | B23: 0.0183 | G23: WS04 post-2022 fit: excess_20d = -5.19 + 2.834 x nights surprise

Sheet Card_5Nov
A1: 5 November 2026 card - the Q3 2026 print
A2: Model columns are live formulas off the Revenue and Costs sheets; the Active column follows the scenario selector on Inputs!B4. External bars are constants with their source. Q3 2026 reports 5 Nov 2026 (Zacks expected date).
A4: Line | B4: Bear | C4: Base | D4: Bull | E4: Active (Inputs!B4) | F4: Company guide | G4: Street / cushion bar | H4: Source of the bar
A5: 3Q26 revenue ($M) | B5: =Revenue!$C$36 | C5: =Revenue!$C$77 | D5: =Revenue!$C$118 | E5: =CHOOSE(Inputs!$B$4,B5,C5,D5) | F5: $4,690-4,770m (+15-17%) | G5: Street $4,740m; cushion-adj $4,815m | H5: 2Q26 letter; WS04 Zacks 7 est; WS02 02_q3_2026_guide_card.csv (last-8 median cushion +1.79%)
A6: revenue growth y/y | B6: =Revenue!$C$37 | C6: =Revenue!$C$78 | D6: =Revenue!$C$119 | E6: =CHOOSE(Inputs!$B$4,B6,C6,D6) | F6: +15% to +17% | G6: +15.79% (Street) | H6: WS02, WS04
A7: 3Q26 nights (M) | B7: =Revenue!$C$22 | C7: =Revenue!$C$63 | D7: =Revenue!$C$104 | E7: =CHOOSE(Inputs!$B$4,B7,C7,D7) | F7: low double-digit growth | G7: 144-146m (derived) | H7: WS04 04_q3_2026_breakeven.csv; WS02 puts the cushion-adjusted range at 150-154m
A8: nights growth y/y | B8: =Revenue!$C$23 | C8: =Revenue!$C$64 | D8: =Revenue!$C$105 | E8: =CHOOSE(Inputs!$B$4,B8,C8,D8) | F8: 'low double digit' (10-12%) | G8: WS08 nowcast +12.1% (9.3-14.9) | H8: WS08 08_q3_2026_nowcast.csv demand_eq; naive baseline +10.3%
A9: 3Q26 ADR ($) | B9: =Revenue!$C$26 | C9: =Revenue!$C$67 | D9: =Revenue!$C$108 | E9: =CHOOSE(Inputs!$B$4,B9,C9,D9) | F9: 'up moderately' | G9: - | H9: 2Q26 letter
A10: ADR growth y/y | B10: =Revenue!$C$27 | C10: =Revenue!$C$68 | D10: =Revenue!$C$109 | E10: =CHOOSE(Inputs!$B$4,B10,C10,D10) | F10: - | G10: +4.05% (WS08) | H10: WS08: ex-FX run-rate +3.25% plus FX +0.80pp; r 0.96, walk-forward 0.44x naive
A11: of which FX | B11: =Revenue!$C$25 | C11: =Revenue!$C$66 | D11: =Revenue!$C$107 | E11: =CHOOSE(Inputs!$B$4,B11,C11,D11) | F11: - | G11: +0.80pp | H11: WS05 05_fx_schedule.csv broad-USD fit; WS08 refit
A12: 3Q26 GBV ($M) | B12: =Revenue!$C$28 | C12: =Revenue!$C$69 | D12: =Revenue!$C$110 | E12: =CHOOSE(Inputs!$B$4,B12,C12,D12) | F12: mid-teens growth | G12: $26.6-27.2bn (WS02 cushion) | H12: 2Q26 letter; WS02
A13: GBV growth y/y | B13: =Revenue!$C$29 | C13: =Revenue!$C$70 | D13: =Revenue!$C$111 | E13: =CHOOSE(Inputs!$B$4,B13,C13,D13) | F13: mid teens (14-16%) | G13: 16-19% | H13: WS02
A14: 3Q26 take rate | B14: =Revenue!$C$30 | C14: =Revenue!$C$71 | D14: =Revenue!$C$112 | E14: =CHOOSE(Inputs!$B$4,B14,C14,D14) | F14: 'relatively in line y/y' | G14: 17.9% +/- 0.2pt | H14: 2Q26 call; WS02. 3Q25 actual 17.88%
A15: 3Q26 adj. EBITDA margin | B15: =Revenue!$C$40 | C15: =Revenue!$C$81 | D15: =Revenue!$C$122 | E15: =CHOOSE(Inputs!$B$4,B15,C15,D15) | F15: 'down slightly' vs 50.1% | G15: 48.7-50.0% | H15: WS07 5 Nov card (bear 48.3 / base 49.0 / bull 50.2); WS02 says 9 of 10 such ceilings were met
A16: 3Q26 adj. EBITDA ($M) | B16: =Revenue!$C$41 | C16: =Revenue!$C$82 | D16: =Revenue!$C$123 | E16: =CHOOSE(Inputs!$B$4,B16,C16,D16) | F16: up y/y | G16: $2,300-2,400m (derived) | H16: WS04 04_q3_2026_breakeven.csv
A18: THE Q4 GUIDE - what the print's reaction actually runs on
A19: 4Q26 revenue ($M), our forecast | B19: =Revenue!$D$36 | C19: =Revenue!$D$77 | D19: =Revenue!$D$118 | E19: =CHOOSE(Inputs!$B$4,B19,C19,D19) | F19: no guide yet | G19: Street $3,200m (3,050-3,700) | H19: WS04 Zacks 10 est - the widest spread in the table (21% high-low)
A20: 4Q26 revenue growth | B20: =Revenue!$D$37 | C20: =Revenue!$D$78 | D20: =Revenue!$D$119 | E20: =CHOOSE(Inputs!$B$4,B20,C20,D20) | F20: - | G20: +11-13% expected | H20: WS05: FX goes from about +3pp in Q3 to -0.4pp in Q4 and 84% of it is already realised
A21: 4Q26 nights growth | B21: =Revenue!$D$23 | C21: =Revenue!$D$64 | D21: =Revenue!$D$105 | E21: =CHOOSE(Inputs!$B$4,B21,C21,D21) | F21: - | G21: accelerating vs Q3 is the bull tell | H21: WS05: post-2022 an accelerating nights guide averaged +6.7% day-1 (n 5), a decelerating one -5.4% (n 9)
A22: FY26 revenue ($M) | B22: =Revenue!$I$36 | C22: =Revenue!$I$77 | D22: =Revenue!$I$118 | E22: =CHOOSE(Inputs!$B$4,B22,C22,D22) | F22: 'at least mid teens' growth | G22: Street $14,100-14,160m | H22: 2Q26 letter; WS04
A23: FY26 revenue growth | B23: =Revenue!$I$37 | C23: =Revenue!$I$78 | D23: =Revenue!$I$119 | E23: =CHOOSE(Inputs!$B$4,B23,C23,D23) | F23: at least +14-16% | G23: +15.2% to +15.6% | H23: WS04
A24: FY26 adj. EBITDA margin | B24: =Costs!$D$22 | C24: =Costs!$D$52 | D24: =Costs!$D$82 | E24: =CHOOSE(Inputs!$B$4,B24,C24,D24) | F24: 'at least 35.5%' | G24: 36.1-36.9% on the FY24/FY25 cushion | H24: WS02: FY24 beat the floor by 140bp, FY25 by 60bp
A26: CONTEXT AND BASE RATES
A27: Alt-data demand index, 3Q26 to date (z) | C27: -0.325 | H27: WS08 08_demand_index_quarterly.csv, demand_eq; 2Q26 was -0.509, so the index improved. Only 4 of 7 components are populated for 3Q26 and no composite beat a naive baseline walk-forward.
A28: Funds-held backlog nowcast, 3Q26 revenue growth | C28: 0.12 | H28: WS08 08_backlog_tests.csv: funds held +10.46% y/y at 2Q26 x slope 0.60. Under-shot 1Q26 by 3.4pp and 2Q26 by 2.8pp because RNPL defers guest cash to check-in; add ~3pp.
A29: Mean absolute day-1 move on a print | C29: 0.0707 | H29: WS09, n 23; median 6.87%
A30: Mean 20-session post-print excess drift | C30: -0.037 | H30: WS09, n 23, t -2.16
A31: Nights-acceleration sign rule hit rate | C31: 0.80952381 | H31: WS01/predictive study: the sign of the nights-growth acceleration has set the day-1 direction in 17 of 21 prints
A32: Share of day-1 move that is re-rating, not estimates | C32: 0.97 | H32: WS12: day-1 move correlates +0.97 with the change in the EV/NTM-revenue multiple, +0.09 with the estimate change
A33: One turn of EV / NTM EBITDA | C33: 9.11 | H33: WS12: $9.11 per share = 5.0% at $181.94
A34: November excess return vs QQQ, 2021-2025 | C34: -0.051 | H34: WS09: ABNB has underperformed in every November since 2021

Sheet Recon
A1: Reconciliation: the Python mirror against this workbook
A2: Column B is the Python mirror (13_driver_model.py), column C is this workbook and column D is a live Excel formula, so Excel re-checks the difference every time the file is opened. Every |delta| should be 0.00. The same 216 outputs are also checked outside Excel by analysis/src/overnight/13_xlsx_eval.py. Workstream 17 then rebuilt the file in Excel 16.0 itself (Application.CalculateFullRebuild via COM): 0 error cells in 5,544, no circular reference, all 216 outputs and all 2,348 formula cells agreeing with the mirror to better than 1e-6 relative (worst 4.2e-15). Full results: data/processed/overnight/13_reconciliation.csv and 17_excel_vs_python.csv; the audit is research/notes/overnight/17_excel-audit.md.
A4: Item | B4: Python mirror | C4: Workbook cell | D4: Delta | E4: Cell reference
A5: Bear FY2026 revenue ($M) | B5: 13933.349 | C5: =Revenue!$I$36 | D5: =C5-B5 | E5: Revenue!$I$36
A6: Bear FY2026 nights (M) | B6: 579.09738 | C6: =Revenue!$I$22 | D6: =C6-B6 | E6: Revenue!$I$22
A7: Bear FY2026 GBV ($M) | B7: 103758.74 | C7: =Revenue!$I$28 | D7: =C7-B7 | E7: Revenue!$I$28
A8: Bear FY2026 adj. EBITDA ($M) | B8: 4812.2867 | C8: =Costs!$D$21 | D8: =C8-B8 | E8: Costs!$D$21
A9: Bear FY2026 adj. EBITDA margin | B9: 0.34537904 | C9: =Costs!$D$22 | D9: =C9-B9 | E9: Costs!$D$22
A10: Bear FY2026 net income ($M) | B10: 2644.862 | C10: =Costs!$D$32 | D10: =C10-B10 | E10: Costs!$D$32
A11: Bear FY2026 FCF ($M) | B11: 4554.8859 | C11: =Cash!$D$14 | D11: =C11-B11 | E11: Cash!$D$14
A12: Bear FY2026 SBC-adj FCF ($M) | B12: 2720.9259 | C12: =Cash!$D$18 | D12: =C12-B12 | E12: Cash!$D$18
A13: Bear FY2026 diluted shares (M) | B13: 589.01948 | C13: =Cash!$D$23 | D13: =C13-B13 | E13: Cash!$D$23
A14: Bear FY2026 FCF per share ($) | B14: 7.732997 | C14: =Cash!$D$24 | D14: =C14-B14 | E14: Cash!$D$24
A15: Bear FY2026 net cash ($M) | B15: 8792.9999 | C15: =Cash!$D$27 | D15: =C15-B15 | E15: Cash!$D$27
A16: Bear FY2027 revenue ($M) | B16: 14180.974 | C16: =Revenue!$J$36 | D16: =C16-B16 | E16: Revenue!$J$36
A17: Bear FY2027 nights (M) | B17: 611.22284 | C17: =Revenue!$J$22 | D17: =C17-B17 | E17: Revenue!$J$22
A18: Bear FY2027 GBV ($M) | B18: 108038.48 | C18: =Revenue!$J$28 | D18: =C18-B18 | E18: Revenue!$J$28
A19: Bear FY2027 adj. EBITDA ($M) | B19: 4026.9273 | C19: =Costs!$E$21 | D19: =C19-B19 | E19: Costs!$E$21
A20: Bear FY2027 adj. EBITDA margin | B20: 0.2839669 | C20: =Costs!$E$22 | D20: =C20-B20 | E20: Costs!$E$22
A21: Bear FY2027 net income ($M) | B21: 1754.2614 | C21: =Costs!$E$32 | D21: =C21-B21 | E21: Costs!$E$32
A22: Bear FY2027 FCF ($M) | B22: 3531.3449 | C22: =Cash!$E$14 | D22: =C22-B22 | E22: Cash!$E$14
A23: Bear FY2027 SBC-adj FCF ($M) | B23: 1440.6305 | C23: =Cash!$E$18 | D23: =C23-B23 | E23: Cash!$E$18
A24: Bear FY2027 diluted shares (M) | B24: 580.42933 | C24: =Cash!$E$23 | D24: =C24-B24 | E24: Cash!$E$23
A25: Bear FY2027 FCF per share ($) | B25: 6.0840222 | C25: =Cash!$E$24 | D25: =C25-B25 | E25: Cash!$E$24
A26: Bear FY2027 net cash ($M) | B26: 8592.5948 | C26: =Cash!$E$27 | D26: =C26-B26 | E26: Cash!$E$27
A27: Bear FY2028 revenue ($M) | B27: 14970.671 | C27: =Revenue!$K$36 | D27: =C27-B27 | E27: Revenue!$K$36
A28: Bear FY2028 nights (M) | B28: 638.41455 | C28: =Revenue!$K$22 | D28: =C28-B28 | E28: Revenue!$K$22
A29: Bear FY2028 GBV ($M) | B29: 113973.28 | C29: =Revenue!$K$28 | D29: =C29-B29 | E29: Revenue!$K$28
A30: Bear FY2028 adj. EBITDA ($M) | B30: 3814.4838 | C30: =Costs!$F$21 | D30: =C30-B30 | E30: Costs!$F$21
A31: Bear FY2028 adj. EBITDA margin | B31: 0.25479712 | C31: =Costs!$F$22 | D31: =C31-B31 | E31: Costs!$F$22
A32: Bear FY2028 net income ($M) | B32: 1351.0166 | C32: =Costs!$F$32 | D32: =C32-B32 | E32: Costs!$F$32
A33: Bear FY2028 FCF ($M) | B33: 3123.5661 | C33: =Cash!$F$14 | D33: =C33-B33 | E33: Cash!$F$14
A34: Bear FY2028 SBC-adj FCF ($M) | B34: 781.96602 | C34: =Cash!$F$18 | D34: =C34-B34 | E34: Cash!$F$18
A35: Bear FY2028 diluted shares (M) | B35: 573.06123 | C35: =Cash!$F$23 | D35: =C35-B35 | E35: Cash!$F$23
A36: Bear FY2028 FCF per share ($) | B36: 5.4506674 | C36: =Cash!$F$24 | D36: =C36-B36 | E36: Cash!$F$24
A37: Bear FY2028 net cash ($M) | B37: 7896.6009 | C37: =Cash!$F$27 | D37: =C37-B37 | E37: Cash!$F$27
A38: Bear 3Q26 revenue ($M) | B38: 4632.3551 | C38: =Revenue!$C$36 | D38: =C38-B38 | E38: Revenue!$C$36
A39: Bear 3Q26 nights (M) | B39: 144.17596 | C39: =Revenue!$C$22 | D39: =C39-B39 | E39: Revenue!$C$22
A40: Bear 3Q26 ADR ($) | B40: 176.11353 | C40: =Revenue!$C$26 | D40: =C40-B40 | E40: Revenue!$C$26
A41: Bear 3Q26 adj. EBITDA ($M) | B41: 2237.4275 | C41: =Revenue!$C$41 | D41: =C41-B41 | E41: Revenue!$C$41
...
