Workbook

Sheet Cover
A1: NASDAQ: ABNB | Airbnb
A2: ="Target Price: $" & ROUND(AVERAGE(E32:E34),3) -> Target Price: $120.889 | O2: Stock Price | P2: 151.39
A3: ="Target Downside: " & ROUND(E36*100,2) & "%" -> Target Downside: -20.61% | O3: Shares Outstanding | P3: 589.6
B4: 1Q25A | C4: 2Q25A | D4: 3Q25A | E4: 4Q25A | F4: 1Q26A | G4: 2Q26A | H4: 3Q26E | I4: 4Q26E | J4: 1Q27E | K4: 2Q27E | L4: 3Q27E | M4: 4Q27E | O4: Market Cap (mm) | P4: =P2*P3 -> 89259.544
A5: Revenue | B5: =Income_Statement!J11 -> 2272 | C5: =Income_Statement!K11 -> 3096 | D5: =Income_Statement!L11 -> 4095 | E5: =Income_Statement!M11 -> 2778 | F5: =Income_Statement!N11 -> 2678 | G5: =Income_Statement!O11 -> 3608 | H5: =Income_Statement!P11 -> 4608.6636 | I5: =Income_Statement!Q11 -> 3078.7194 | ... M5: =Income_Statement!U11 -> 3309.1926 | O5: Debt | P5: 2476
A6: YoY Growth Rate | B6: =Income_Statement!J12 -> 0.060690943 | C6: =Income_Statement!K12 -> 0.12663755 | D6: =Income_Statement!L12 -> 0.097266881 | E6: =Income_Statement!M12 -> 0.12016129 | F6: =Income_Statement!N12 -> 0.17869718 | G6: =Income_Statement!O12 -> 0.16537468 | H6: =Income_Statement!P12 -> 0.12543676 | I6: =Income_Statement!Q12 -> 0.10825034 | ... M6: =Income_Statement!U12 -> 0.074860074 | O6: Cash | P6: 12069
A7: Nights (mm) | B7: =Income_Statement!J4 -> 143.1 | C7: =Income_Statement!K4 -> 134.4 | D7: =Income_Statement!L4 -> 133.6 | E7: =Income_Statement!M4 -> 121.9 | F7: =Income_Statement!N4 -> 156.2 | G7: =Income_Statement!O4 -> 148.3 | H7: =Income_Statement!P4 -> 145.8912 | I7: =Income_Statement!Q4 -> 130.76335 | ... M7: =Income_Statement!U4 -> 138.51631 | O7: Enterprise Value | P7: =P4+P5-P6 -> 79666.544
A8: YoY Growth Rate | B8: =Income_Statement!J5 -> 0.07918552 | C8: =Income_Statement!K5 -> 0.074340528 | D8: =Income_Statement!L5 -> 0.087947883 | E8: =Income_Statement!M5 -> 0.098198198 | F8: =Income_Statement!N5 -> 0.091544375 | G8: =Income_Statement!O5 -> 0.10342262 | H8: =Income_Statement!P5 -> 0.092 | I8: =Income_Statement!Q5 -> 0.07271 | ... M8: =Income_Statement!U5 -> 0.05929
A9: ADR | B9: =Income_Statement!J9 -> 171.34 | C9: =Income_Statement!K9 -> 174.48 | D9: =Income_Statement!L9 -> 171.29 | E9: =Income_Statement!M9 -> 167.51 | F9: =Income_Statement!N9 -> 186.82 | G9: =Income_Statement!O9 -> 183.73 | H9: =Income_Statement!P9 -> 175.66234 | I9: =Income_Statement!Q9 -> 170.95632 | ... M9: =Income_Statement!U9 -> 173.46913
A10: YoY Growth Rate | B10: =Income_Statement!J10 -> -0.008907913 | C10: =Income_Statement!K10 -> 0.029198372 | D10: =Income_Statement!L10 -> 0.046748961 | E10: =Income_Statement!M10 -> 0.059318282 | F10: =Income_Statement!N10 -> 0.090346679 | G10: =Income_Statement!O10 -> 0.053014672 | H10: =Income_Statement!P10 -> 0.025525946 | I10: =Income_Statement!Q10 -> 0.020573793 | ... M10: =Income_Statement!U10 -> 0.014698595
A11: Take Rate | B11: =Income_Statement!J13 -> 0.092663763 | C11: =Income_Statement!K13 -> 0.13202496 | D11: =Income_Statement!L13 -> 0.1789433 | E11: =Income_Statement!M13 -> 0.13604663 | F11: =Income_Statement!N13 -> 0.09177115 | G11: =Income_Statement!O13 -> 0.13241748 | H11: =Income_Statement!P13 -> 0.17983211 | I11: =Income_Statement!Q13 -> 0.13772061 | ... M11: =Income_Statement!U13 -> 0.13772061
A13: Total Cash Costs of Revenue | B13: =Income_Statement!J20 -> 1880 | C13: =Income_Statement!K20 -> 2067 | D13: =Income_Statement!L20 -> 2067 | E13: =Income_Statement!M20 -> 2017 | F13: =Income_Statement!N20 -> 2179 | G13: =Income_Statement!O20 -> 2365 | H13: =Income_Statement!P20 -> 2397.2264 | I13: =Income_Statement!Q20 -> 2287.7491 | ... M13: =Income_Statement!U20 -> 2500.7534
A14: Adjusted EBITDA | B14: =Income_Statement!J23 -> 417 | C14: =Income_Statement!K23 -> 1043 | D14: =Income_Statement!L23 -> 2051 | E14: =Income_Statement!M23 -> 786 | F14: =Income_Statement!N23 -> 519 | G14: =Income_Statement!O23 -> 1261 | H14: =Income_Statement!P23 -> 2232.0711 | I14: =Income_Statement!Q23 -> 811.60431 | ... M14: =Income_Statement!U23 -> 829.07315
A15: YoY Growth Rate | B15: =Income_Statement!J23/Income_Statement!F23-1 -> -0.016509434 | C15: =Income_Statement!K23/Income_Statement!G23-1 -> 0.16666667 | D15: =Income_Statement!L23/Income_Statement!H23-1 -> 0.047497446 | E15: =Income_Statement!M23/Income_Statement!I23-1 -> 0.02745098 | F15: =Income_Statement!N23/Income_Statement!J23-1 -> 0.24460432 | G15: =Income_Statement!O23/Income_Statement!K23-1 -> 0.20901246 | H15: =Income_Statement!P23/Income_Statement!L23-1 -> 0.088284293 | I15: =Income_Statement!Q23/Income_Statement!M23-1 -> 0.032575452 | ... M15: =Income_Statement!U23/Income_Statement!Q23-1 -> 0.021523849
A16: Adjusted EBITDA Margin | B16: =B14/B5 -> 0.18353873 | C16: =C14/C5 -> 0.3368863 | D16: =D14/D5 -> 0.5008547 | E16: =E14/E5 -> 0.28293737 | F16: =F14/F5 -> 0.19380134 | G16: =G14/G5 -> 0.34950111 | H16: =H14/H5 -> 0.48432068 | I16: =I14/I5 -> 0.26361749 | ... M16: =M14/M5 -> 0.25053638
A18: GAAP Operating Income | B18: =Income_Statement!J27 -> 38 | C18: =Income_Statement!K27 -> 612 | D18: =Income_Statement!L27 -> 1625 | E18: =Income_Statement!M27 -> 269 | F18: =Income_Statement!N27 -> 86 | G18: =Income_Statement!O27 -> 758 | H18: =Income_Statement!P27 -> 1759.8579 | I18: =Income_Statement!Q27 -> 325.80982 | ... M18: =Income_Statement!U27 -> 281.98102
A19: Net Income | B19: =Income_Statement!J33 -> 154 | C19: =Income_Statement!K33 -> 642 | D19: =Income_Statement!L33 -> 1374 | E19: =Income_Statement!M33 -> 341 | F19: =Income_Statement!N33 -> 160 | G19: =Income_Statement!O33 -> 816 | H19: =Income_Statement!P33 -> 1565.8805 | I19: =Income_Statement!Q33 -> 374.40379 | ... M19: =Income_Statement!U33 -> 344.50482
A20: Diluted EPS | B20: =Income_Statement!J35 -> 0.24 | C20: =Income_Statement!K35 -> 1.03 | D20: =Income_Statement!L35 -> 2.21 | E20: =Income_Statement!M35 -> 0.56 | F20: =Income_Statement!N35 -> 0.26 | G20: =Income_Statement!O35 -> 1.37 | H20: =Income_Statement!P35 -> 2.6465176 | I20: =Income_Statement!Q35 -> 0.63853116 | ... M20: =Income_Statement!U35 -> 0.60968383
B22: Modeled | C22: Cons. | D22: Modeled | E22: Cons. | F22: Modeled | G22: Cons. | H22: Modeled | I22: Cons. | J22: Modeled | K22: Cons.
A23: Our Model vs Consensus | B23: 3Q26 | C23: 3Q26 | D23: 4Q26 | E23: 4Q26 | F23: 1Q27 | G23: 1Q27 | H23: 2Q27 | I23: 2Q27 | J23: FY27 | K23: FY27
A24: Revenue | B24: =H5 -> 4608.6636 | C24: =Income_Statement!P38 -> 4744.32 | D24: =I5 -> 3078.7194 | E24: =Income_Statement!Q38 -> 3161.82 | F24: =J5 -> 2902.326 | G24: =Income_Statement!R38 -> 3010.32 | H24: =L5 -> 4951.0709 | I24: =Income_Statement!T38 -> 5269.9673 | J24: =SUM(J5:M5) -> 15022.449 | K24: =SUM(Income_Statement!R38:U38) -> 15846.147
A25: delta | B25: =B24/C24-1 -> -0.028593444 | D25: =D24/E24-1 -> -0.026282507 | F25: =F24/G24-1 -> -0.035874604 | H25: =H24/I24-1 -> -0.060512028 | J25: =J24/K24-1 -> -0.051980935
A26: Nights | B26: =H7 -> 145.8912 | C26: 149 | D26: =I7 -> 130.76335 | E26: 134 | F26: =J7 -> 168.41484 | H26: =L7 -> 154.78035 | J26: =SUM(J7:M7) -> 618.49426
A27: ADR | B27: =H9 -> 175.66234 | C27: 177.06 | D27: =I9 -> 170.95632 | E27: 171.33 | F27: =J9 -> 187.90967 | H27: =K9 -> 185.59486 | J27: 181.56
A28: Adjusted EBITDA | B28: =H14 -> 2232.0711 | C28: =Income_Statement!P40 -> 2361.52 | D28: =I14 -> 811.60431 | E28: =Income_Statement!Q40 -> 913.68 | F28: =J14 -> 420.31108 | G28: =Income_Statement!R40 -> 610.73 | H28: =K14 -> 1214.6999 | I28: =Income_Statement!S40 -> 1451.71 | J28: =SUM(J14:M14) -> 4894.7104 | K28: =SUM(Income_Statement!R40:U40) -> 5826.3888
A29: EPS | B29: =H20 -> 2.6465176 | C29: 2.85 | D29: =I20 -> 0.63853116 | E29: 0.86 | F29: =J20 -> 0.11402339 | G29: 0.39 | H29: =K20 -> 1.1606667 | I29: 1.53 | J29: =SUM(J20:M20) -> 4.8560874 | K29: 6.24
A31: Multiples | B31: Our Number | C31: Consensus | D31: Target Multiple | E31: Target Price
A32: EV/EBITDA NTM | B32: =P7/SUM(H14:K14) -> 17.027545 | C32: =P7/SUM(C28,E28,G28,I28) -> 14.925425 | D32: =C32-1.5 -> 13.425425 | E32: =(D32*SUM(H14:K14)+$P$6-$P$5)/$P$3 -> 122.80589
A33: EV/ Q4 EBITDA | B33: =P7/D28 -> 98.159341 | C33: =P7/E28 -> 87.193048 | D33: =C33-10 -> 77.193048 | E33: =(D33*D28+$P$6-$P$5)/$P$3 -> 122.52919
A34: EV/FY27 EBITDA | B34: =P7/J28 -> 16.276049 | C34: =P7/K28 -> 13.6734 | D34: =C34-1.5 -> 12.1734 | E34: =(D34*J28+$P$6-$P$5)/$P$3 -> 117.33085
E35: =AVERAGE(E32:E34)-0.7 -> 120.18864
E36: =E35/P2-1 -> -0.20609921

Sheet Income_Statement
A1: Airbnb — income statement, official (built line by line; nights first). USD millions unless stated.
A3: Quarter | B3: 1Q23A | C3: 2Q23A | D3: 3Q23A | E3: 4Q23A | F3: 1Q24A | G3: 2Q24A | H3: 3Q24A | I3: 4Q24A | J3: 1Q25A | K3: 2Q25A | L3: 3Q25A | M3: 4Q25A | N3: 1Q26A | O3: 2Q26A | P3: 3Q26E | Q3: 4Q26E | R3: 1Q27E | S3: 2Q27E | T3: 3Q27E | U3: 4Q27E | W3: FY23 | X3: FY24 | Y3: FY25 | Z3: FY26
A4: Nights & seats booked (m) | B4: =Nights_Engine!J6 -> 121.1 | C4: =Nights_Engine!K6 -> 115.1 | D4: =Nights_Engine!L6 -> 113.2 | E4: =Nights_Engine!M6 -> 98.8 | F4: =Nights_Engine!N6 -> 132.6 | G4: =Nights_Engine!O6 -> 125.1 | H4: =Nights_Engine!P6 -> 122.8 | I4: =Nights_Engine!Q6 -> 111 | ... O4: =Nights_Engine!W6 -> 148.3 | P4: =Nights_Engine!X84 -> 145.8912 | Q4: =Nights_Engine!Y84 -> 130.76335 | R4: =Nights_Engine!Z84 -> 168.41484 | S4: =Nights_Engine!AA84 -> 156.78276 | T4: =Nights_Engine!AB84 -> 154.78035 | U4: =Nights_Engine!AC84 -> 138.51631 | W4: =B4+C4+D4+E4 -> 448.2 | X4: =F4+G4+H4+I4 -> 491.5 | Y4: =J4+K4+L4+M4 -> 533 | Z4: =N4+O4+P4+Q4 -> 581.15455
A5: y/y | B5: =Nights_Engine!J7 -> 0.18609207 | C5: =Nights_Engine!K7 -> 0.1099325 | D5: =Nights_Engine!L7 -> 0.13540622 | E5: =Nights_Engine!M7 -> 0.12018141 | F5: =F4/B4-1 -> 0.094962841 | G5: =G4/C4-1 -> 0.086880973 | H5: =H4/D4-1 -> 0.084805654 | I5: =I4/E4-1 -> 0.12348178 | J5: =J4/F4-1 -> 0.07918552 | K5: =K4/G4-1 -> 0.074340528 | L5: =L4/H4-1 -> 0.087947883 | M5: =M4/I4-1 -> 0.098198198 | ... U5: =U4/Q4-1 -> 0.05929 | X5: =X4/W4-1 -> 0.096608657 | Y5: =Y4/X4-1 -> 0.084435402 | Z5: =Z4/Y4-1 -> 0.090346246
A6: Lines to build together (in order) — empty until each has its rationale file
A7: Gross booking value ($bn) | B7: =B4*B9/1000 -> 20.396873 | C7: =C4*C9/1000 -> 19.107751 | D7: =D4*D9/1000 -> 18.268216 | E7: =E4*E9/1000 -> 15.484924 | F7: =F4*F9/1000 -> 22.923888 | G7: =G4*G9/1000 -> 21.208203 | H7: =H4*H9/1000 -> 20.094992 | I7: =I4*I9/1000 -> 17.55243 | ... U7: =U4*U9/1000 -> 24.028304
A8: y/y | F8: =F7/B7-1 -> 0.12389228 | G8: =G7/C7-1 -> 0.1099267 | H8: =H7/D7-1 -> 0.099997504 | I8: =I7/E7-1 -> 0.13351735 | J8: =J7/F7-1 -> 0.06957223 | K8: =K7/G7-1 -> 0.10570952 | L8: =L7/H7-1 -> 0.13880832 | M8: =M7/I7-1 -> 0.16334143 | ... U8: =U7/Q7-1 -> 0.074860074
A9: ADR ($ = GBV / nights) | B9: =ADR_Engine!K6 -> 168.43 | C9: =ADR_Engine!L6 -> 166.01 | D9: =ADR_Engine!M6 -> 161.38 | E9: =ADR_Engine!N6 -> 156.73 | F9: =ADR_Engine!O6 -> 172.88 | G9: =ADR_Engine!P6 -> 169.53 | H9: =ADR_Engine!Q6 -> 163.64 | I9: =ADR_Engine!R6 -> 158.13 | ... U9: =ADR_Engine!AD6 -> 173.46913
A10: y/y | B10: =ADR_Engine!K7 -> 0.0021419647 | C10: =ADR_Engine!L7 -> 0.013863442 | D10: =ADR_Engine!M7 -> 0.031577602 | E10: =ADR_Engine!N7 -> 0.025652771 | F10: =F9/B9-1 -> 0.026420471 | G10: =G9/C9-1 -> 0.021203542 | H10: =H9/D9-1 -> 0.014004214 | I10: =I9/E9-1 -> 0.0089325592 | J10: =J9/F9-1 -> -0.008907913 | K10: =K9/G9-1 -> 0.029198372 | L10: =L9/H9-1 -> 0.046748961 | M10: =M9/I9-1 -> 0.059318282 | ... U10: =U9/Q9-1 -> 0.014698595
A11: Revenue | B11: 1818 | C11: 2484 | D11: 3397 | E11: 2218 | F11: 2142 | G11: 2748 | H11: 3732 | I11: 2480 | J11: 2272 | K11: 3096 | L11: 4095 | M11: 2778 | N11: 2678 | O11: 3608 | P11: =P7*1000*P13 -> 4608.6636 | Q11: =Q7*1000*Q13 -> 3078.7194 | R11: =R7*1000*R13 -> 2902.326 | S11: =S7*1000*S13 -> 3859.8597 | T11: =T7*1000*T13 -> 4951.0709 | U11: =U7*1000*U13 -> 3309.1926 | W11: =SUM(B11:E11) -> 9917 | X11: =SUM(F11:I11) -> 11102 | Y11: =SUM(J11:M11) -> 12241 | Z11: =SUM(N11:Q11) -> 13973.383
A12: y/y | F12: =F11/B11-1 -> 0.17821782 | G12: =G11/C11-1 -> 0.10628019 | H12: =H11/D11-1 -> 0.098616426 | I12: =I11/E11-1 -> 0.11812444 | J12: =J11/F11-1 -> 0.060690943 | K12: =K11/G11-1 -> 0.12663755 | L12: =L11/H11-1 -> 0.097266881 | M12: =M11/I11-1 -> 0.12016129 | ... U12: =U11/Q11-1 -> 0.074860074 | X12: =X11/W11-1 -> 0.11949178 | Y12: =Y11/X11-1 -> 0.10259413 | Z12: =Z11/Y11-1 -> 0.141523
A13: Take rate (revenue / GBV) | B13: =B11/(B7*1000) -> 0.089131309 | C13: =C11/(C7*1000) -> 0.1299996 | D13: =D11/(D7*1000) -> 0.18595138 | E13: =E11/(E7*1000) -> 0.14323609 | F13: =F11/(F7*1000) -> 0.093439647 | G13: =G11/(G7*1000) -> 0.12957251 | H13: =H11/(H7*1000) -> 0.18571791 | I13: =I11/(I7*1000) -> 0.14129098 | ... O13: =O11/(O7*1000) -> 0.13241748 | P13: 0.17983211 | Q13: 0.13772061 | R13: 0.09171 | S13: 0.13265 | T13: 0.17983211 | U13: 0.13772061 | W13: =W11/(SUM(B7:E7)*1000) -> 0.13537132 | X13: =X11/(SUM(F7:I7)*1000) -> 0.13575527 | Y13: =Y11/(SUM(J7:M7)*1000) -> 0.13411461 | Z13: =Z11/(SUM(N7:Q7)*1000) -> 0.13383075
A15: Cost of revenue (cash) | B15: 428 | C15: 432 | D15: 459 | E15: 384 | F15: 480 | G15: 506 | H15: 465 | I15: 427 | J15: 506 | K15: 544 | L15: 549 | M15: 487 | N15: 581 | O15: 633 | P15: =P134 -> 633.27718 | Q15: =Q134 -> 566.40061 | R15: =R134 -> 691.12654 | S15: =S134 -> 717.4014 | T15: =T134 -> 683.71493 | U15: =U134 -> 612.03994 | W15: =SUM(B15:E15) -> 1703 | X15: =SUM(F15:I15) -> 1878 | Y15: =SUM(J15:M15) -> 2086 | Z15: =SUM(N15:Q15) -> 2413.6778
A16: Operations & support (cash) | B16: 267 | C16: 298 | D16: 299 | E16: 254 | F16: 266 | G16: 314 | H16: 347 | I16: 265 | J16: 282 | K16: 309 | L16: 343 | M16: 303 | N16: 301 | O16: 323 | P16: =P139 -> 360.99951 | Q16: =Q139 -> 317.80492 | R16: =R139 -> 318.85814 | S16: =S139 -> 340.83264 | T16: =T139 -> 381.19426 | U16: =U139 -> 335.48106 | W16: =SUM(B16:E16) -> 1118 | X16: =SUM(F16:I16) -> 1192 | Y16: =SUM(J16:M16) -> 1237 | Z16: =SUM(N16:Q16) -> 1302.8044
A17: Product development (cash) | B17: 271 | C17: 260 | D17: 244 | E17: 253 | F17: 290 | G17: 280 | H17: 294 | I17: 306 | J17: 338 | K17: 331 | L17: 333 | M17: 335 | N17: 375 | O17: 374 | P17: =P140 -> 359.09488 | Q17: =Q140 -> 369.02512 | R17: =R140 -> 414.12379 | S17: =S140 -> 400.79642 | T17: =T140 -> 399.65871 | U17: =U140 -> 410.71068 | W17: =SUM(B17:E17) -> 1028 | X17: =SUM(F17:I17) -> 1170 | Y17: =SUM(J17:M17) -> 1337 | Z17: =SUM(N17:Q17) -> 1477.12
A18: Sales & marketing (cash) | B18: 422 | C18: 450 | D18: 370 | E18: 391 | F18: 479 | G18: 527 | H18: 471 | I18: 501 | J18: 519 | K18: 639 | L18: 585 | M18: 633 | N18: 696 | O18: 808 | P18: =P143 -> 778.4658 | Q18: =Q143 -> 758.10753 | R18: =R143 -> 829.31313 | S18: =S143 -> 935.18289 | T18: =T143 -> 819.97168 | U18: =U143 -> 875.32842 | W18: =SUM(B18:E18) -> 1633 | X18: =SUM(F18:I18) -> 1978 | Y18: =SUM(J18:M18) -> 2376 | Z18: =SUM(N18:Q18) -> 3040.5733
A19: General & administrative (cash, ex lodging-tax reserves) | B19: 191 | C19: 219 | D19: 202 | E19: 211 | F19: 223 | G19: 242 | H19: 210 | I19: 226 | J19: 235 | K19: 244 | L19: 257 | M19: 259 | N19: 226 | O19: 227 | P19: =P144 -> 265.38907 | Q19: =Q144 -> 276.41093 | R19: =R144 -> 249.22724 | S19: =S144 -> 271.5804 | T19: =T144 -> 256.53902 | U19: =U144 -> 267.19333 | W19: =SUM(B19:E19) -> 823 | X19: =SUM(F19:I19) -> 901 | Y19: =SUM(J19:M19) -> 995 | Z19: =SUM(N19:Q19) -> 994.8
A20: Total cash costs | B20: =SUM(B15:B19) -> 1579 | C20: =SUM(C15:C19) -> 1659 | D20: =SUM(D15:D19) -> 1574 | E20: =SUM(E15:E19) -> 1493 | F20: =SUM(F15:F19) -> 1738 | G20: =SUM(G15:G19) -> 1869 | H20: =SUM(H15:H19) -> 1787 | I20: =SUM(I15:I19) -> 1725 | ... U20: =SUM(U15:U19) -> 2500.7534 | W20: =SUM(B20:E20) -> 6305 | X20: =SUM(F20:I20) -> 7119 | Y20: =SUM(J20:M20) -> 8031 | Z20: =SUM(N20:Q20) -> 9228.9755
A21: % of revenue | B21: =B20/B11 -> 0.86853685 | C21: =C20/C11 -> 0.6678744 | D21: =D20/D11 -> 0.46335001 | E21: =E20/E11 -> 0.67312894 | F21: =F20/F11 -> 0.81139122 | G21: =G20/G11 -> 0.680131 | H21: =H20/H11 -> 0.47883173 | I21: =I20/I11 -> 0.69556452 | ... U21: =U20/U11 -> 0.75569896 | W21: =W20/W11 -> 0.63577695 | X21: =X20/X11 -> 0.64123581 | Y21: =Y20/Y11 -> 0.65607385 | Z21: =Z20/Z11 -> 0.66046823
A22: Depreciation & amortisation | B22: 11 | C22: 9 | D22: 8 | E22: 16 | F22: 14 | G22: 14 | H22: 15 | I22: 22 | J22: 25 | K22: 21 | L22: 22 | M22: 23 | N22: 22 | O22: 17 | P22: =$B$86 -> 20.633971 | Q22: =$B$86 -> 20.633971 | R22: =$B$86 -> 20.633971 | S22: =$B$86 -> 20.633971 | T22: =$B$86 -> 20.633971 | U22: =$B$86 -> 20.633971 | W22: =SUM(B22:E22) -> 44 | X22: =SUM(F22:I22) -> 65 | Y22: =SUM(J22:M22) -> 91 | Z22: =SUM(N22:Q22) -> 80.267941
A23: Adjusted EBITDA | B23: 262 | C23: 819 | D23: 1834 | E23: 738 | F23: 424 | G23: 894 | H23: 1958 | I23: 765 | J23: 417 | K23: 1043 | L23: 2051 | M23: 786 | N23: 519 | O23: 1261 | P23: =P11-P20+P22+P25 -> 2232.0711 | Q23: =Q11-Q20+Q22+Q25 -> 811.60431 | R23: =R11-R20+R22+R25 -> 420.31108 | S23: =S11-S20+S22+S25 -> 1214.6999 | T23: =T11-T20+T22+T25 -> 2430.6263 | U23: =U11-U20+U22+U25 -> 829.07315 | W23: =SUM(B23:E23) -> 3653 | X23: =SUM(F23:I23) -> 4041 | Y23: =SUM(J23:M23) -> 4297 | Z23: =SUM(N23:Q23) -> 4823.6754
A24: Adjusted EBITDA margin | B24: =B23/B11 -> 0.14411441 | C24: =C23/C11 -> 0.32971014 | D24: =D23/D11 -> 0.53988814 | E24: =E23/E11 -> 0.33273219 | F24: =F23/F11 -> 0.19794585 | G24: =G23/G11 -> 0.32532751 | H24: =H23/H11 -> 0.52465166 | I24: =I23/I11 -> 0.30846774 | ... U24: =U23/U11 -> 0.25053638 | W24: =W23/W11 -> 0.36835737 | X24: =X23/X11 -> 0.36398847 | Y24: =Y23/Y11 -> 0.35103341 | Z24: =Z23/Z11 -> 0.34520455
B25: 12 | C25: -15 | D25: 3 | E25: -3 | F25: 6 | G25: 1 | H25: -2 | I25: -12 | J25: 0 | K25: -7 | L25: 1 | M25: 2 | N25: -2 | O25: 1 | P25: 0 | Q25: 0 | R25: 0 | S25: 0 | T25: 0 | U25: 0 | W25: =SUM(B25:E25) -> -3 | X25: =SUM(F25:I25) -> -7 | Y25: =SUM(J25:M25) -> -4 | Z25: =SUM(N25:Q25) -> -1
A26: Stock-based compensation | B26: 240 | C26: 304 | D26: 286 | E26: 290 | F26: 295 | G26: 382 | H26: 362 | I26: 368 | J26: 358 | K26: 424 | L26: 399 | M26: 411 | N26: 410 | O26: 487 | P26: =P145 -> 451.57919 | Q26: =Q145 -> 465.16051 | R26: =R145 -> 464.02874 | S26: =S145 -> 551.1756 | T26: =T145 -> 511.08712 | U26: =U145 -> 526.45816 | W26: =SUM(B26:E26) -> 1120 | X26: =SUM(F26:I26) -> 1407 | Y26: =SUM(J26:M26) -> 1592 | Z26: =SUM(N26:Q26) -> 1813.7397
A27: Operating income (GAAP) | B27: -5 | C27: 523 | D27: 1496 | E27: -496 | F27: 101 | G27: 497 | H27: 1525 | I27: 430 | J27: 38 | K27: 612 | L27: 1625 | M27: 269 | N27: 86 | O27: 758 | P27: =P23-P22-P26 -> 1759.8579 | Q27: =Q23-Q22-Q26 -> 325.80982 | R27: =R23-R22-R26 -> -64.351623 | S27: =S23-S22-S26 -> 642.89032 | T27: =T23-T22-T26 -> 1898.9052 | U27: =U23-U22-U26 -> 281.98102 | W27: =SUM(B27:E27) -> 1518 | X27: =SUM(F27:I27) -> 2553 | Y27: =SUM(J27:M27) -> 2544 | Z27: =SUM(N27:Q27) -> 2929.6677
A28: Interest income | B28: 146 | C28: 191 | D28: 192 | E28: 192 | F28: 202 | G28: 226 | H28: 207 | I28: 183 | J28: 173 | K28: 190 | L28: 180 | M28: 162 | N28: 155 | O28: 183 | P28: =P148 -> 183.0524 | Q28: =Q148 -> 164.08016 | R28: =R148 -> 177.95552 | S28: =S148 -> 200.34856 | T28: =T148 -> 188.94413 | U28: =U148 -> 168.90058 | W28: =SUM(B28:E28) -> 721 | X28: =SUM(F28:I28) -> 818 | Y28: =SUM(J28:M28) -> 705 | Z28: =SUM(N28:Q28) -> 685.13256
A29: Interest expense | B29: 4 | C29: 2 | D29: 6 | E29: 71 | F29: 0 | G29: 9 | H29: 2 | I29: 10 | J29: 5 | K29: 6 | L29: 6 | M29: 26 | N29: 21 | O29: 37 | P29: =$B$92 -> 37 | Q29: =$B$92 -> 37 | R29: =$B$92 -> 37 | S29: =$B$92 -> 37 | T29: =$B$92 -> 37 | U29: =$B$92 -> 37 | W29: =SUM(B29:E29) -> 83 | X29: =SUM(F29:I29) -> 21 | Y29: =SUM(J29:M29) -> 43 | Z29: =SUM(N29:Q29) -> 132
A30: Other income / (expense), net | B30: -7 | C30: -36 | D30: -3 | E30: -8 | F30: -10 | G30: -33 | H30: 5 | I30: 19 | J30: -33 | K30: -17 | L30: -7 | M30: -12 | N30: 61 | O30: -7 | P30: =$B$93 -> 3.7 | Q30: =$B$93 -> 3.7 | R30: =$B$93 -> 3.7 | S30: =$B$93 -> 3.7 | T30: =$B$93 -> 3.7 | U30: =$B$93 -> 3.7 | W30: =SUM(B30:E30) -> -54 | X30: =SUM(F30:I30) -> -19 | Y30: =SUM(J30:M30) -> -69 | Z30: =SUM(N30:Q30) -> 61.4
A31: Pre-tax income | B31: 130 | C31: 676 | D31: 1679 | E31: -383 | F31: 293 | G31: 681 | H31: 1735 | I31: 622 | J31: 173 | K31: 779 | L31: 1792 | M31: 393 | N31: 281 | O31: 897 | P31: =P27+P28-P29+P30 -> 1909.6103 | Q31: =Q27+Q28-Q29+Q30 -> 456.58998 | R31: =R27+R28-R29+R30 -> 80.303901 | S31: =S27+S28-S29+S30 -> 809.93888 | T31: =T27+T28-T29+T30 -> 2054.5493 | U31: =U27+U28-U29+U30 -> 417.5816 | W31: =SUM(B31:E31) -> 2102 | X31: =SUM(F31:I31) -> 3331 | Y31: =SUM(J31:M31) -> 3137 | Z31: =SUM(N31:Q31) -> 3544.2003
A32: Income tax | B32: 13.4 | C32: 26 | D32: -2695 | E32: -34 | F32: 29 | G32: 126 | H32: 367 | I32: 161 | J32: 19 | K32: 137 | L32: 418 | M32: 52 | N32: 121 | O32: 81 | P32: =P31*$B$94/100 -> 343.72986 | Q32: =Q31*$B$94/100 -> 82.186197 | R32: =R31*$B$95/100 -> 14.053183 | S32: =S31*$B$95/100 -> 141.7393 | T32: =T31*$B$95/100 -> 359.54613 | U32: =U31*$B$95/100 -> 73.07678 | W32: =SUM(B32:E32) -> -2689.6 | X32: =SUM(F32:I32) -> 683 | Y32: =SUM(J32:M32) -> 626 | Z32: =SUM(N32:Q32) -> 627.91606
A33: Net income | B33: 117 | C33: 650 | D33: 4374 | E33: -349 | F33: 264 | G33: 555 | H33: 1368 | I33: 461 | J33: 154 | K33: 642 | L33: 1374 | M33: 341 | N33: 160 | O33: 816 | P33: =P31-P32 -> 1565.8805 | Q33: =Q31-Q32 -> 374.40379 | R33: =R31-R32 -> 66.250718 | S33: =S31-S32 -> 668.19958 | T33: =T31-T32 -> 1695.0032 | U33: =U31-U32 -> 344.50482 | W33: =SUM(B33:E33) -> 4792 | X33: =SUM(F33:I33) -> 2648 | Y33: =SUM(J33:M33) -> 2511 | Z33: =SUM(N33:Q33) -> 2916.2843
A34: Diluted shares (m) | B34: 670 | C34: 665 | D34: 660 | E34: 640 | F34: 654 | G34: 649 | H34: 642 | I34: 636 | J34: 632 | K34: 626 | L34: 621 | M34: 614 | N34: 608 | O34: 597 | P34: =P149 -> 591.67581 | Q34: =Q149 -> 586.35163 | R34: =R149 -> 581.02744 | S34: =S149 -> 575.70325 | T34: =T149 -> 570.37907 | U34: =U149 -> 565.05488 | W34: 662 | X34: 645 | Y34: 623 | Z34: =AVERAGE(N34:Q34) -> 595.75686
A35: Diluted EPS ($) | B35: 0.18 | C35: 0.98 | D35: 6.63 | E35: -0.55 | F35: 0.41 | G35: 0.86 | H35: 2.13 | I35: 0.73 | J35: 0.24 | K35: 1.03 | L35: 2.21 | M35: 0.56 | N35: 0.26 | O35: 1.37 | P35: =P33/P34 -> 2.6465176 | Q35: =Q33/Q34 -> 0.63853116 | R35: =R33/R34 -> 0.11402339 | S35: =S33/S34 -> 1.1606667 | T35: =T33/T34 -> 2.9717135 | U35: =U33/U34 -> 0.60968383 | W35: 7.24 | X35: 4.11 | Y35: 4.03 | Z35: =Z33/Z34 -> 4.8950914
A37: Cross-checks against the Street, and the open choices this line does not settle (memo rows - none of these feed the statement above)
A38: Street revenue ($m) | P38: 4744.32 | Q38: 3161.82 | R38: 3010.32 | S38: 4036.94 | T38: 5269.9673 | U38: 3528.9194
A39: ours vs Street | P39: =P11/P38-1 -> -0.028593444 | Q39: =Q11/Q38-1 -> -0.026282507 | R39: =R11/R38-1 -> -0.035874604 | S39: =S11/S38-1 -> -0.043864989 | T39: =T11/T38-1 -> -0.060512028 | U39: =U11/U38-1 -> -0.062264599
A40: Street adj. EBITDA ($m) | P40: 2361.52 | Q40: 913.68 | R40: 610.73 | S40: 1451.71 | T40: 2695.5528 | U40: 1068.3961
A41: ours vs Street | P41: =P23/P40-1 -> -0.05481593 | Q41: =Q23/Q40-1 -> -0.11171931 | R41: =R23/R40-1 -> -0.31178903 | S41: =S23/S40-1 -> -0.16326271 | T41: =T23/T40-1 -> -0.098282816 | U41: =U23/U40-1 -> -0.22400206
A42: memo: adj. EBITDA if costs flexed to hold the line build's own margin | P42: =P11*0.503668738501203 -> 2321.2398 | Q42: =Q11*0.282832332284408 -> 870.7614 | R42: =R11*0.182124867688651 -> 528.58573 | S42: =S11*0.340987932196394 -> 1316.1656 | T42: =T11*0.519629645378934 -> 2572.7232 | U42: =U11*0.279965538169394 -> 926.45989
A43: difference vs the statement above | P43: =P42-P23 -> 89.168672 | Q43: =Q42-Q23 -> 59.157096 | R43: =R42-R23 -> 108.27465 | S43: =S42-S23 -> 101.46568 | T43: =T42-T23 -> 142.09695 | U43: =U42-U23 -> 97.386737
...

Sheet Nights_Engine
A1: Airbnb — nights engine (reviews_index_v2, v2.1 stay-quarter mix). Blue = input with source; black = formula; green = link.
A3: Quarter | B3: 1Q21A | C3: 2Q21A | D3: 3Q21A | E3: 4Q21A | F3: 1Q22A | G3: 2Q22A | H3: 3Q22A | I3: 4Q22A | J3: 1Q23A | K3: 2Q23A | L3: 3Q23A | M3: 4Q23A | N3: 1Q24A | O3: 2Q24A | P3: 3Q24A | Q3: 4Q24A | R3: 1Q25A | S3: 2Q25A | T3: 3Q25A | U3: 4Q25A | V3: 1Q26A | W3: 2Q26A | X3: 3Q26E | Y3: 4Q26E | Z3: 1Q27E | AA3: 2Q27E | AB3: 3Q27E | AC3: 4Q27E
A5: A. Printed nights (the KPI, booking-dated)
A6: Nights & seats booked (m) | B6: 64.4 | C6: 83.1 | D6: 79.7 | E6: 73.4 | F6: 102.1 | G6: 103.7 | H6: 99.7 | I6: 88.2 | J6: 121.1 | K6: 115.1 | L6: 113.2 | M6: 98.8 | N6: 132.6 | O6: 125.1 | P6: 122.8 | Q6: 111 | R6: 143.1 | S6: 134.4 | T6: 133.6 | U6: 121.9 | V6: 156.2 | W6: 148.3
A7: y/y | F7: =F6/B6-1 -> 0.58540373 | G7: =G6/C6-1 -> 0.2478941 | H7: =H6/D6-1 -> 0.25094103 | I7: =I6/E6-1 -> 0.20163488 | J7: =J6/F6-1 -> 0.18609207 | K7: =K6/G6-1 -> 0.1099325 | L7: =L6/H6-1 -> 0.13540622 | M7: =M6/I6-1 -> 0.12018141 | ... W7: =W6/S6-1 -> 0.10342262
A9: B. Stays index — regional stays growth (same-age two-vintage review counts) × stay-quarter mix weights
A10: Stays y/y, NAM (%) | B10: -30.009186 | C10: 256.22579 | D10: 84.267421 | E10: 86.208477 | F10: 67.324547 | G10: 46.571018 | H10: 22.732978 | I10: 11.322568 | J10: 9.7224684 | K10: 3.9560507 | L10: 4.3760435 | M10: 1.61386 | N10: 1.4023741 | O10: 0.11141141 | P10: 2.569901 | Q10: 2.7347428 | R10: -2.6372923 | S10: -0.91095634 | T10: -0.38243552 | U10: 0.059808764 | V10: 5.4096747 | W10: 6.8959656
A11: Stays y/y, EMEA (%) | B11: -74.978465 | C11: 408.42535 | D11: 76.402152 | E11: 266.06162 | F11: 324.38397 | G11: 256.4864 | H11: 55.237057 | I11: 34.48634 | J11: 36.693192 | K11: 23.201082 | L11: 11.821018 | M11: 14.612667 | N11: 9.2353198 | O11: 8.8281243 | P11: 5.5260003 | Q11: 6.7601096 | R11: 4.2529156 | S11: 2.9855344 | T11: 2.1806637 | U11: 5.5190956 | V11: 4.7307413 | W11: 1.4823409
A12: Stays y/y, LatAm (%) | B12: -50.559682 | C12: 384.87718 | D12: 131.73399 | E12: 101.51506 | F12: 128.20255 | G12: 134.69878 | H12: 102.44056 | I12: 67.420907 | J12: 50.234582 | K12: 35.123094 | L12: 33.380883 | M12: 38.083971 | N12: 24.186325 | O12: 16.542043 | P12: 24.111263 | Q12: 13.35591 | R12: 27.15945 | S12: 34.005572 | T12: 18.44378 | U12: 24.824748 | V12: 18.22158 | W12: 20.395825
A13: Stays y/y, APAC (%) | B13: -24.215632 | C13: 231.83258 | D13: -3.9807107 | E13: -2.6257212 | F13: 12.215553 | G13: 16.689583 | H13: 95.7677 | I13: 74.884346 | J13: 53.345968 | K13: 18.132796 | L13: 14.799396 | M13: 16.516761 | N13: 21.770867 | O13: 4.8761296 | P13: 2.0800717 | Q13: 8.6573671 | R13: -0.82253826 | S13: 4.7150993 | T13: 4.9485043 | U13: 6.2442451 | V13: 8.8637261 | W13: 2.3029909
A14: Stay-mix weight, NAM | F14: 0.39766449 | G14: 0.39419766 | H14: 0.34525404 | I14: 0.36554987 | J14: 0.36026345 | K14: 0.35450833 | L14: 0.32168886 | M14: 0.33132229 | N14: 0.32794356 | O14: 0.35097958 | P14: 0.30945651 | Q14: 0.31131842 | R14: 0.31811106 | S14: 0.32187024 | T14: 0.28670938 | U14: 0.28052526 | V14: 0.28475207 | W14: 0.31848284 | X14: 0.26492132 | Y14: 0.25327854 | Z14: 0.25205453 | AA14: 0.28037536 | AB14: 0.22127536 | AC14: 0.20414601
A15: Stay-mix weight, EMEA | F15: 0.26416206 | G15: 0.38471524 | H15: 0.48141011 | I15: 0.30864625 | J15: 0.26113228 | K15: 0.409691 | L15: 0.48845027 | M15: 0.31761694 | N15: 0.26818392 | O15: 0.41167264 | P15: 0.49739852 | Q15: 0.32570758 | R15: 0.26377225 | S15: 0.42191656 | T15: 0.51045491 | U15: 0.33326286 | V15: 0.27362882 | W15: 0.41680142 | X15: 0.5148668 | Y15: 0.33860146 | Z15: 0.27996478 | AA15: 0.42439557 | AB15: 0.52370473 | AC15: 0.34822828
A16: Stay-mix weight, LatAm | F16: 0.17982266 | G16: 0.10270976 | H16: 0.075576971 | I16: 0.14966176 | J16: 0.19112864 | K16: 0.10123186 | L16: 0.080902329 | M16: 0.16451195 | N16: 0.20713375 | O16: 0.10366336 | P16: 0.081804952 | Q16: 0.16267281 | R16: 0.21617811 | S16: 0.11275565 | T16: 0.086904517 | U16: 0.17942126 | V16: 0.23565714 | W16: 0.12141438 | X16: 0.10018467 | Y16: 0.19611738 | Z16: 0.25576405 | AA16: 0.14471699 | AB16: 0.12678753 | AC16: 0.22622459
A17: Stay-mix weight, APAC | F17: 0.15835079 | G17: 0.11837735 | H17: 0.097758872 | I17: 0.17614213 | J17: 0.18747562 | K17: 0.1345688 | L17: 0.10895854 | M17: 0.18654882 | N17: 0.19673876 | O17: 0.13368442 | P17: 0.11134002 | Q17: 0.20030119 | R17: 0.20193858 | S17: 0.14345755 | T17: 0.11593119 | U17: 0.20679061 | V17: 0.20596198 | W17: 0.14330136 | X17: 0.12002721 | Y17: 0.21200261 | Z17: 0.21221664 | AA17: 0.15051208 | AB17: 0.12823238 | AC17: 0.22140113
A18: Global stays index, y/y (%) | F18: =SUMPRODUCT(F10:F13,F14:F17) -> 137.45058 | G18: =SUMPRODUCT(G10:G13,G14:G17) -> 132.84296 | H18: =SUMPRODUCT(H10:H13,H14:H17) -> 51.54462 | I18: =SUMPRODUCT(I10:I13,I14:I17) -> 38.063662 | J18: =SUMPRODUCT(J10:J13,J14:J17) -> 32.686763 | K18: =SUMPRODUCT(K10:K13,K14:K17) -> 16.903412 | L18: =SUMPRODUCT(L10:L13,L14:L17) -> 11.494816 | M18: =SUMPRODUCT(M10:M13,M14:M17) -> 14.522389 | ... W18: =SUMPRODUCT(W10:W13,W14:W17) -> 5.6204567
W19: *
A20: C. Mapping to the KPI — nights y/y = a + b × index, fitted 1Q23–2Q25 and frozen; scored walk-forward
A21: Intercept a (frozen, 1Q23–2Q25) | B21: =INTERCEPT(J7:S7,J18:S18)*100 -> 6.8246002 | C21: pp
A22: Slope b (frozen, 1Q23–2Q25) | B22: =SLOPE(J7:S7,J18:S18)*100 -> 0.34969 | C22: pp of nights per index point
A24: Stays-implied nights y/y (%) | J24: =$B$21+$B$22*J18 -> 18.254834 | K24: =$B$21+$B$22*K18 -> 12.735555 | L24: =$B$21+$B$22*L18 -> 10.844222 | M24: =$B$21+$B$22*M18 -> 11.902934 | N24: =$B$21+$B$22*N18 -> 11.101184 | O24: =$B$21+$B$22*O18 -> 8.9367511 | P24: =$B$21+$B$22*P18 -> 8.8345879 | Q24: =$B$21+$B$22*Q18 -> 9.2584143 | ... W24: =$B$21+$B$22*W18 -> 8.7900177
A25: Gap: printed − stays-implied (pp) | J25: =J7*100-J24 -> 0.35437224 | K25: =K7*100-K24 -> -1.7423048 | L25: =L7*100-L24 -> 2.6963996 | M25: =M7*100-M24 -> 0.11520611 | N25: =N7*100-N24 -> -1.6048994 | O25: =O7*100-O24 -> -0.24865384 | P25: =P7*100-P24 -> -0.35402249 | Q25: =Q7*100-Q24 -> 3.0897638 | ... W25: =W7*100-W24 -> 1.5522442
A27: C1. Walk-forward W1 — window 1Q22+, scored 1Q23–2Q26
A28: prediction (refit on quarters before t) | J28: =(INTERCEPT(F7:I7,F18:I18)+SLOPE(F7:I7,F18:I18)*J18)*100 -> 19.454303 | K28: =(INTERCEPT(F7:J7,F18:J18)+SLOPE(F7:J7,F18:J18)*K18)*100 -> 15.569258 | L28: =(INTERCEPT(F7:K7,F18:K18)+SLOPE(F7:K7,F18:K18)*L18)*100 -> 12.640135 | M28: =(INTERCEPT(F7:L7,F18:L18)+SLOPE(F7:L7,F18:L18)*M18)*100 -> 13.619791 | N28: =(INTERCEPT(F7:M7,F18:M18)+SLOPE(F7:M7,F18:M18)*N18)*100 -> 12.726287 | O28: =(INTERCEPT(F7:N7,F18:N18)+SLOPE(F7:N7,F18:N18)*O18)*100 -> 10.603466 | P28: =(INTERCEPT(F7:O7,F18:O18)+SLOPE(F7:O7,F18:O18)*P18)*100 -> 10.203171 | Q28: =(INTERCEPT(F7:P7,F18:P18)+SLOPE(F7:P7,F18:P18)*Q18)*100 -> 10.259625 | R28: =(INTERCEPT(F7:Q7,F18:Q18)+SLOPE(F7:Q7,F18:Q18)*R18)*100 -> 10.275645 | S28: =(INTERCEPT(F7:R7,F18:R18)+SLOPE(F7:R7,F18:R18)*S18)*100 -> 9.8788874 | T28: =(INTERCEPT(F7:S7,F18:S18)+SLOPE(F7:S7,F18:S18)*T18)*100 -> 9.0365752 | U28: =(INTERCEPT(F7:T7,F18:T18)+SLOPE(F7:T7,F18:T18)*U18)*100 -> 10.15263 | V28: =(INTERCEPT(F7:U7,F18:U18)+SLOPE(F7:U7,F18:U18)*V18)*100 -> 10.47465 | W28: =(INTERCEPT(F7:V7,F18:V18)+SLOPE(F7:V7,F18:V18)*W18)*100 -> 9.514287
A29: error: prediction − printed (pp) | J29: =J28-J7*100 -> 0.84509657 | K29: =K28-K7*100 -> 4.576008 | L29: =L28-L7*100 -> -0.90048698 | M29: =M28-M7*100 -> 1.6016503 | N29: =N28-N7*100 -> 3.2300026 | O29: =O28-O7*100 -> 1.9153685 | P29: =P28-P7*100 -> 1.7226053 | Q29: =Q28-Q7*100 -> -2.0885532 | ... W29: =W28-W7*100 -> -0.82797486
A30: naive error: last quarter's y/y − printed (pp) | J30: =(I7-J7)*100 -> 1.5542811 | K30: =(J7-K7)*100 -> 7.6159569 | L30: =(K7-L7)*100 -> -2.5473721 | M30: =(L7-M7)*100 -> 1.5224813 | N30: =(M7-N7)*100 -> 2.5218565 | O30: =(N7-O7)*100 -> 0.80818676 | P30: =(O7-P7)*100 -> 0.20753194 | Q30: =(P7-Q7)*100 -> -3.8676128 | ... W30: =(V7-W7)*100 -> -1.1878244
A31: RMSE engine / RMSE naive | B31: =SQRT(SUMSQ(J29:W29)/COUNT(J29:W29)) -> 2.0803847 | C31: =SQRT(SUMSQ(J30:W30)/COUNT(J30:W30)) -> 2.8766591 | D31: =B31/C31 -> 0.72319473 | E31: ratio (pass line ≤ 0.75)
A32: mean error (pp) | B32: =AVERAGE(J29:W29) -> 1.1978896
A33: C2. Walk-forward W2 — window 1Q23+, scored 1Q24–2Q26
A34: prediction (refit on quarters before t) | N34: =(INTERCEPT(J7:M7,J18:M18)+SLOPE(J7:M7,J18:M18)*N18)*100 -> 11.758526 | O34: =(INTERCEPT(J7:N7,J18:N18)+SLOPE(J7:N7,J18:N18)*O18)*100 -> 8.9628958 | P34: =(INTERCEPT(J7:O7,J18:O18)+SLOPE(J7:O7,J18:O18)*P18)*100 -> 8.753463 | Q34: =(INTERCEPT(J7:P7,J18:P18)+SLOPE(J7:P7,J18:P18)*Q18)*100 -> 9.1056806 | R34: =(INTERCEPT(J7:Q7,J18:Q18)+SLOPE(J7:Q7,J18:Q18)*R18)*100 -> 9.4435499 | S34: =(INTERCEPT(J7:R7,J18:R18)+SLOPE(J7:R7,J18:R18)*S18)*100 -> 8.9939625 | T34: =(INTERCEPT(J7:S7,J18:S18)+SLOPE(J7:S7,J18:S18)*T18)*100 -> 7.9366202 | U34: =(INTERCEPT(J7:T7,J18:T18)+SLOPE(J7:T7,J18:T18)*U18)*100 -> 9.5934136 | V34: =(INTERCEPT(J7:U7,J18:U18)+SLOPE(J7:U7,J18:U18)*V18)*100 -> 10.07429 | W34: =(INTERCEPT(J7:V7,J18:V18)+SLOPE(J7:V7,J18:V18)*W18)*100 -> 8.8623061
A35: error: prediction − printed (pp) | N35: =N34-N7*100 -> 2.2622421 | O35: =O34-O7*100 -> 0.2747985 | P35: =P34-P7*100 -> 0.27289762 | Q35: =Q34-Q7*100 -> -3.2424975 | R35: =R34-R7*100 -> 1.5249979 | S35: =S34-S7*100 -> 1.5599098 | T35: =T34-T7*100 -> -0.8581681 | U35: =U34-U7*100 -> -0.22640621 | ... W35: =W34-W7*100 -> -1.4799558
A36: naive error: last quarter's y/y − printed (pp) | N36: =(M7-N7)*100 -> 2.5218565 | O36: =(N7-O7)*100 -> 0.80818676 | P36: =(O7-P7)*100 -> 0.20753194 | Q36: =(P7-Q7)*100 -> -3.8676128 | R36: =(Q7-R7)*100 -> 4.4296261 | S36: =(R7-S7)*100 -> 0.48449928 | T36: =(S7-T7)*100 -> -1.3607355 | U36: =(T7-U7)*100 -> -1.0250315 | ... W36: =(V7-W7)*100 -> -1.1878244
A37: RMSE engine / RMSE naive | B37: =SQRT(SUMSQ(N35:W35)/COUNT(N35:W35)) -> 1.5609152 | C37: =SQRT(SUMSQ(N36:W36)/COUNT(N36:W36)) -> 2.1593217 | D37: =B37/C37 -> 0.72287293 | E37: ratio (pass line ≤ 0.75)
A38: mean error (pp) | B38: =AVERAGE(N35:W35) -> 0.10076703
A39: C3. Band — W2 walk-forward on the pre-RNPL quarters only, scored 1Q24–2Q25
A40: prediction (refit on quarters before t) | N40: =(INTERCEPT(J7:M7,J18:M18)+SLOPE(J7:M7,J18:M18)*N18)*100 -> 11.758526 | O40: =(INTERCEPT(J7:N7,J18:N18)+SLOPE(J7:N7,J18:N18)*O18)*100 -> 8.9628958 | P40: =(INTERCEPT(J7:O7,J18:O18)+SLOPE(J7:O7,J18:O18)*P18)*100 -> 8.753463 | Q40: =(INTERCEPT(J7:P7,J18:P18)+SLOPE(J7:P7,J18:P18)*Q18)*100 -> 9.1056806 | R40: =(INTERCEPT(J7:Q7,J18:Q18)+SLOPE(J7:Q7,J18:Q18)*R18)*100 -> 9.4435499 | S40: =(INTERCEPT(J7:R7,J18:R18)+SLOPE(J7:R7,J18:R18)*S18)*100 -> 8.9939625
A41: error: prediction − printed (pp) | N41: =N40-N7*100 -> 2.2622421 | O41: =O40-O7*100 -> 0.2747985 | P41: =P40-P7*100 -> 0.27289762 | Q41: =Q40-Q7*100 -> -3.2424975 | R41: =R40-R7*100 -> 1.5249979 | S41: =S40-S7*100 -> 1.5599098
A42: naive error: last quarter's y/y − printed (pp) | N42: =(M7-N7)*100 -> 2.5218565 | O42: =(N7-O7)*100 -> 0.80818676 | P42: =(O7-P7)*100 -> 0.20753194 | Q42: =(P7-Q7)*100 -> -3.8676128 | R42: =(Q7-R7)*100 -> 4.4296261 | S42: =(R7-S7)*100 -> 0.48449928
A43: RMSE engine / RMSE naive | B43: =SQRT(SUMSQ(N41:S41)/COUNT(N41:S41)) -> 1.8502457 | C43: =SQRT(SUMSQ(N42:S42)/COUNT(N42:S42)) -> 2.6416772 | D43: =B43/C43 -> 0.70040565 | E43: ratio (pass line ≤ 0.75) | F43: ← the RMSE in the first cell of this row is the band (±pp) on every read
A44: mean error (pp) | B44: =AVERAGE(N41:S41) -> 0.44205806
A46: D. The 3Q26 read — quarter-to-date, day-matched, same-age two vintages, through the frozen mapping
...

Sheet ADR_Engine
A1: Airbnb — ADR engine (line 2). reported ADR y/y = ex-FX mechanism + FX translation identity (ex ante, spot held). Blue = input with source; black = formula; green = link.
A3: Quarter | B3: A = printed, E = engine | C3: 1Q21A | D3: 2Q21A | E3: 3Q21A | F3: 4Q21A | G3: 1Q22A | H3: 2Q22A | I3: 3Q22A | J3: 4Q22A | K3: 1Q23A | L3: 2Q23A | M3: 3Q23A | N3: 4Q23A | O3: 1Q24A | P3: 2Q24A | Q3: 3Q24A | R3: 4Q24A | S3: 1Q25A | T3: 2Q25A | U3: 3Q25A | V3: 4Q25A | W3: 1Q26A | X3: 2Q26A | Y3: 3Q26E | Z3: 4Q26E | AA3: 1Q27E | AB3: 2Q27E | AC3: 3Q27E | AD3: 4Q27E
A5: A. Printed ADR and the disclosed identity: reported y/y − ex-FX y/y = FX effect (closes to ≤0.04pp)
A6: ADR ($, GBV ÷ nights, printed; forward = engine path) | B6: data/processed/overnight/02_kpi_panel_quarterly.csv adr_usd (letters / 10-Q) | C6: 159.82 | D6: 161.45 | E6: 149.15 | F6: 153.61 | G6: 168.07 | H6: 163.74 | I6: 156.44 | J6: 152.81 | K6: 168.43 | L6: 166.01 | M6: 161.38 | N6: 156.73 | O6: 172.88 | P6: 169.53 | Q6: 163.64 | R6: 158.13 | S6: 171.34 | T6: 174.48 | U6: 171.29 | V6: 167.51 | W6: 186.82 | X6: 183.73 | Y6: =Y95 -> 175.66234 | Z6: =Z95 -> 170.95632 | AA6: =AA95 -> 187.90967 | AB6: =AB95 -> 185.59486 | AC6: =AC95 -> 177.87547 | AD6: =AD95 -> 173.46913
A7: reported y/y | B7: → ADR / ADR four quarters earlier − 1 | G7: =G6/C6-1 -> 0.051620573 | H7: =H6/D6-1 -> 0.014183958 | I7: =I6/E6-1 -> 0.048876969 | J7: =J6/F6-1 -> -0.0052079943 | K7: =K6/G6-1 -> 0.0021419647 | L7: =L6/H6-1 -> 0.013863442 | M7: =M6/I6-1 -> 0.031577602 | N7: =N6/J6-1 -> 0.025652771 | ... AD7: =AD6/Z6-1 -> 0.014698595
A8: ex-FX y/y, as stated in the letter (whole points; 3Q23/4Q23 'less than 1%' → 0.5) | B8: 02_kpi_panel_quarterly.csv adr_yoy_exfx_pct; 2Q22 onward | H8: 7 | I8: 12 | J8: 5 | K8: 3 | L8: 2 | M8: 0.5 | N8: 0.5 | O8: 2 | P8: 3 | Q8: 2 | R8: 2 | S8: 1 | T8: 1 | U8: 2 | V8: 3 | W8: 4 | X8: 4
A9: FX effect on ADR (pp) — the disclosed target | B9: → reported y/y × 100 − ex-FX y/y | H9: =H7*100-H8 -> -5.5816042 | I9: =I7*100-I8 -> -7.1123031 | J9: =J7*100-J8 -> -5.5207994 | K9: =K7*100-K8 -> -2.7858035 | L9: =L7*100-L8 -> -0.6136558 | M9: =M7*100-M8 -> 2.6577602 | N9: =N7*100-N8 -> 2.0652771 | O9: =O7*100-O8 -> 0.64204714 | ... X9: =X7*100-X8 -> 1.3014672
A11: B. FX translation identity (ex ante): FX pp = Σ_region GBV share × Σ_currency κ × (avg rate / avg rate a year earlier − 1) — zero fitted parameters
A12: Quarterly average USD per EUR (business days; forward = spot held from 2026-09-18) | B12: FRED DEXUSEU → adr_engine/fx_daily_2026-09-21.csv (fetch_fx.py) | C12: 1.2051578 | D12: 1.2052631 | E12: 1.1786621 | F12: 1.1432652 | G12: 1.1220844 | H12: 1.0644092 | I12: 1.0070318 | J12: 1.0219185 | K12: 1.0729677 | L12: 1.0886154 | M12: 1.0883215 | N12: 1.0763308 | O12: 1.0858477 | P12: 1.07668 | Q12: 1.0985045 | R12: 1.0666939 | S12: 1.0523953 | T12: 1.1344462 | U12: 1.1686682 | V12: 1.1640894 | W12: 1.1703063 | X12: 1.1628877 | Y12: 1.1515591 | Z12: 1.1464 | AA12: 1.1464 | AB12: 1.1464 | AC12: 1.1464 | AD12: 1.1464
A13: Quarterly average USD per GBP (business days; forward = spot held from 2026-09-18) | B13: FRED DEXUSUK → adr_engine/fx_daily_2026-09-21.csv (fetch_fx.py) | C13: 1.3790891 | D13: 1.3984477 | E13: 1.3780667 | F13: 1.3484455 | G13: 1.3413922 | H13: 1.2559246 | I13: 1.176797 | J13: 1.1751738 | K13: 1.2150692 | L13: 1.2521308 | M13: 1.2662 | N13: 1.2419846 | O13: 1.2682554 | P13: 1.2621554 | Q13: 1.3003091 | R13: 1.2814455 | S13: 1.2597047 | T13: 1.3357262 | U13: 1.3486742 | V13: 1.3304591 | W13: 1.3478812 | X13: 1.34264 | Y13: 1.3456939 | Z13: 1.3372 | AA13: 1.3372 | AB13: 1.3372 | AC13: 1.3372 | AD13: 1.3372
A14: Quarterly average USD per BRL (business days; forward = spot held from 2026-09-18) | B14: FRED DEXBZUS → adr_engine/fx_daily_2026-09-21.csv (fetch_fx.py) | C14: 0.1828723 | D14: 0.1892938 | E14: 0.19140422 | F14: 0.17901789 | G14: 0.19180331 | H14: 0.20348532 | I14: 0.19074296 | J14: 0.19031259 | K14: 0.19255919 | L14: 0.20206913 | M14: 0.20494515 | N14: 0.20197053 | O14: 0.20203222 | P14: 0.19200767 | Q14: 0.18034804 | R14: 0.17142182 | S14: 0.1709568 | T14: 0.17648985 | U14: 0.18360546 | V14: 0.18528564 | W14: 0.19021328 | X14: 0.19812416 | Y14: 0.19477107 | Z14: 0.19381347 | AA14: 0.19381347 | AB14: 0.19381347 | AC14: 0.19381347 | AD14: 0.19381347
A15: Quarterly average USD per MXN (business days; forward = spot held from 2026-09-18) | B15: FRED DEXMXUS → adr_engine/fx_daily_2026-09-21.csv (fetch_fx.py) | C15: 0.049188327 | D15: 0.049977378 | E15: 0.049941177 | F15: 0.048211633 | G15: 0.048790826 | H15: 0.049882551 | I15: 0.049438854 | J15: 0.050840307 | K15: 0.053601005 | L15: 0.056587911 | M15: 0.058640683 | N15: 0.057045653 | O15: 0.058894717 | P15: 0.05812609 | Q15: 0.052918776 | R15: 0.049783664 | S15: 0.048979898 | T15: 0.051289124 | U15: 0.053691549 | V15: 0.054659442 | W15: 0.056955797 | X15: 0.057533585 | Y15: 0.058112133 | Z15: 0.057986478 | AA15: 0.057986478 | AB15: 0.057986478 | AC15: 0.057986478 | AD15: 0.057986478
A16: Quarterly average USD per JPY (business days; forward = spot held from 2026-09-18) | B16: FRED DEXJPUS → adr_engine/fx_daily_2026-09-21.csv (fetch_fx.py) | C16: 0.0094349051 | D16: 0.0091381254 | E16: 0.0090842013 | F16: 0.0087968935 | G16: 0.0086023215 | H16: 0.007712152 | I16: 0.0072346139 | J16: 0.007089682 | K16: 0.0075563288 | L16: 0.0072794962 | M16: 0.0069207958 | N16: 0.0067688001 | O16: 0.0067398721 | P16: 0.0064187659 | Q16: 0.0067138749 | R16: 0.006564705 | S16: 0.0065592852 | T16: 0.0069232239 | U16: 0.0067818577 | V16: 0.0064909558 | W16: 0.0063765536 | X16: 0.0062743757 | Y16: 0.0062864113 | Z16: 0.0063747052 | AA16: 0.0063747052 | AB16: 0.0063747052 | AC16: 0.0063747052 | AD16: 0.0063747052
A17: Quarterly average USD per AUD (business days; forward = spot held from 2026-09-18) | B17: FRED DEXUSAL → adr_engine/fx_daily_2026-09-21.csv (fetch_fx.py) | C17: 0.77284219 | D17: 0.77006615 | E17: 0.73476667 | F17: 0.72878939 | G17: 0.72470469 | H17: 0.71404769 | I17: 0.68325606 | J17: 0.65758769 | K17: 0.68345538 | L17: 0.6681 | M17: 0.65481231 | N17: 0.65147231 | O17: 0.65780462 | P17: 0.65907231 | Q17: 0.66993485 | R17: 0.65226515 | S17: 0.62754219 | T17: 0.64107231 | U17: 0.6543197 | V17: 0.65672576 | W17: 0.69493594 | X17: 0.70997385 | Y17: 0.7071303 | Z17: 0.7111 | AA17: 0.7111 | AB17: 0.7111 | AC17: 0.7111 | AD17: 0.7111
A18: Quarterly average USD per KRW (business days; forward = spot held from 2026-09-18) | B18: FRED DEXKOUS → adr_engine/fx_daily_2026-09-21.csv (fetch_fx.py) | C18: 0.00089805741 | D18: 0.00089194501 | E18: 0.00086250124 | F18: 0.00084489755 | G18: 0.00082949308 | H18: 0.00079350424 | I18: 0.00074657344 | J18: 0.00073713865 | K18: 0.00078425692 | L18: 0.00076050865 | M18: 0.00076178375 | N18: 0.00075699545 | O18: 0.00075258659 | P18: 0.00072983185 | Q18: 0.00073789966 | R18: 0.00071545038 | S18: 0.00068861141 | T18: 0.00071531199 | U18: 0.00072120431 | V18: 0.00069039611 | W18: 0.00068276249 | X18: 0.00066626241 | Y18: 0.00070476994 | Z18: 0.00072047667 | AA18: 0.00072047667 | AB18: 0.00072047667 | AC18: 0.00072047667 | AD18: 0.00072047667
A19: Quarterly average USD per CAD (business days; forward = spot held from 2026-09-18) | B19: FRED DEXCAUS → adr_engine/fx_daily_2026-09-21.csv (fetch_fx.py) | C19: 0.78993696 | D19: 0.8144081 | E19: 0.79401148 | F19: 0.79344988 | G19: 0.78974132 | H19: 0.78333727 | I19: 0.76598682 | J19: 0.73679988 | K19: 0.73938089 | L19: 0.74472729 | M19: 0.7457969 | N19: 0.73473312 | O19: 0.74185751 | P19: 0.73094942 | Q19: 0.73325029 | R19: 0.71493814 | S19: 0.69696586 | T19: 0.72265336 | U19: 0.72630067 | V19: 0.71747374 | W19: 0.72912713 | X19: 0.72266251 | Y19: 0.71533732 | Z19: 0.71387778 | AA19: 0.71387778 | AB19: 0.71387778 | AC19: 0.71387778 | AD19: 0.71387778
A20: Quarterly average USD per INR (business days; forward = spot held from 2026-09-18) | B20: FRED DEXINUS → adr_engine/fx_daily_2026-09-21.csv (fetch_fx.py) | C20: 0.013716405 | D20: 0.013558294 | E20: 0.013498359 | F20: 0.013348796 | G20: 0.013297218 | H20: 0.012954458 | I20: 0.012537862 | J20: 0.012175212 | K20: 0.012165732 | L20: 0.012169914 | M20: 0.012095919 | N20: 0.012012913 | O20: 0.012044004 | P20: 0.011989327 | Q20: 0.011940174 | R20: 0.01184369 | S20: 0.011549405 | T20: 0.011686775 | U20: 0.011453966 | V20: 0.01122424 | W20: 0.010931728 | X20: 0.010567997 | Y20: 0.010461347 | Z20: 0.010430792 | AA20: 0.010430792 | AB20: 0.010430792 | AC20: 0.010430792 | AD20: 0.010430792
A21: share of the quarter's business days printed at 18 Sep 2026 | B21: engine fx_forecast_asof.csv obs_frac_at_asof | C21: 1 | D21: 1 | E21: 1 | F21: 1 | G21: 1 | H21: 1 | I21: 1 | J21: 1 | K21: 1 | L21: 1 | M21: 1 | N21: 1 | O21: 1 | P21: 1 | Q21: 1 | R21: 1 | S21: 1 | T21: 1 | U21: 1 | V21: 1 | W21: 1 | X21: 1 | Y21: 0.87878788 | Z21: 0 | AA21: 0 | AB21: 0 | AC21: 0 | AD21: 0
A23: EUR y/y of the quarterly average (%) | B23: → (avg / avg four quarters earlier − 1) × 100 | G23: =(G12/C12-1)*100 -> -6.8931584 | H23: =(H12/D12-1)*100 -> -11.686564 | I23: =(I12/E12-1)*100 -> -14.561451 | J23: =(J12/F12-1)*100 -> -10.614046 | K23: =(K12/G12-1)*100 -> -4.3772718 | L23: =(L12/H12-1)*100 -> 2.2741398 | M23: =(M12/I12-1)*100 -> 8.0722097 | N23: =(N12/J12-1)*100 -> 5.3245254 | ... AD23: =(AD12/Z12-1)*100 -> 0
A24: GBP y/y of the quarterly average (%) | B24: → (avg / avg four quarters earlier − 1) × 100 | G24: =(G13/C13-1)*100 -> -2.733462 | H24: =(H13/D13-1)*100 -> -10.19152 | I24: =(I13/E13-1)*100 -> -14.605222 | J24: =(J13/F13-1)*100 -> -12.849731 | K24: =(K13/G13-1)*100 -> -9.4173023 | L24: =(L13/H13-1)*100 -> -0.30207595 | M24: =(M13/I13-1)*100 -> 7.5971499 | N24: =(N13/J13-1)*100 -> 5.6851818 | ... AD24: =(AD13/Z13-1)*100 -> 0
A25: BRL y/y of the quarterly average (%) | B25: → (avg / avg four quarters earlier − 1) × 100 | G25: =(G14/C14-1)*100 -> 4.8837417 | H25: =(H14/D14-1)*100 -> 7.4970888 | I25: =(I14/E14-1)*100 -> -0.34547466 | J25: =(J14/F14-1)*100 -> 6.3092573 | K25: =(K14/G14-1)*100 -> 0.39409243 | L25: =(L14/H14-1)*100 -> -0.69596721 | M25: =(M14/I14-1)*100 -> 7.4457166 | N25: =(N14/J14-1)*100 -> 6.1256803 | ... AD25: =(AD14/Z14-1)*100 -> 0
A26: MXN y/y of the quarterly average (%) | B26: → (avg / avg four quarters earlier − 1) × 100 | G26: =(G15/C15-1)*100 -> -0.80811973 | H26: =(H15/D15-1)*100 -> -0.18974069 | I26: =(I15/E15-1)*100 -> -1.0058289 | J26: =(J15/F15-1)*100 -> 5.4523649 | K26: =(K15/G15-1)*100 -> 9.858778 | L26: =(L15/H15-1)*100 -> 13.442295 | M26: =(M15/I15-1)*100 -> 18.612544 | N26: =(N15/J15-1)*100 -> 12.205564 | ... AD26: =(AD15/Z15-1)*100 -> 0
A27: JPY y/y of the quarterly average (%) | B27: → (avg / avg four quarters earlier − 1) × 100 | G27: =(G16/C16-1)*100 -> -8.8245043 | H27: =(H16/D16-1)*100 -> -15.60466 | I27: =(I16/E16-1)*100 -> -20.360484 | J27: =(J16/F16-1)*100 -> -19.406981 | K27: =(K16/G16-1)*100 -> -12.159423 | L27: =(L16/H16-1)*100 -> -5.6100523 | M27: =(M16/I16-1)*100 -> -4.3377316 | N27: =(N16/J16-1)*100 -> -4.5260402 | ... AD27: =(AD16/Z16-1)*100 -> 0
A28: AUD y/y of the quarterly average (%) | B28: → (avg / avg four quarters earlier − 1) × 100 | G28: =(G17/C17-1)*100 -> -6.2286325 | H28: =(H17/D17-1)*100 -> -7.2744999 | I28: =(I17/E17-1)*100 -> -7.0104713 | J28: =(J17/F17-1)*100 -> -9.7698597 | K28: =(K17/G17-1)*100 -> -5.6918775 | L28: =(L17/H17-1)*100 -> -6.4348212 | M28: =(M17/I17-1)*100 -> -4.1629712 | N28: =(N17/J17-1)*100 -> -0.92997249 | ... AD28: =(AD17/Z17-1)*100 -> 0
A29: KRW y/y of the quarterly average (%) | B29: → (avg / avg four quarters earlier − 1) × 100 | G29: =(G18/C18-1)*100 -> -7.6347376 | H29: =(H18/D18-1)*100 -> -11.036641 | I29: =(I18/E18-1)*100 -> -13.440885 | J29: =(J18/F18-1)*100 -> -12.754078 | K29: =(K18/G18-1)*100 -> -5.45347 | L29: =(L18/H18-1)*100 -> -4.1582117 | M29: =(M18/I18-1)*100 -> 2.0373483 | N29: =(N18/J18-1)*100 -> 2.6937669 | ... AD29: =(AD18/Z18-1)*100 -> 0
A30: CAD y/y of the quarterly average (%) | B30: → (avg / avg four quarters earlier − 1) × 100 | G30: =(G19/C19-1)*100 -> -0.024765877 | H30: =(H19/D19-1)*100 -> -3.8151426 | I30: =(I19/E19-1)*100 -> -3.529504 | J30: =(J19/F19-1)*100 -> -7.1397079 | K30: =(K19/G19-1)*100 -> -6.3768263 | L30: =(L19/H19-1)*100 -> -4.9289085 | M30: =(M19/I19-1)*100 -> -2.6358046 | N30: =(N19/J19-1)*100 -> -0.28050398 | ... AD30: =(AD19/Z19-1)*100 -> 0
A31: INR y/y of the quarterly average (%) | B31: → (avg / avg four quarters earlier − 1) × 100 | G31: =(G20/C20-1)*100 -> -3.0560932 | H31: =(H20/D20-1)*100 -> -4.4536226 | I31: =(I20/E20-1)*100 -> -7.1156601 | J31: =(J20/F20-1)*100 -> -8.7916896 | K31: =(K20/G20-1)*100 -> -8.5091983 | L31: =(L20/H20-1)*100 -> -6.0561763 | M31: =(M20/I20-1)*100 -> -3.5248667 | N31: =(N20/J20-1)*100 -> -1.3330265 | ... AD31: =(AD20/Z20-1)*100 -> 0
A33: Destination-currency basket weights κ (frozen judgement, 01b_basket_weights_used.csv; USD legs carry 0) | B33: rows = region; columns C..K = EUR GBP BRL MXN JPY AUD KRW CAD INR; L = USD | C33: EUR | D33: GBP | E33: BRL | F33: MXN | G33: JPY | H33: AUD | I33: KRW | J33: CAD | K33: INR | L33: USD
A34: κ na | C34: 0 | D34: 0 | E34: 0 | F34: 0.02 | G34: 0 | H34: 0 | I34: 0 | J34: 0.08 | K34: 0 | L34: 0.9
A35: κ emea | C35: 0.7 | D35: 0.25 | E35: 0 | F35: 0 | G35: 0 | H35: 0 | I35: 0 | J35: 0 | K35: 0 | L35: 0.05
A36: κ latam | C36: 0 | D36: 0 | E36: 0.55 | F36: 0.38 | G36: 0 | H36: 0 | I36: 0 | J36: 0 | K36: 0 | L36: 0.07
A37: κ apac | C37: 0 | D37: 0 | E37: 0 | F37: 0 | G37: 0.2 | H37: 0.55 | I37: 0.1 | J37: 0 | K37: 0.07 | L37: 0.08
A39: basket y/y, na (%) | B39: → Σ_currency κ × currency y/y | G39: =$F$34*G26+$J$34*G30 -> -0.018143665 | H39: =$F$34*H26+$J$34*H30 -> -0.30900622 | I39: =$F$34*I26+$J$34*I30 -> -0.3024769 | J39: =$F$34*J26+$J$34*J30 -> -0.46212933 | K39: =$F$34*K26+$J$34*K30 -> -0.31297055 | L39: =$F$34*L26+$J$34*L30 -> -0.12546678 | M39: =$F$34*M26+$J$34*M30 -> 0.16138651 | N39: =$F$34*N26+$J$34*N30 -> 0.22167095 | ... AD39: =$F$34*AD26+$J$34*AD30 -> 0
A40: basket y/y, emea (%) | B40: → Σ_currency κ × currency y/y | G40: =$C$35*G23+$D$35*G24 -> -5.5085764 | H40: =$C$35*H23+$D$35*H24 -> -10.728475 | I40: =$C$35*I23+$D$35*I24 -> -13.844321 | J40: =$C$35*J23+$D$35*J24 -> -10.642265 | K40: =$C$35*K23+$D$35*K24 -> -5.4184158 | L40: =$C$35*L23+$D$35*L24 -> 1.5163789 | M40: =$C$35*M23+$D$35*M24 -> 7.5498343 | N40: =$C$35*N23+$D$35*N24 -> 5.1484632 | ... AD40: =$C$35*AD23+$D$35*AD24 -> 0
A41: basket y/y, latam (%) | B41: → Σ_currency κ × currency y/y | G41: =$E$36*G25+$F$36*G26 -> 2.3789724 | H41: =$E$36*H25+$F$36*H26 -> 4.0512974 | I41: =$E$36*I25+$F$36*I26 -> -0.57222604 | J41: =$E$36*J25+$F$36*J26 -> 5.5419902 | K41: =$E$36*K25+$F$36*K26 -> 3.9630865 | L41: =$E$36*L25+$F$36*L26 -> 4.7252902 | M41: =$E$36*M25+$F$36*M26 -> 11.167911 | N41: =$E$36*N25+$F$36*N26 -> 8.0072383 | ... AD41: =$E$36*AD25+$F$36*AD26 -> 0
A42: basket y/y, apac (%) | B42: → Σ_currency κ × currency y/y | G42: =$G$37*G27+$H$37*G28+$I$37*G29+$K$37*G31 -> -6.168049 | H42: =$G$37*H27+$H$37*H28+$I$37*H29+$K$37*H31 -> -8.5373246 | I42: =$G$37*I27+$H$37*I28+$I$37*I29+$K$37*I31 -> -9.7700407 | J42: =$G$37*J27+$H$37*J28+$I$37*J29+$K$37*J31 -> -11.145645 | K42: =$G$37*K27+$H$37*K28+$I$37*K29+$K$37*K31 -> -6.7034081 | L42: =$G$37*L27+$H$37*L28+$I$37*L29+$K$37*L31 -> -5.5009156 | M42: =$G$37*M27+$H$37*M28+$I$37*M29+$K$37*M31 -> -3.2001863 | N42: =$G$37*N27+$H$37*N28+$I$37*N29+$K$37*N31 -> -1.2406281 | ... AD42: =$G$37*AD27+$H$37*AD28+$I$37*AD29+$K$37*AD31 -> 0
A43: Regional GBV shares (10-K Geographic Mix, latest fiscal year filed before the quarter's print; FY2025 forward) | B43: data/processed/adr/01_regional_annual.csv gbv_share_pct
A44: GBV share, na | C44: 0.55111332 | D44: 0.55111332 | E44: 0.55111332 | F44: 0.55111332 | G44: 0.53982763 | H44: 0.53982763 | I44: 0.53982763 | J44: 0.53982763 | K44: 0.51012466 | L44: 0.51012466 | M44: 0.51012466 | N44: 0.51012466 | O44: 0.47699722 | P44: 0.47699722 | Q44: 0.47699722 | R44: 0.47699722 | S44: 0.46238873 | T44: 0.46238873 | U44: 0.46238873 | V44: 0.46238873 | W44: 0.44147776 | X44: 0.44147776 | Y44: 0.44147776 | Z44: 0.44147776 | AA44: 0.44147776 | AB44: 0.44147776 | AC44: 0.44147776 | AD44: 0.44147776
A45: GBV share, emea | C45: 0.27870142 | D45: 0.27870142 | E45: 0.27870142 | F45: 0.27870142 | G45: 0.31160057 | H45: 0.31160057 | I45: 0.31160057 | J45: 0.31160057 | K45: 0.33990382 | L45: 0.33990382 | M45: 0.33990382 | N45: 0.33990382 | O45: 0.35822913 | P45: 0.35822913 | Q45: 0.35822913 | R45: 0.35822913 | S45: 0.36376308 | T45: 0.36376308 | U45: 0.36376308 | V45: 0.36376308 | W45: 0.37428374 | X45: 0.37428374 | Y45: 0.37428374 | Z45: 0.37428374 | AA45: 0.37428374 | AB45: 0.37428374 | AC45: 0.37428374 | AD45: 0.37428374
A46: GBV share, latam | C46: 0.071172411 | D46: 0.071172411 | E46: 0.071172411 | F46: 0.071172411 | G46: 0.07905796 | H46: 0.07905796 | I46: 0.07905796 | J46: 0.07905796 | K46: 0.076536101 | L46: 0.076536101 | M46: 0.076536101 | N46: 0.076536101 | O46: 0.082646208 | P46: 0.082646208 | Q46: 0.082646208 | R46: 0.082646208 | S46: 0.086716228 | T46: 0.086716228 | U46: 0.086716228 | V46: 0.086716228 | W46: 0.09358737 | X46: 0.09358737 | Y46: 0.09358737 | Z46: 0.09358737 | AA46: 0.09358737 | AB46: 0.09358737 | AC46: 0.09358737 | AD46: 0.09358737
...
